{
  "timestamp": "2025-07-28T21:09:46.508591",
  "duration": "0:00:15.385042",
  "health_status": {
    "agent-wizard": {
      "status": "\u2717 UNAVAILABLE",
      "error": "All connection attempts failed"
    },
    "analytics": {
      "status": "\u2717 UNAVAILABLE",
      "error": "All connection attempts failed"
    },
    "billing": {
      "status": "\u2717 UNAVAILABLE",
      "error": "All connection attempts failed"
    },
    "dashboard": {
      "status": "\u2717 UNAVAILABLE",
      "error": "All connection attempts failed"
    },
    "widget": {
      "status": "\u2717 UNAVAILABLE",
      "error": "All connection attempts failed"
    },
    "my-agents": {
      "status": "\u2717 UNAVAILABLE",
      "error": "All connection attempts failed"
    }
  },
  "unit_results": {
    "agent-wizard": {
      "return_code": 1,
      "passed": false,
      "failed": true,
      "output": "============================= test session starts ==============================\nplatform linux -- Python 3.11.13, pytest-8.4.1, pluggy-1.6.0 -- /home/runner/workspace/.pythonlibs/bin/python3\ncachedir: .pytest_cache\nrootdir: /home/runner/workspace\nconfigfile: pyproject.toml\nplugins: anyio-4.9.0, asyncio-1.1.0\nasyncio: mode=Mode.AUTO, asyncio_default_fixture_loop_scope=None, asyncio_default_test_loop_scope=function\ncollecting ... collected 12 items\n\ntest_agent_wizard.py::TestAgentWizardService::test_health_endpoint FAILED [  8%]\ntest_agent_wizard.py::TestAgentWizardService::test_create_agent_valid_data FAILED [ 16%]\ntest_agent_wizard.py::TestAgentWizardService::test_create_agent_invalid_data FAILED [ 25%]\ntest_agent_wizard.py::TestAgentWizardService::test_get_agents_list FAILED [ 33%]\ntest_agent_wizard.py::TestAgentWizardService::test_get_agent_by_id FAILED [ 41%]\ntest_agent_wizard.py::TestAgentWizardService::test_update_agent FAILED   [ 50%]\ntest_agent_wizard.py::TestAgentWizardService::test_delete_agent FAILED   [ 58%]\ntest_agent_wizard.py::TestAgentWizardService::test_system_prompt_generation FAILED [ 66%]\ntest_agent_wizard.py::TestAgentWizardService::test_industry_metadata FAILED [ 75%]\ntest_agent_wizard.py::TestAgentWizardService::test_llm_model_validation FAILED [ 83%]\ntest_agent_wizard.py::TestAgentWizardService::test_chat_capabilities FAILED [ 91%]\ntest_agent_wizard.py::test_performance_benchmarks FAILED                 [100%]\n\n=================================== FAILURES ===================================\n_________________ TestAgentWizardService.test_health_endpoint __________________\n../../.pythonlibs/lib/python3.11/site-packages/httpx/_transports/default.py:101: in map_httpcore_exceptions\n    yield\n../../.pythonlibs/lib/python3.11/site-packages/httpx/_transports/default.py:394: in handle_async_request\n    resp = await self._pool.handle_async_request(req)\n           ^^^^^^^^^^^^^^^^^^^^^^^^^^^^^^^^^^^^^^^^^^\n../../.pythonlibs/lib/python3.11/site-packages/httpcore/_async/connection_pool.py:256: in handle_async_request\n    raise exc from None\n../../.pythonlibs/lib/python3.11/site-packages/httpcore/_async/connection_pool.py:236: in handle_async_request\n    response = await connection.handle_async_request(\n../../.pythonlibs/lib/python3.11/site-packages/httpcore/_async/connection.py:101: in handle_async_request\n    raise exc\n../../.pythonlibs/lib/python3.11/site-packages/httpcore/_async/connection.py:78: in handle_async_request\n    stream = await self._connect(request)\n             ^^^^^^^^^^^^^^^^^^^^^^^^^^^^\n../../.pythonlibs/lib/python3.11/site-packages/httpcore/_async/connection.py:124: in _connect\n    stream = await self._network_backend.connect_tcp(**kwargs)\n             ^^^^^^^^^^^^^^^^^^^^^^^^^^^^^^^^^^^^^^^^^^^^^^^^^\n../../.pythonlibs/lib/python3.11/site-packages/httpcore/_backends/auto.py:31: in connect_tcp\n    return await self._backend.connect_tcp(\n../../.pythonlibs/lib/python3.11/site-packages/httpcore/_backends/anyio.py:113: in connect_tcp\n    with map_exceptions(exc_map):\n/nix/store/7d088dip86hlzri9sk0h78b63yfmx0a0-python3-3.11.13/lib/python3.11/contextlib.py:158: in __exit__\n    self.gen.throw(typ, value, traceback)\n../../.pythonlibs/lib/python3.11/site-packages/httpcore/_exceptions.py:14: in map_exceptions\n    raise to_exc(exc) from exc\nE   httpcore.ConnectError: All connection attempts failed\n\nThe above exception was the direct cause of the following exception:\ntest_agent_wizard.py:35: in test_health_endpoint\n    response = await client.get(\"/health\")\n               ^^^^^^^^^^^^^^^^^^^^^^^^^^^\n../../.pythonlibs/lib/python3.11/site-packages/httpx/_client.py:1768: in get\n    return await self.request(\n../../.pythonlibs/lib/python3.11/site-packages/httpx/_client.py:1540: in request\n    return await self.send(request, auth=auth, follow_redirects=follow_redirects)\n           ^^^^^^^^^^^^^^^^^^^^^^^^^^^^^^^^^^^^^^^^^^^^^^^^^^^^^^^^^^^^^^^^^^^^^^\n../../.pythonlibs/lib/python3.11/site-packages/httpx/_client.py:1629: in send\n    response = await self._send_handling_auth(\n../../.pythonlibs/lib/python3.11/site-packages/httpx/_client.py:1657: in _send_handling_auth\n    response = await self._send_handling_redirects(\n../../.pythonlibs/lib/python3.11/site-packages/httpx/_client.py:1694: in _send_handling_redirects\n    response = await self._send_single_request(request)\n               ^^^^^^^^^^^^^^^^^^^^^^^^^^^^^^^^^^^^^^^^\n../../.pythonlibs/lib/python3.11/site-packages/httpx/_client.py:1730: in _send_single_request\n    response = await transport.handle_async_request(request)\n               ^^^^^^^^^^^^^^^^^^^^^^^^^^^^^^^^^^^^^^^^^^^^^\n../../.pythonlibs/lib/python3.11/site-packages/httpx/_transports/default.py:393: in handle_async_request\n    with map_httpcore_exceptions():\n/nix/store/7d088dip86hlzri9sk0h78b63yfmx0a0-python3-3.11.13/lib/python3.11/contextlib.py:158: in __exit__\n    self.gen.throw(typ, value, traceback)\n../../.pythonlibs/lib/python3.11/site-packages/httpx/_transports/default.py:118: in map_httpcore_exceptions\n    raise mapped_exc(message) from exc\nE   httpx.ConnectError: All connection attempts failed\n_____________ TestAgentWizardService.test_create_agent_valid_data ______________\n../../.pythonlibs/lib/python3.11/site-packages/httpx/_transports/default.py:101: in map_httpcore_exceptions\n    yield\n../../.pythonlibs/lib/python3.11/site-packages/httpx/_transports/default.py:394: in handle_async_request\n    resp = await self._pool.handle_async_request(req)\n           ^^^^^^^^^^^^^^^^^^^^^^^^^^^^^^^^^^^^^^^^^^\n../../.pythonlibs/lib/python3.11/site-packages/httpcore/_async/connection_pool.py:256: in handle_async_request\n    raise exc from None\n../../.pythonlibs/lib/python3.11/site-packages/httpcore/_async/connection_pool.py:236: in handle_async_request\n    response = await connection.handle_async_request(\n../../.pythonlibs/lib/python3.11/site-packages/httpcore/_async/connection.py:101: in handle_async_request\n    raise exc\n../../.pythonlibs/lib/python3.11/site-packages/httpcore/_async/connection.py:78: in handle_async_request\n    stream = await self._connect(request)\n             ^^^^^^^^^^^^^^^^^^^^^^^^^^^^\n../../.pythonlibs/lib/python3.11/site-packages/httpcore/_async/connection.py:124: in _connect\n    stream = await self._network_backend.connect_tcp(**kwargs)\n             ^^^^^^^^^^^^^^^^^^^^^^^^^^^^^^^^^^^^^^^^^^^^^^^^^\n../../.pythonlibs/lib/python3.11/site-packages/httpcore/_backends/auto.py:31: in connect_tcp\n    return await self._backend.connect_tcp(\n../../.pythonlibs/lib/python3.11/site-packages/httpcore/_backends/anyio.py:113: in connect_tcp\n    with map_exceptions(exc_map):\n/nix/store/7d088dip86hlzri9sk0h78b63yfmx0a0-python3-3.11.13/lib/python3.11/contextlib.py:158: in __exit__\n    self.gen.throw(typ, value, traceback)\n../../.pythonlibs/lib/python3.11/site-packages/httpcore/_exceptions.py:14: in map_exceptions\n    raise to_exc(exc) from exc\nE   httpcore.ConnectError: All connection attempts failed\n\nThe above exception was the direct cause of the following exception:\ntest_agent_wizard.py:46: in test_create_agent_valid_data\n    response = await client.post(\"/api/agents\", json=sample_agent_data)\n               ^^^^^^^^^^^^^^^^^^^^^^^^^^^^^^^^^^^^^^^^^^^^^^^^^^^^^^^^\n../../.pythonlibs/lib/python3.11/site-packages/httpx/_client.py:1859: in post\n    return await self.request(\n../../.pythonlibs/lib/python3.11/site-packages/httpx/_client.py:1540: in request\n    return await self.send(request, auth=auth, follow_redirects=follow_redirects)\n           ^^^^^^^^^^^^^^^^^^^^^^^^^^^^^^^^^^^^^^^^^^^^^^^^^^^^^^^^^^^^^^^^^^^^^^\n../../.pythonlibs/lib/python3.11/site-packages/httpx/_client.py:1629: in send\n    response = await self._send_handling_auth(\n../../.pythonlibs/lib/python3.11/site-packages/httpx/_client.py:1657: in _send_handling_auth\n    response = await self._send_handling_redirects(\n../../.pythonlibs/lib/python3.11/site-packages/httpx/_client.py:1694: in _send_handling_redirects\n    response = await self._send_single_request(request)\n               ^^^^^^^^^^^^^^^^^^^^^^^^^^^^^^^^^^^^^^^^\n../../.pythonlibs/lib/python3.11/site-packages/httpx/_client.py:1730: in _send_single_request\n    response = await transport.handle_async_request(request)\n               ^^^^^^^^^^^^^^^^^^^^^^^^^^^^^^^^^^^^^^^^^^^^^\n../../.pythonlibs/lib/python3.11/site-packages/httpx/_transports/default.py:393: in handle_async_request\n    with map_httpcore_exceptions():\n/nix/store/7d088dip86hlzri9sk0h78b63yfmx0a0-python3-3.11.13/lib/python3.11/contextlib.py:158: in __exit__\n    self.gen.throw(typ, value, traceback)\n../../.pythonlibs/lib/python3.11/site-packages/httpx/_transports/default.py:118: in map_httpcore_exceptions\n    raise mapped_exc(message) from exc\nE   httpx.ConnectError: All connection attempts failed\n____________ TestAgentWizardService.test_create_agent_invalid_data _____________\n../../.pythonlibs/lib/python3.11/site-packages/httpx/_transports/default.py:101: in map_httpcore_exceptions\n    yield\n../../.pythonlibs/lib/python3.11/site-packages/httpx/_transports/default.py:394: in handle_async_request\n    resp = await self._pool.handle_async_request(req)\n           ^^^^^^^^^^^^^^^^^^^^^^^^^^^^^^^^^^^^^^^^^^\n../../.pythonlibs/lib/python3.11/site-packages/httpcore/_async/connection_pool.py:256: in handle_async_request\n    raise exc from None\n../../.pythonlibs/lib/python3.11/site-packages/httpcore/_async/connection_pool.py:236: in handle_async_request\n    response = await connection.handle_async_request(\n../../.pythonlibs/lib/python3.11/site-packages/httpcore/_async/connection.py:101: in handle_async_request\n    raise exc\n../../.pythonlibs/lib/python3.11/site-packages/httpcore/_async/connection.py:78: in handle_async_request\n    stream = await self._connect(request)\n             ^^^^^^^^^^^^^^^^^^^^^^^^^^^^\n../../.pythonlibs/lib/python3.11/site-packages/httpcore/_async/connection.py:124: in _connect\n    stream = await self._network_backend.connect_tcp(**kwargs)\n             ^^^^^^^^^^^^^^^^^^^^^^^^^^^^^^^^^^^^^^^^^^^^^^^^^\n../../.pythonlibs/lib/python3.11/site-packages/httpcore/_backends/auto.py:31: in connect_tcp\n    return await self._backend.connect_tcp(\n../../.pythonlibs/lib/python3.11/site-packages/httpcore/_backends/anyio.py:113: in connect_tcp\n    with map_exceptions(exc_map):\n/nix/store/7d088dip86hlzri9sk0h78b63yfmx0a0-python3-3.11.13/lib/python3.11/contextlib.py:158: in __exit__\n    self.gen.throw(typ, value, traceback)\n../../.pythonlibs/lib/python3.11/site-packages/httpcore/_exceptions.py:14: in map_exceptions\n    raise to_exc(exc) from exc\nE   httpcore.ConnectError: All connection attempts failed\n\nThe above exception was the direct cause of the following exception:\ntest_agent_wizard.py:63: in test_create_agent_invalid_data\n    response = await client.post(\"/api/agents\", json=invalid_data)\n               ^^^^^^^^^^^^^^^^^^^^^^^^^^^^^^^^^^^^^^^^^^^^^^^^^^^\n../../.pythonlibs/lib/python3.11/site-packages/httpx/_client.py:1859: in post\n    return await self.request(\n../../.pythonlibs/lib/python3.11/site-packages/httpx/_client.py:1540: in request\n    return await self.send(request, auth=auth, follow_redirects=follow_redirects)\n           ^^^^^^^^^^^^^^^^^^^^^^^^^^^^^^^^^^^^^^^^^^^^^^^^^^^^^^^^^^^^^^^^^^^^^^\n../../.pythonlibs/lib/python3.11/site-packages/httpx/_client.py:1629: in send\n    response = await self._send_handling_auth(\n../../.pythonlibs/lib/python3.11/site-packages/httpx/_client.py:1657: in _send_handling_auth\n    response = await self._send_handling_redirects(\n../../.pythonlibs/lib/python3.11/site-packages/httpx/_client.py:1694: in _send_handling_redirects\n    response = await self._send_single_request(request)\n               ^^^^^^^^^^^^^^^^^^^^^^^^^^^^^^^^^^^^^^^^\n../../.pythonlibs/lib/python3.11/site-packages/httpx/_client.py:1730: in _send_single_request\n    response = await transport.handle_async_request(request)\n               ^^^^^^^^^^^^^^^^^^^^^^^^^^^^^^^^^^^^^^^^^^^^^\n../../.pythonlibs/lib/python3.11/site-packages/httpx/_transports/default.py:393: in handle_async_request\n    with map_httpcore_exceptions():\n/nix/store/7d088dip86hlzri9sk0h78b63yfmx0a0-python3-3.11.13/lib/python3.11/contextlib.py:158: in __exit__\n    self.gen.throw(typ, value, traceback)\n../../.pythonlibs/lib/python3.11/site-packages/httpx/_transports/default.py:118: in map_httpcore_exceptions\n    raise mapped_exc(message) from exc\nE   httpx.ConnectError: All connection attempts failed\n_________________ TestAgentWizardService.test_get_agents_list __________________\n../../.pythonlibs/lib/python3.11/site-packages/httpx/_transports/default.py:101: in map_httpcore_exceptions\n    yield\n../../.pythonlibs/lib/python3.11/site-packages/httpx/_transports/default.py:394: in handle_async_request\n    resp = await self._pool.handle_async_request(req)\n           ^^^^^^^^^^^^^^^^^^^^^^^^^^^^^^^^^^^^^^^^^^\n../../.pythonlibs/lib/python3.11/site-packages/httpcore/_async/connection_pool.py:256: in handle_async_request\n    raise exc from None\n../../.pythonlibs/lib/python3.11/site-packages/httpcore/_async/connection_pool.py:236: in handle_async_request\n    response = await connection.handle_async_request(\n../../.pythonlibs/lib/python3.11/site-packages/httpcore/_async/connection.py:101: in handle_async_request\n    raise exc\n../../.pythonlibs/lib/python3.11/site-packages/httpcore/_async/connection.py:78: in handle_async_request\n    stream = await self._connect(request)\n             ^^^^^^^^^^^^^^^^^^^^^^^^^^^^\n../../.pythonlibs/lib/python3.11/site-packages/httpcore/_async/connection.py:124: in _connect\n    stream = await self._network_backend.connect_tcp(**kwargs)\n             ^^^^^^^^^^^^^^^^^^^^^^^^^^^^^^^^^^^^^^^^^^^^^^^^^\n../../.pythonlibs/lib/python3.11/site-packages/httpcore/_backends/auto.py:31: in connect_tcp\n    return await self._backend.connect_tcp(\n../../.pythonlibs/lib/python3.11/site-packages/httpcore/_backends/anyio.py:113: in connect_tcp\n    with map_exceptions(exc_map):\n/nix/store/7d088dip86hlzri9sk0h78b63yfmx0a0-python3-3.11.13/lib/python3.11/contextlib.py:158: in __exit__\n    self.gen.throw(typ, value, traceback)\n../../.pythonlibs/lib/python3.11/site-packages/httpcore/_exceptions.py:14: in map_exceptions\n    raise to_exc(exc) from exc\nE   httpcore.ConnectError: All connection attempts failed\n\nThe above exception was the direct cause of the following exception:\ntest_agent_wizard.py:69: in test_get_agents_list\n    response = await client.get(\"/api/agents\")\n               ^^^^^^^^^^^^^^^^^^^^^^^^^^^^^^^\n../../.pythonlibs/lib/python3.11/site-packages/httpx/_client.py:1768: in get\n    return await self.request(\n../../.pythonlibs/lib/python3.11/site-packages/httpx/_client.py:1540: in request\n    return await self.send(request, auth=auth, follow_redirects=follow_redirects)\n           ^^^^^^^^^^^^^^^^^^^^^^^^^^^^^^^^^^^^^^^^^^^^^^^^^^^^^^^^^^^^^^^^^^^^^^\n../../.pythonlibs/lib/python3.11/site-packages/httpx/_client.py:1629: in send\n    response = await self._send_handling_auth(\n../../.pythonlibs/lib/python3.11/site-packages/httpx/_client.py:1657: in _send_handling_auth\n    response = await self._send_handling_redirects(\n../../.pythonlibs/lib/python3.11/site-packages/httpx/_client.py:1694: in _send_handling_redirects\n    response = await self._send_single_request(request)\n               ^^^^^^^^^^^^^^^^^^^^^^^^^^^^^^^^^^^^^^^^\n../../.pythonlibs/lib/python3.11/site-packages/httpx/_client.py:1730: in _send_single_request\n    response = await transport.handle_async_request(request)\n               ^^^^^^^^^^^^^^^^^^^^^^^^^^^^^^^^^^^^^^^^^^^^^\n../../.pythonlibs/lib/python3.11/site-packages/httpx/_transports/default.py:393: in handle_async_request\n    with map_httpcore_exceptions():\n/nix/store/7d088dip86hlzri9sk0h78b63yfmx0a0-python3-3.11.13/lib/python3.11/contextlib.py:158: in __exit__\n    self.gen.throw(typ, value, traceback)\n../../.pythonlibs/lib/python3.11/site-packages/httpx/_transports/default.py:118: in map_httpcore_exceptions\n    raise mapped_exc(message) from exc\nE   httpx.ConnectError: All connection attempts failed\n_________________ TestAgentWizardService.test_get_agent_by_id __________________\n../../.pythonlibs/lib/python3.11/site-packages/httpx/_transports/default.py:101: in map_httpcore_exceptions\n    yield\n../../.pythonlibs/lib/python3.11/site-packages/httpx/_transports/default.py:394: in handle_async_request\n    resp = await self._pool.handle_async_request(req)\n           ^^^^^^^^^^^^^^^^^^^^^^^^^^^^^^^^^^^^^^^^^^\n../../.pythonlibs/lib/python3.11/site-packages/httpcore/_async/connection_pool.py:256: in handle_async_request\n    raise exc from None\n../../.pythonlibs/lib/python3.11/site-packages/httpcore/_async/connection_pool.py:236: in handle_async_request\n    response = await connection.handle_async_request(\n../../.pythonlibs/lib/python3.11/site-packages/httpcore/_async/connection.py:101: in handle_async_request\n    raise exc\n../../.pythonlibs/lib/python3.11/site-packages/httpcore/_async/connection.py:78: in handle_async_request\n    stream = await self._connect(request)\n             ^^^^^^^^^^^^^^^^^^^^^^^^^^^^\n../../.pythonlibs/lib/python3.11/site-packages/httpcore/_async/connection.py:124: in _connect\n    stream = await self._network_backend.connect_tcp(**kwargs)\n             ^^^^^^^^^^^^^^^^^^^^^^^^^^^^^^^^^^^^^^^^^^^^^^^^^\n../../.pythonlibs/lib/python3.11/site-packages/httpcore/_backends/auto.py:31: in connect_tcp\n    return await self._backend.connect_tcp(\n../../.pythonlibs/lib/python3.11/site-packages/httpcore/_backends/anyio.py:113: in connect_tcp\n    with map_exceptions(exc_map):\n/nix/store/7d088dip86hlzri9sk0h78b63yfmx0a0-python3-3.11.13/lib/python3.11/contextlib.py:158: in __exit__\n    self.gen.throw(typ, value, traceback)\n../../.pythonlibs/lib/python3.11/site-packages/httpcore/_exceptions.py:14: in map_exceptions\n    raise to_exc(exc) from exc\nE   httpcore.ConnectError: All connection attempts failed\n\nThe above exception was the direct cause of the following exception:\ntest_agent_wizard.py:78: in test_get_agent_by_id\n    create_response = await client.post(\"/api/agents\", json=sample_agent_data)\n                      ^^^^^^^^^^^^^^^^^^^^^^^^^^^^^^^^^^^^^^^^^^^^^^^^^^^^^^^^\n../../.pythonlibs/lib/python3.11/site-packages/httpx/_client.py:1859: in post\n    return await self.request(\n../../.pythonlibs/lib/python3.11/site-packages/httpx/_client.py:1540: in request\n    return await self.send(request, auth=auth, follow_redirects=follow_redirects)\n           ^^^^^^^^^^^^^^^^^^^^^^^^^^^^^^^^^^^^^^^^^^^^^^^^^^^^^^^^^^^^^^^^^^^^^^\n../../.pythonlibs/lib/python3.11/site-packages/httpx/_client.py:1629: in send\n    response = await self._send_handling_auth(\n../../.pythonlibs/lib/python3.11/site-packages/httpx/_client.py:1657: in _send_handling_auth\n    response = await self._send_handling_redirects(\n../../.pythonlibs/lib/python3.11/site-packages/httpx/_client.py:1694: in _send_handling_redirects\n    response = await self._send_single_request(request)\n               ^^^^^^^^^^^^^^^^^^^^^^^^^^^^^^^^^^^^^^^^\n../../.pythonlibs/lib/python3.11/site-packages/httpx/_client.py:1730: in _send_single_request\n    response = await transport.handle_async_request(request)\n               ^^^^^^^^^^^^^^^^^^^^^^^^^^^^^^^^^^^^^^^^^^^^^\n../../.pythonlibs/lib/python3.11/site-packages/httpx/_transports/default.py:393: in handle_async_request\n    with map_httpcore_exceptions():\n/nix/store/7d088dip86hlzri9sk0h78b63yfmx0a0-python3-3.11.13/lib/python3.11/contextlib.py:158: in __exit__\n    self.gen.throw(typ, value, traceback)\n../../.pythonlibs/lib/python3.11/site-packages/httpx/_transports/default.py:118: in map_httpcore_exceptions\n    raise mapped_exc(message) from exc\nE   httpx.ConnectError: All connection attempts failed\n___________________ TestAgentWizardService.test_update_agent ___________________\n../../.pythonlibs/lib/python3.11/site-packages/httpx/_transports/default.py:101: in map_httpcore_exceptions\n    yield\n../../.pythonlibs/lib/python3.11/site-packages/httpx/_transports/default.py:394: in handle_async_request\n    resp = await self._pool.handle_async_request(req)\n           ^^^^^^^^^^^^^^^^^^^^^^^^^^^^^^^^^^^^^^^^^^\n../../.pythonlibs/lib/python3.11/site-packages/httpcore/_async/connection_pool.py:256: in handle_async_request\n    raise exc from None\n../../.pythonlibs/lib/python3.11/site-packages/httpcore/_async/connection_pool.py:236: in handle_async_request\n    response = await connection.handle_async_request(\n../../.pythonlibs/lib/python3.11/site-packages/httpcore/_async/connection.py:101: in handle_async_request\n    raise exc\n../../.pythonlibs/lib/python3.11/site-packages/httpcore/_async/connection.py:78: in handle_async_request\n    stream = await self._connect(request)\n             ^^^^^^^^^^^^^^^^^^^^^^^^^^^^\n../../.pythonlibs/lib/python3.11/site-packages/httpcore/_async/connection.py:124: in _connect\n    stream = await self._network_backend.connect_tcp(**kwargs)\n             ^^^^^^^^^^^^^^^^^^^^^^^^^^^^^^^^^^^^^^^^^^^^^^^^^\n../../.pythonlibs/lib/python3.11/site-packages/httpcore/_backends/auto.py:31: in connect_tcp\n    return await self._backend.connect_tcp(\n../../.pythonlibs/lib/python3.11/site-packages/httpcore/_backends/anyio.py:113: in connect_tcp\n    with map_exceptions(exc_map):\n/nix/store/7d088dip86hlzri9sk0h78b63yfmx0a0-python3-3.11.13/lib/python3.11/contextlib.py:158: in __exit__\n    self.gen.throw(typ, value, traceback)\n../../.pythonlibs/lib/python3.11/site-packages/httpcore/_exceptions.py:14: in map_exceptions\n    raise to_exc(exc) from exc\nE   httpcore.ConnectError: All connection attempts failed\n\nThe above exception was the direct cause of the following exception:\ntest_agent_wizard.py:92: in test_update_agent\n    create_response = await client.post(\"/api/agents\", json=sample_agent_data)\n                      ^^^^^^^^^^^^^^^^^^^^^^^^^^^^^^^^^^^^^^^^^^^^^^^^^^^^^^^^\n../../.pythonlibs/lib/python3.11/site-packages/httpx/_client.py:1859: in post\n    return await self.request(\n../../.pythonlibs/lib/python3.11/site-packages/httpx/_client.py:1540: in request\n    return await self.send(request, auth=auth, follow_redirects=follow_redirects)\n           ^^^^^^^^^^^^^^^^^^^^^^^^^^^^^^^^^^^^^^^^^^^^^^^^^^^^^^^^^^^^^^^^^^^^^^\n../../.pythonlibs/lib/python3.11/site-packages/httpx/_client.py:1629: in send\n    response = await self._send_handling_auth(\n../../.pythonlibs/lib/python3.11/site-packages/httpx/_client.py:1657: in _send_handling_auth\n    response = await self._send_handling_redirects(\n../../.pythonlibs/lib/python3.11/site-packages/httpx/_client.py:1694: in _send_handling_redirects\n    response = await self._send_single_request(request)\n               ^^^^^^^^^^^^^^^^^^^^^^^^^^^^^^^^^^^^^^^^\n../../.pythonlibs/lib/python3.11/site-packages/httpx/_client.py:1730: in _send_single_request\n    response = await transport.handle_async_request(request)\n               ^^^^^^^^^^^^^^^^^^^^^^^^^^^^^^^^^^^^^^^^^^^^^\n../../.pythonlibs/lib/python3.11/site-packages/httpx/_transports/default.py:393: in handle_async_request\n    with map_httpcore_exceptions():\n/nix/store/7d088dip86hlzri9sk0h78b63yfmx0a0-python3-3.11.13/lib/python3.11/contextlib.py:158: in __exit__\n    self.gen.throw(typ, value, traceback)\n../../.pythonlibs/lib/python3.11/site-packages/httpx/_transports/default.py:118: in map_httpcore_exceptions\n    raise mapped_exc(message) from exc\nE   httpx.ConnectError: All connection attempts failed\n___________________ TestAgentWizardService.test_delete_agent ___________________\n../../.pythonlibs/lib/python3.11/site-packages/httpx/_transports/default.py:101: in map_httpcore_exceptions\n    yield\n../../.pythonlibs/lib/python3.11/site-packages/httpx/_transports/default.py:394: in handle_async_request\n    resp = await self._pool.handle_async_request(req)\n           ^^^^^^^^^^^^^^^^^^^^^^^^^^^^^^^^^^^^^^^^^^\n../../.pythonlibs/lib/python3.11/site-packages/httpcore/_async/connection_pool.py:256: in handle_async_request\n    raise exc from None\n../../.pythonlibs/lib/python3.11/site-packages/httpcore/_async/connection_pool.py:236: in handle_async_request\n    response = await connection.handle_async_request(\n../../.pythonlibs/lib/python3.11/site-packages/httpcore/_async/connection.py:101: in handle_async_request\n    raise exc\n../../.pythonlibs/lib/python3.11/site-packages/httpcore/_async/connection.py:78: in handle_async_request\n    stream = await self._connect(request)\n             ^^^^^^^^^^^^^^^^^^^^^^^^^^^^\n../../.pythonlibs/lib/python3.11/site-packages/httpcore/_async/connection.py:124: in _connect\n    stream = await self._network_backend.connect_tcp(**kwargs)\n             ^^^^^^^^^^^^^^^^^^^^^^^^^^^^^^^^^^^^^^^^^^^^^^^^^\n../../.pythonlibs/lib/python3.11/site-packages/httpcore/_backends/auto.py:31: in connect_tcp\n    return await self._backend.connect_tcp(\n../../.pythonlibs/lib/python3.11/site-packages/httpcore/_backends/anyio.py:113: in connect_tcp\n    with map_exceptions(exc_map):\n/nix/store/7d088dip86hlzri9sk0h78b63yfmx0a0-python3-3.11.13/lib/python3.11/contextlib.py:158: in __exit__\n    self.gen.throw(typ, value, traceback)\n../../.pythonlibs/lib/python3.11/site-packages/httpcore/_exceptions.py:14: in map_exceptions\n    raise to_exc(exc) from exc\nE   httpcore.ConnectError: All connection attempts failed\n\nThe above exception was the direct cause of the following exception:\ntest_agent_wizard.py:108: in test_delete_agent\n    create_response = await client.post(\"/api/agents\", json=sample_agent_data)\n                      ^^^^^^^^^^^^^^^^^^^^^^^^^^^^^^^^^^^^^^^^^^^^^^^^^^^^^^^^\n../../.pythonlibs/lib/python3.11/site-packages/httpx/_client.py:1859: in post\n    return await self.request(\n../../.pythonlibs/lib/python3.11/site-packages/httpx/_client.py:1540: in request\n    return await self.send(request, auth=auth, follow_redirects=follow_redirects)\n           ^^^^^^^^^^^^^^^^^^^^^^^^^^^^^^^^^^^^^^^^^^^^^^^^^^^^^^^^^^^^^^^^^^^^^^\n../../.pythonlibs/lib/python3.11/site-packages/httpx/_client.py:1629: in send\n    response = await self._send_handling_auth(\n../../.pythonlibs/lib/python3.11/site-packages/httpx/_client.py:1657: in _send_handling_auth\n    response = await self._send_handling_redirects(\n../../.pythonlibs/lib/python3.11/site-packages/httpx/_client.py:1694: in _send_handling_redirects\n    response = await self._send_single_request(request)\n               ^^^^^^^^^^^^^^^^^^^^^^^^^^^^^^^^^^^^^^^^\n../../.pythonlibs/lib/python3.11/site-packages/httpx/_client.py:1730: in _send_single_request\n    response = await transport.handle_async_request(request)\n               ^^^^^^^^^^^^^^^^^^^^^^^^^^^^^^^^^^^^^^^^^^^^^\n../../.pythonlibs/lib/python3.11/site-packages/httpx/_transports/default.py:393: in handle_async_request\n    with map_httpcore_exceptions():\n/nix/store/7d088dip86hlzri9sk0h78b63yfmx0a0-python3-3.11.13/lib/python3.11/contextlib.py:158: in __exit__\n    self.gen.throw(typ, value, traceback)\n../../.pythonlibs/lib/python3.11/site-packages/httpx/_transports/default.py:118: in map_httpcore_exceptions\n    raise mapped_exc(message) from exc\nE   httpx.ConnectError: All connection attempts failed\n_____________ TestAgentWizardService.test_system_prompt_generation _____________\n../../.pythonlibs/lib/python3.11/site-packages/httpx/_transports/default.py:101: in map_httpcore_exceptions\n    yield\n../../.pythonlibs/lib/python3.11/site-packages/httpx/_transports/default.py:394: in handle_async_request\n    resp = await self._pool.handle_async_request(req)\n           ^^^^^^^^^^^^^^^^^^^^^^^^^^^^^^^^^^^^^^^^^^\n../../.pythonlibs/lib/python3.11/site-packages/httpcore/_async/connection_pool.py:256: in handle_async_request\n    raise exc from None\n../../.pythonlibs/lib/python3.11/site-packages/httpcore/_async/connection_pool.py:236: in handle_async_request\n    response = await connection.handle_async_request(\n../../.pythonlibs/lib/python3.11/site-packages/httpcore/_async/connection.py:101: in handle_async_request\n    raise exc\n../../.pythonlibs/lib/python3.11/site-packages/httpcore/_async/connection.py:78: in handle_async_request\n    stream = await self._connect(request)\n             ^^^^^^^^^^^^^^^^^^^^^^^^^^^^\n../../.pythonlibs/lib/python3.11/site-packages/httpcore/_async/connection.py:124: in _connect\n    stream = await self._network_backend.connect_tcp(**kwargs)\n             ^^^^^^^^^^^^^^^^^^^^^^^^^^^^^^^^^^^^^^^^^^^^^^^^^\n../../.pythonlibs/lib/python3.11/site-packages/httpcore/_backends/auto.py:31: in connect_tcp\n    return await self._backend.connect_tcp(\n../../.pythonlibs/lib/python3.11/site-packages/httpcore/_backends/anyio.py:113: in connect_tcp\n    with map_exceptions(exc_map):\n/nix/store/7d088dip86hlzri9sk0h78b63yfmx0a0-python3-3.11.13/lib/python3.11/contextlib.py:158: in __exit__\n    self.gen.throw(typ, value, traceback)\n../../.pythonlibs/lib/python3.11/site-packages/httpcore/_exceptions.py:14: in map_exceptions\n    raise to_exc(exc) from exc\nE   httpcore.ConnectError: All connection attempts failed\n\nThe above exception was the direct cause of the following exception:\ntest_agent_wizard.py:122: in test_system_prompt_generation\n    response = await client.post(\"/api/system-prompt\", json=sample_agent_data)\n               ^^^^^^^^^^^^^^^^^^^^^^^^^^^^^^^^^^^^^^^^^^^^^^^^^^^^^^^^^^^^^^^\n../../.pythonlibs/lib/python3.11/site-packages/httpx/_client.py:1859: in post\n    return await self.request(\n../../.pythonlibs/lib/python3.11/site-packages/httpx/_client.py:1540: in request\n    return await self.send(request, auth=auth, follow_redirects=follow_redirects)\n           ^^^^^^^^^^^^^^^^^^^^^^^^^^^^^^^^^^^^^^^^^^^^^^^^^^^^^^^^^^^^^^^^^^^^^^\n../../.pythonlibs/lib/python3.11/site-packages/httpx/_client.py:1629: in send\n    response = await self._send_handling_auth(\n../../.pythonlibs/lib/python3.11/site-packages/httpx/_client.py:1657: in _send_handling_auth\n    response = await self._send_handling_redirects(\n../../.pythonlibs/lib/python3.11/site-packages/httpx/_client.py:1694: in _send_handling_redirects\n    response = await self._send_single_request(request)\n               ^^^^^^^^^^^^^^^^^^^^^^^^^^^^^^^^^^^^^^^^\n../../.pythonlibs/lib/python3.11/site-packages/httpx/_client.py:1730: in _send_single_request\n    response = await transport.handle_async_request(request)\n               ^^^^^^^^^^^^^^^^^^^^^^^^^^^^^^^^^^^^^^^^^^^^^\n../../.pythonlibs/lib/python3.11/site-packages/httpx/_transports/default.py:393: in handle_async_request\n    with map_httpcore_exceptions():\n/nix/store/7d088dip86hlzri9sk0h78b63yfmx0a0-python3-3.11.13/lib/python3.11/contextlib.py:158: in __exit__\n    self.gen.throw(typ, value, traceback)\n../../.pythonlibs/lib/python3.11/site-packages/httpx/_transports/default.py:118: in map_httpcore_exceptions\n    raise mapped_exc(message) from exc\nE   httpx.ConnectError: All connection attempts failed\n________________ TestAgentWizardService.test_industry_metadata _________________\n../../.pythonlibs/lib/python3.11/site-packages/httpx/_transports/default.py:101: in map_httpcore_exceptions\n    yield\n../../.pythonlibs/lib/python3.11/site-packages/httpx/_transports/default.py:394: in handle_async_request\n    resp = await self._pool.handle_async_request(req)\n           ^^^^^^^^^^^^^^^^^^^^^^^^^^^^^^^^^^^^^^^^^^\n../../.pythonlibs/lib/python3.11/site-packages/httpcore/_async/connection_pool.py:256: in handle_async_request\n    raise exc from None\n../../.pythonlibs/lib/python3.11/site-packages/httpcore/_async/connection_pool.py:236: in handle_async_request\n    response = await connection.handle_async_request(\n../../.pythonlibs/lib/python3.11/site-packages/httpcore/_async/connection.py:101: in handle_async_request\n    raise exc\n../../.pythonlibs/lib/python3.11/site-packages/httpcore/_async/connection.py:78: in handle_async_request\n    stream = await self._connect(request)\n             ^^^^^^^^^^^^^^^^^^^^^^^^^^^^\n../../.pythonlibs/lib/python3.11/site-packages/httpcore/_async/connection.py:124: in _connect\n    stream = await self._network_backend.connect_tcp(**kwargs)\n             ^^^^^^^^^^^^^^^^^^^^^^^^^^^^^^^^^^^^^^^^^^^^^^^^^\n../../.pythonlibs/lib/python3.11/site-packages/httpcore/_backends/auto.py:31: in connect_tcp\n    return await self._backend.connect_tcp(\n../../.pythonlibs/lib/python3.11/site-packages/httpcore/_backends/anyio.py:113: in connect_tcp\n    with map_exceptions(exc_map):\n/nix/store/7d088dip86hlzri9sk0h78b63yfmx0a0-python3-3.11.13/lib/python3.11/contextlib.py:158: in __exit__\n    self.gen.throw(typ, value, traceback)\n../../.pythonlibs/lib/python3.11/site-packages/httpcore/_exceptions.py:14: in map_exceptions\n    raise to_exc(exc) from exc\nE   httpcore.ConnectError: All connection attempts failed\n\nThe above exception was the direct cause of the following exception:\ntest_agent_wizard.py:132: in test_industry_metadata\n    response = await client.get(\"/api/industries\")\n               ^^^^^^^^^^^^^^^^^^^^^^^^^^^^^^^^^^^\n../../.pythonlibs/lib/python3.11/site-packages/httpx/_client.py:1768: in get\n    return await self.request(\n../../.pythonlibs/lib/python3.11/site-packages/httpx/_client.py:1540: in request\n    return await self.send(request, auth=auth, follow_redirects=follow_redirects)\n           ^^^^^^^^^^^^^^^^^^^^^^^^^^^^^^^^^^^^^^^^^^^^^^^^^^^^^^^^^^^^^^^^^^^^^^\n../../.pythonlibs/lib/python3.11/site-packages/httpx/_client.py:1629: in send\n    response = await self._send_handling_auth(\n../../.pythonlibs/lib/python3.11/site-packages/httpx/_client.py:1657: in _send_handling_auth\n    response = await self._send_handling_redirects(\n../../.pythonlibs/lib/python3.11/site-packages/httpx/_client.py:1694: in _send_handling_redirects\n    response = await self._send_single_request(request)\n               ^^^^^^^^^^^^^^^^^^^^^^^^^^^^^^^^^^^^^^^^\n../../.pythonlibs/lib/python3.11/site-packages/httpx/_client.py:1730: in _send_single_request\n    response = await transport.handle_async_request(request)\n               ^^^^^^^^^^^^^^^^^^^^^^^^^^^^^^^^^^^^^^^^^^^^^\n../../.pythonlibs/lib/python3.11/site-packages/httpx/_transports/default.py:393: in handle_async_request\n    with map_httpcore_exceptions():\n/nix/store/7d088dip86hlzri9sk0h78b63yfmx0a0-python3-3.11.13/lib/python3.11/contextlib.py:158: in __exit__\n    self.gen.throw(typ, value, traceback)\n../../.pythonlibs/lib/python3.11/site-packages/httpx/_transports/default.py:118: in map_httpcore_exceptions\n    raise mapped_exc(message) from exc\nE   httpx.ConnectError: All connection attempts failed\n_______________ TestAgentWizardService.test_llm_model_validation _______________\n../../.pythonlibs/lib/python3.11/site-packages/httpx/_transports/default.py:101: in map_httpcore_exceptions\n    yield\n../../.pythonlibs/lib/python3.11/site-packages/httpx/_transports/default.py:394: in handle_async_request\n    resp = await self._pool.handle_async_request(req)\n           ^^^^^^^^^^^^^^^^^^^^^^^^^^^^^^^^^^^^^^^^^^\n../../.pythonlibs/lib/python3.11/site-packages/httpcore/_async/connection_pool.py:256: in handle_async_request\n    raise exc from None\n../../.pythonlibs/lib/python3.11/site-packages/httpcore/_async/connection_pool.py:236: in handle_async_request\n    response = await connection.handle_async_request(\n../../.pythonlibs/lib/python3.11/site-packages/httpcore/_async/connection.py:101: in handle_async_request\n    raise exc\n../../.pythonlibs/lib/python3.11/site-packages/httpcore/_async/connection.py:78: in handle_async_request\n    stream = await self._connect(request)\n             ^^^^^^^^^^^^^^^^^^^^^^^^^^^^\n../../.pythonlibs/lib/python3.11/site-packages/httpcore/_async/connection.py:124: in _connect\n    stream = await self._network_backend.connect_tcp(**kwargs)\n             ^^^^^^^^^^^^^^^^^^^^^^^^^^^^^^^^^^^^^^^^^^^^^^^^^\n../../.pythonlibs/lib/python3.11/site-packages/httpcore/_backends/auto.py:31: in connect_tcp\n    return await self._backend.connect_tcp(\n../../.pythonlibs/lib/python3.11/site-packages/httpcore/_backends/anyio.py:113: in connect_tcp\n    with map_exceptions(exc_map):\n/nix/store/7d088dip86hlzri9sk0h78b63yfmx0a0-python3-3.11.13/lib/python3.11/contextlib.py:158: in __exit__\n    self.gen.throw(typ, value, traceback)\n../../.pythonlibs/lib/python3.11/site-packages/httpcore/_exceptions.py:14: in map_exceptions\n    raise to_exc(exc) from exc\nE   httpcore.ConnectError: All connection attempts failed\n\nThe above exception was the direct cause of the following exception:\ntest_agent_wizard.py:149: in test_llm_model_validation\n    response = await client.get(\"/api/models\")\n               ^^^^^^^^^^^^^^^^^^^^^^^^^^^^^^^\n../../.pythonlibs/lib/python3.11/site-packages/httpx/_client.py:1768: in get\n    return await self.request(\n../../.pythonlibs/lib/python3.11/site-packages/httpx/_client.py:1540: in request\n    return await self.send(request, auth=auth, follow_redirects=follow_redirects)\n           ^^^^^^^^^^^^^^^^^^^^^^^^^^^^^^^^^^^^^^^^^^^^^^^^^^^^^^^^^^^^^^^^^^^^^^\n../../.pythonlibs/lib/python3.11/site-packages/httpx/_client.py:1629: in send\n    response = await self._send_handling_auth(\n../../.pythonlibs/lib/python3.11/site-packages/httpx/_client.py:1657: in _send_handling_auth\n    response = await self._send_handling_redirects(\n../../.pythonlibs/lib/python3.11/site-packages/httpx/_client.py:1694: in _send_handling_redirects\n    response = await self._send_single_request(request)\n               ^^^^^^^^^^^^^^^^^^^^^^^^^^^^^^^^^^^^^^^^\n../../.pythonlibs/lib/python3.11/site-packages/httpx/_client.py:1730: in _send_single_request\n    response = await transport.handle_async_request(request)\n               ^^^^^^^^^^^^^^^^^^^^^^^^^^^^^^^^^^^^^^^^^^^^^\n../../.pythonlibs/lib/python3.11/site-packages/httpx/_transports/default.py:393: in handle_async_request\n    with map_httpcore_exceptions():\n/nix/store/7d088dip86hlzri9sk0h78b63yfmx0a0-python3-3.11.13/lib/python3.11/contextlib.py:158: in __exit__\n    self.gen.throw(typ, value, traceback)\n../../.pythonlibs/lib/python3.11/site-packages/httpx/_transports/default.py:118: in map_httpcore_exceptions\n    raise mapped_exc(message) from exc\nE   httpx.ConnectError: All connection attempts failed\n________________ TestAgentWizardService.test_chat_capabilities _________________\n../../.pythonlibs/lib/python3.11/site-packages/httpx/_transports/default.py:101: in map_httpcore_exceptions\n    yield\n../../.pythonlibs/lib/python3.11/site-packages/httpx/_transports/default.py:394: in handle_async_request\n    resp = await self._pool.handle_async_request(req)\n           ^^^^^^^^^^^^^^^^^^^^^^^^^^^^^^^^^^^^^^^^^^\n../../.pythonlibs/lib/python3.11/site-packages/httpcore/_async/connection_pool.py:256: in handle_async_request\n    raise exc from None\n../../.pythonlibs/lib/python3.11/site-packages/httpcore/_async/connection_pool.py:236: in handle_async_request\n    response = await connection.handle_async_request(\n../../.pythonlibs/lib/python3.11/site-packages/httpcore/_async/connection.py:101: in handle_async_request\n    raise exc\n../../.pythonlibs/lib/python3.11/site-packages/httpcore/_async/connection.py:78: in handle_async_request\n    stream = await self._connect(request)\n             ^^^^^^^^^^^^^^^^^^^^^^^^^^^^\n../../.pythonlibs/lib/python3.11/site-packages/httpcore/_async/connection.py:124: in _connect\n    stream = await self._network_backend.connect_tcp(**kwargs)\n             ^^^^^^^^^^^^^^^^^^^^^^^^^^^^^^^^^^^^^^^^^^^^^^^^^\n../../.pythonlibs/lib/python3.11/site-packages/httpcore/_backends/auto.py:31: in connect_tcp\n    return await self._backend.connect_tcp(\n../../.pythonlibs/lib/python3.11/site-packages/httpcore/_backends/anyio.py:113: in connect_tcp\n    with map_exceptions(exc_map):\n/nix/store/7d088dip86hlzri9sk0h78b63yfmx0a0-python3-3.11.13/lib/python3.11/contextlib.py:158: in __exit__\n    self.gen.throw(typ, value, traceback)\n../../.pythonlibs/lib/python3.11/site-packages/httpcore/_exceptions.py:14: in map_exceptions\n    raise to_exc(exc) from exc\nE   httpcore.ConnectError: All connection attempts failed\n\nThe above exception was the direct cause of the following exception:\ntest_agent_wizard.py:169: in test_chat_capabilities\n    create_response = await client.post(\"/api/agents\", json=sample_agent_data)\n                      ^^^^^^^^^^^^^^^^^^^^^^^^^^^^^^^^^^^^^^^^^^^^^^^^^^^^^^^^\n../../.pythonlibs/lib/python3.11/site-packages/httpx/_client.py:1859: in post\n    return await self.request(\n../../.pythonlibs/lib/python3.11/site-packages/httpx/_client.py:1540: in request\n    return await self.send(request, auth=auth, follow_redirects=follow_redirects)\n           ^^^^^^^^^^^^^^^^^^^^^^^^^^^^^^^^^^^^^^^^^^^^^^^^^^^^^^^^^^^^^^^^^^^^^^\n../../.pythonlibs/lib/python3.11/site-packages/httpx/_client.py:1629: in send\n    response = await self._send_handling_auth(\n../../.pythonlibs/lib/python3.11/site-packages/httpx/_client.py:1657: in _send_handling_auth\n    response = await self._send_handling_redirects(\n../../.pythonlibs/lib/python3.11/site-packages/httpx/_client.py:1694: in _send_handling_redirects\n    response = await self._send_single_request(request)\n               ^^^^^^^^^^^^^^^^^^^^^^^^^^^^^^^^^^^^^^^^\n../../.pythonlibs/lib/python3.11/site-packages/httpx/_client.py:1730: in _send_single_request\n    response = await transport.handle_async_request(request)\n               ^^^^^^^^^^^^^^^^^^^^^^^^^^^^^^^^^^^^^^^^^^^^^\n../../.pythonlibs/lib/python3.11/site-packages/httpx/_transports/default.py:393: in handle_async_request\n    with map_httpcore_exceptions():\n/nix/store/7d088dip86hlzri9sk0h78b63yfmx0a0-python3-3.11.13/lib/python3.11/contextlib.py:158: in __exit__\n    self.gen.throw(typ, value, traceback)\n../../.pythonlibs/lib/python3.11/site-packages/httpx/_transports/default.py:118: in map_httpcore_exceptions\n    raise mapped_exc(message) from exc\nE   httpx.ConnectError: All connection attempts failed\n_________________________ test_performance_benchmarks __________________________\n../../.pythonlibs/lib/python3.11/site-packages/httpx/_transports/default.py:101: in map_httpcore_exceptions\n    yield\n../../.pythonlibs/lib/python3.11/site-packages/httpx/_transports/default.py:394: in handle_async_request\n    resp = await self._pool.handle_async_request(req)\n           ^^^^^^^^^^^^^^^^^^^^^^^^^^^^^^^^^^^^^^^^^^\n../../.pythonlibs/lib/python3.11/site-packages/httpcore/_async/connection_pool.py:256: in handle_async_request\n    raise exc from None\n../../.pythonlibs/lib/python3.11/site-packages/httpcore/_async/connection_pool.py:236: in handle_async_request\n    response = await connection.handle_async_request(\n../../.pythonlibs/lib/python3.11/site-packages/httpcore/_async/connection.py:101: in handle_async_request\n    raise exc\n../../.pythonlibs/lib/python3.11/site-packages/httpcore/_async/connection.py:78: in handle_async_request\n    stream = await self._connect(request)\n             ^^^^^^^^^^^^^^^^^^^^^^^^^^^^\n../../.pythonlibs/lib/python3.11/site-packages/httpcore/_async/connection.py:124: in _connect\n    stream = await self._network_backend.connect_tcp(**kwargs)\n             ^^^^^^^^^^^^^^^^^^^^^^^^^^^^^^^^^^^^^^^^^^^^^^^^^\n../../.pythonlibs/lib/python3.11/site-packages/httpcore/_backends/auto.py:31: in connect_tcp\n    return await self._backend.connect_tcp(\n../../.pythonlibs/lib/python3.11/site-packages/httpcore/_backends/anyio.py:113: in connect_tcp\n    with map_exceptions(exc_map):\n/nix/store/7d088dip86hlzri9sk0h78b63yfmx0a0-python3-3.11.13/lib/python3.11/contextlib.py:158: in __exit__\n    self.gen.throw(typ, value, traceback)\n../../.pythonlibs/lib/python3.11/site-packages/httpcore/_exceptions.py:14: in map_exceptions\n    raise to_exc(exc) from exc\nE   httpcore.ConnectError: All connection attempts failed\n\nThe above exception was the direct cause of the following exception:\ntest_agent_wizard.py:201: in test_performance_benchmarks\n    responses = await asyncio.gather(*tasks)\n                ^^^^^^^^^^^^^^^^^^^^^^^^^^^^\n../../.pythonlibs/lib/python3.11/site-packages/httpx/_client.py:1859: in post\n    return await self.request(\n../../.pythonlibs/lib/python3.11/site-packages/httpx/_client.py:1540: in request\n    return await self.send(request, auth=auth, follow_redirects=follow_redirects)\n           ^^^^^^^^^^^^^^^^^^^^^^^^^^^^^^^^^^^^^^^^^^^^^^^^^^^^^^^^^^^^^^^^^^^^^^\n../../.pythonlibs/lib/python3.11/site-packages/httpx/_client.py:1629: in send\n    response = await self._send_handling_auth(\n../../.pythonlibs/lib/python3.11/site-packages/httpx/_client.py:1657: in _send_handling_auth\n    response = await self._send_handling_redirects(\n../../.pythonlibs/lib/python3.11/site-packages/httpx/_client.py:1694: in _send_handling_redirects\n    response = await self._send_single_request(request)\n               ^^^^^^^^^^^^^^^^^^^^^^^^^^^^^^^^^^^^^^^^\n../../.pythonlibs/lib/python3.11/site-packages/httpx/_client.py:1730: in _send_single_request\n    response = await transport.handle_async_request(request)\n               ^^^^^^^^^^^^^^^^^^^^^^^^^^^^^^^^^^^^^^^^^^^^^\n../../.pythonlibs/lib/python3.11/site-packages/httpx/_transports/default.py:393: in handle_async_request\n    with map_httpcore_exceptions():\n/nix/store/7d088dip86hlzri9sk0h78b63yfmx0a0-python3-3.11.13/lib/python3.11/contextlib.py:158: in __exit__\n    self.gen.throw(typ, value, traceback)\n../../.pythonlibs/lib/python3.11/site-packages/httpx/_transports/default.py:118: in map_httpcore_exceptions\n    raise mapped_exc(message) from exc\nE   httpx.ConnectError: All connection attempts failed\n=========================== short test summary info ============================\nFAILED test_agent_wizard.py::TestAgentWizardService::test_health_endpoint - h...\nFAILED test_agent_wizard.py::TestAgentWizardService::test_create_agent_valid_data\nFAILED test_agent_wizard.py::TestAgentWizardService::test_create_agent_invalid_data\nFAILED test_agent_wizard.py::TestAgentWizardService::test_get_agents_list - h...\nFAILED test_agent_wizard.py::TestAgentWizardService::test_get_agent_by_id - h...\nFAILED test_agent_wizard.py::TestAgentWizardService::test_update_agent - http...\nFAILED test_agent_wizard.py::TestAgentWizardService::test_delete_agent - http...\nFAILED test_agent_wizard.py::TestAgentWizardService::test_system_prompt_generation\nFAILED test_agent_wizard.py::TestAgentWizardService::test_industry_metadata\nFAILED test_agent_wizard.py::TestAgentWizardService::test_llm_model_validation\nFAILED test_agent_wizard.py::TestAgentWizardService::test_chat_capabilities\nFAILED test_agent_wizard.py::test_performance_benchmarks - httpx.ConnectError...\n============================== 12 failed in 2.17s ==============================\n",
      "errors": ""
    },
    "my-agents": {
      "return_code": 1,
      "passed": false,
      "failed": true,
      "output": "============================= test session starts ==============================\nplatform linux -- Python 3.11.13, pytest-8.4.1, pluggy-1.6.0 -- /home/runner/workspace/.pythonlibs/bin/python3\ncachedir: .pytest_cache\nrootdir: /home/runner/workspace\nconfigfile: pyproject.toml\nplugins: anyio-4.9.0, asyncio-1.1.0\nasyncio: mode=Mode.AUTO, asyncio_default_fixture_loop_scope=None, asyncio_default_test_loop_scope=function\ncollecting ... collected 14 items\n\ntest_my_agents.py::TestMyAgentsService::test_health_endpoint FAILED      [  7%]\ntest_my_agents.py::TestMyAgentsService::test_get_agents_dashboard FAILED [ 14%]\ntest_my_agents.py::TestMyAgentsService::test_get_all_agents FAILED       [ 21%]\ntest_my_agents.py::TestMyAgentsService::test_get_agent_details FAILED    [ 28%]\ntest_my_agents.py::TestMyAgentsService::test_agent_status_operations FAILED [ 35%]\ntest_my_agents.py::TestMyAgentsService::test_bulk_operations FAILED      [ 42%]\ntest_my_agents.py::TestMyAgentsService::test_agent_metrics FAILED        [ 50%]\ntest_my_agents.py::TestMyAgentsService::test_status_history FAILED       [ 57%]\ntest_my_agents.py::TestMyAgentsService::test_agent_backups FAILED        [ 64%]\ntest_my_agents.py::TestMyAgentsService::test_update_agent FAILED         [ 71%]\ntest_my_agents.py::TestMyAgentsService::test_agent_archive_and_delete FAILED [ 78%]\ntest_my_agents.py::TestMyAgentsService::test_error_handling FAILED       [ 85%]\ntest_my_agents.py::TestMyAgentsService::test_pagination_and_filtering FAILED [ 92%]\ntest_my_agents.py::test_cross_service_communication FAILED               [100%]\n\n=================================== FAILURES ===================================\n___________________ TestMyAgentsService.test_health_endpoint ___________________\n../../.pythonlibs/lib/python3.11/site-packages/httpx/_transports/default.py:101: in map_httpcore_exceptions\n    yield\n../../.pythonlibs/lib/python3.11/site-packages/httpx/_transports/default.py:394: in handle_async_request\n    resp = await self._pool.handle_async_request(req)\n           ^^^^^^^^^^^^^^^^^^^^^^^^^^^^^^^^^^^^^^^^^^\n../../.pythonlibs/lib/python3.11/site-packages/httpcore/_async/connection_pool.py:256: in handle_async_request\n    raise exc from None\n../../.pythonlibs/lib/python3.11/site-packages/httpcore/_async/connection_pool.py:236: in handle_async_request\n    response = await connection.handle_async_request(\n../../.pythonlibs/lib/python3.11/site-packages/httpcore/_async/connection.py:101: in handle_async_request\n    raise exc\n../../.pythonlibs/lib/python3.11/site-packages/httpcore/_async/connection.py:78: in handle_async_request\n    stream = await self._connect(request)\n             ^^^^^^^^^^^^^^^^^^^^^^^^^^^^\n../../.pythonlibs/lib/python3.11/site-packages/httpcore/_async/connection.py:124: in _connect\n    stream = await self._network_backend.connect_tcp(**kwargs)\n             ^^^^^^^^^^^^^^^^^^^^^^^^^^^^^^^^^^^^^^^^^^^^^^^^^\n../../.pythonlibs/lib/python3.11/site-packages/httpcore/_backends/auto.py:31: in connect_tcp\n    return await self._backend.connect_tcp(\n../../.pythonlibs/lib/python3.11/site-packages/httpcore/_backends/anyio.py:113: in connect_tcp\n    with map_exceptions(exc_map):\n/nix/store/7d088dip86hlzri9sk0h78b63yfmx0a0-python3-3.11.13/lib/python3.11/contextlib.py:158: in __exit__\n    self.gen.throw(typ, value, traceback)\n../../.pythonlibs/lib/python3.11/site-packages/httpcore/_exceptions.py:14: in map_exceptions\n    raise to_exc(exc) from exc\nE   httpcore.ConnectError: All connection attempts failed\n\nThe above exception was the direct cause of the following exception:\ntest_my_agents.py:33: in test_health_endpoint\n    response = await client.get(\"/health\")\n               ^^^^^^^^^^^^^^^^^^^^^^^^^^^\n../../.pythonlibs/lib/python3.11/site-packages/httpx/_client.py:1768: in get\n    return await self.request(\n../../.pythonlibs/lib/python3.11/site-packages/httpx/_client.py:1540: in request\n    return await self.send(request, auth=auth, follow_redirects=follow_redirects)\n           ^^^^^^^^^^^^^^^^^^^^^^^^^^^^^^^^^^^^^^^^^^^^^^^^^^^^^^^^^^^^^^^^^^^^^^\n../../.pythonlibs/lib/python3.11/site-packages/httpx/_client.py:1629: in send\n    response = await self._send_handling_auth(\n../../.pythonlibs/lib/python3.11/site-packages/httpx/_client.py:1657: in _send_handling_auth\n    response = await self._send_handling_redirects(\n../../.pythonlibs/lib/python3.11/site-packages/httpx/_client.py:1694: in _send_handling_redirects\n    response = await self._send_single_request(request)\n               ^^^^^^^^^^^^^^^^^^^^^^^^^^^^^^^^^^^^^^^^\n../../.pythonlibs/lib/python3.11/site-packages/httpx/_client.py:1730: in _send_single_request\n    response = await transport.handle_async_request(request)\n               ^^^^^^^^^^^^^^^^^^^^^^^^^^^^^^^^^^^^^^^^^^^^^\n../../.pythonlibs/lib/python3.11/site-packages/httpx/_transports/default.py:393: in handle_async_request\n    with map_httpcore_exceptions():\n/nix/store/7d088dip86hlzri9sk0h78b63yfmx0a0-python3-3.11.13/lib/python3.11/contextlib.py:158: in __exit__\n    self.gen.throw(typ, value, traceback)\n../../.pythonlibs/lib/python3.11/site-packages/httpx/_transports/default.py:118: in map_httpcore_exceptions\n    raise mapped_exc(message) from exc\nE   httpx.ConnectError: All connection attempts failed\n________________ TestMyAgentsService.test_get_agents_dashboard _________________\n../../.pythonlibs/lib/python3.11/site-packages/httpx/_transports/default.py:101: in map_httpcore_exceptions\n    yield\n../../.pythonlibs/lib/python3.11/site-packages/httpx/_transports/default.py:394: in handle_async_request\n    resp = await self._pool.handle_async_request(req)\n           ^^^^^^^^^^^^^^^^^^^^^^^^^^^^^^^^^^^^^^^^^^\n../../.pythonlibs/lib/python3.11/site-packages/httpcore/_async/connection_pool.py:256: in handle_async_request\n    raise exc from None\n../../.pythonlibs/lib/python3.11/site-packages/httpcore/_async/connection_pool.py:236: in handle_async_request\n    response = await connection.handle_async_request(\n../../.pythonlibs/lib/python3.11/site-packages/httpcore/_async/connection.py:101: in handle_async_request\n    raise exc\n../../.pythonlibs/lib/python3.11/site-packages/httpcore/_async/connection.py:78: in handle_async_request\n    stream = await self._connect(request)\n             ^^^^^^^^^^^^^^^^^^^^^^^^^^^^\n../../.pythonlibs/lib/python3.11/site-packages/httpcore/_async/connection.py:124: in _connect\n    stream = await self._network_backend.connect_tcp(**kwargs)\n             ^^^^^^^^^^^^^^^^^^^^^^^^^^^^^^^^^^^^^^^^^^^^^^^^^\n../../.pythonlibs/lib/python3.11/site-packages/httpcore/_backends/auto.py:31: in connect_tcp\n    return await self._backend.connect_tcp(\n../../.pythonlibs/lib/python3.11/site-packages/httpcore/_backends/anyio.py:113: in connect_tcp\n    with map_exceptions(exc_map):\n/nix/store/7d088dip86hlzri9sk0h78b63yfmx0a0-python3-3.11.13/lib/python3.11/contextlib.py:158: in __exit__\n    self.gen.throw(typ, value, traceback)\n../../.pythonlibs/lib/python3.11/site-packages/httpcore/_exceptions.py:14: in map_exceptions\n    raise to_exc(exc) from exc\nE   httpcore.ConnectError: All connection attempts failed\n\nThe above exception was the direct cause of the following exception:\ntest_my_agents.py:44: in test_get_agents_dashboard\n    response = await client.get(\"/api/my-agents/dashboard\")\n               ^^^^^^^^^^^^^^^^^^^^^^^^^^^^^^^^^^^^^^^^^^^^\n../../.pythonlibs/lib/python3.11/site-packages/httpx/_client.py:1768: in get\n    return await self.request(\n../../.pythonlibs/lib/python3.11/site-packages/httpx/_client.py:1540: in request\n    return await self.send(request, auth=auth, follow_redirects=follow_redirects)\n           ^^^^^^^^^^^^^^^^^^^^^^^^^^^^^^^^^^^^^^^^^^^^^^^^^^^^^^^^^^^^^^^^^^^^^^\n../../.pythonlibs/lib/python3.11/site-packages/httpx/_client.py:1629: in send\n    response = await self._send_handling_auth(\n../../.pythonlibs/lib/python3.11/site-packages/httpx/_client.py:1657: in _send_handling_auth\n    response = await self._send_handling_redirects(\n../../.pythonlibs/lib/python3.11/site-packages/httpx/_client.py:1694: in _send_handling_redirects\n    response = await self._send_single_request(request)\n               ^^^^^^^^^^^^^^^^^^^^^^^^^^^^^^^^^^^^^^^^\n../../.pythonlibs/lib/python3.11/site-packages/httpx/_client.py:1730: in _send_single_request\n    response = await transport.handle_async_request(request)\n               ^^^^^^^^^^^^^^^^^^^^^^^^^^^^^^^^^^^^^^^^^^^^^\n../../.pythonlibs/lib/python3.11/site-packages/httpx/_transports/default.py:393: in handle_async_request\n    with map_httpcore_exceptions():\n/nix/store/7d088dip86hlzri9sk0h78b63yfmx0a0-python3-3.11.13/lib/python3.11/contextlib.py:158: in __exit__\n    self.gen.throw(typ, value, traceback)\n../../.pythonlibs/lib/python3.11/site-packages/httpx/_transports/default.py:118: in map_httpcore_exceptions\n    raise mapped_exc(message) from exc\nE   httpx.ConnectError: All connection attempts failed\n___________________ TestMyAgentsService.test_get_all_agents ____________________\n../../.pythonlibs/lib/python3.11/site-packages/httpx/_transports/default.py:101: in map_httpcore_exceptions\n    yield\n../../.pythonlibs/lib/python3.11/site-packages/httpx/_transports/default.py:394: in handle_async_request\n    resp = await self._pool.handle_async_request(req)\n           ^^^^^^^^^^^^^^^^^^^^^^^^^^^^^^^^^^^^^^^^^^\n../../.pythonlibs/lib/python3.11/site-packages/httpcore/_async/connection_pool.py:256: in handle_async_request\n    raise exc from None\n../../.pythonlibs/lib/python3.11/site-packages/httpcore/_async/connection_pool.py:236: in handle_async_request\n    response = await connection.handle_async_request(\n../../.pythonlibs/lib/python3.11/site-packages/httpcore/_async/connection.py:101: in handle_async_request\n    raise exc\n../../.pythonlibs/lib/python3.11/site-packages/httpcore/_async/connection.py:78: in handle_async_request\n    stream = await self._connect(request)\n             ^^^^^^^^^^^^^^^^^^^^^^^^^^^^\n../../.pythonlibs/lib/python3.11/site-packages/httpcore/_async/connection.py:124: in _connect\n    stream = await self._network_backend.connect_tcp(**kwargs)\n             ^^^^^^^^^^^^^^^^^^^^^^^^^^^^^^^^^^^^^^^^^^^^^^^^^\n../../.pythonlibs/lib/python3.11/site-packages/httpcore/_backends/auto.py:31: in connect_tcp\n    return await self._backend.connect_tcp(\n../../.pythonlibs/lib/python3.11/site-packages/httpcore/_backends/anyio.py:113: in connect_tcp\n    with map_exceptions(exc_map):\n/nix/store/7d088dip86hlzri9sk0h78b63yfmx0a0-python3-3.11.13/lib/python3.11/contextlib.py:158: in __exit__\n    self.gen.throw(typ, value, traceback)\n../../.pythonlibs/lib/python3.11/site-packages/httpcore/_exceptions.py:14: in map_exceptions\n    raise to_exc(exc) from exc\nE   httpcore.ConnectError: All connection attempts failed\n\nThe above exception was the direct cause of the following exception:\ntest_my_agents.py:61: in test_get_all_agents\n    response = await client.get(\"/api/my-agents\")\n               ^^^^^^^^^^^^^^^^^^^^^^^^^^^^^^^^^^\n../../.pythonlibs/lib/python3.11/site-packages/httpx/_client.py:1768: in get\n    return await self.request(\n../../.pythonlibs/lib/python3.11/site-packages/httpx/_client.py:1540: in request\n    return await self.send(request, auth=auth, follow_redirects=follow_redirects)\n           ^^^^^^^^^^^^^^^^^^^^^^^^^^^^^^^^^^^^^^^^^^^^^^^^^^^^^^^^^^^^^^^^^^^^^^\n../../.pythonlibs/lib/python3.11/site-packages/httpx/_client.py:1629: in send\n    response = await self._send_handling_auth(\n../../.pythonlibs/lib/python3.11/site-packages/httpx/_client.py:1657: in _send_handling_auth\n    response = await self._send_handling_redirects(\n../../.pythonlibs/lib/python3.11/site-packages/httpx/_client.py:1694: in _send_handling_redirects\n    response = await self._send_single_request(request)\n               ^^^^^^^^^^^^^^^^^^^^^^^^^^^^^^^^^^^^^^^^\n../../.pythonlibs/lib/python3.11/site-packages/httpx/_client.py:1730: in _send_single_request\n    response = await transport.handle_async_request(request)\n               ^^^^^^^^^^^^^^^^^^^^^^^^^^^^^^^^^^^^^^^^^^^^^\n../../.pythonlibs/lib/python3.11/site-packages/httpx/_transports/default.py:393: in handle_async_request\n    with map_httpcore_exceptions():\n/nix/store/7d088dip86hlzri9sk0h78b63yfmx0a0-python3-3.11.13/lib/python3.11/contextlib.py:158: in __exit__\n    self.gen.throw(typ, value, traceback)\n../../.pythonlibs/lib/python3.11/site-packages/httpx/_transports/default.py:118: in map_httpcore_exceptions\n    raise mapped_exc(message) from exc\nE   httpx.ConnectError: All connection attempts failed\n__________________ TestMyAgentsService.test_get_agent_details __________________\n../../.pythonlibs/lib/python3.11/site-packages/httpx/_transports/default.py:101: in map_httpcore_exceptions\n    yield\n../../.pythonlibs/lib/python3.11/site-packages/httpx/_transports/default.py:394: in handle_async_request\n    resp = await self._pool.handle_async_request(req)\n           ^^^^^^^^^^^^^^^^^^^^^^^^^^^^^^^^^^^^^^^^^^\n../../.pythonlibs/lib/python3.11/site-packages/httpcore/_async/connection_pool.py:256: in handle_async_request\n    raise exc from None\n../../.pythonlibs/lib/python3.11/site-packages/httpcore/_async/connection_pool.py:236: in handle_async_request\n    response = await connection.handle_async_request(\n../../.pythonlibs/lib/python3.11/site-packages/httpcore/_async/connection.py:101: in handle_async_request\n    raise exc\n../../.pythonlibs/lib/python3.11/site-packages/httpcore/_async/connection.py:78: in handle_async_request\n    stream = await self._connect(request)\n             ^^^^^^^^^^^^^^^^^^^^^^^^^^^^\n../../.pythonlibs/lib/python3.11/site-packages/httpcore/_async/connection.py:124: in _connect\n    stream = await self._network_backend.connect_tcp(**kwargs)\n             ^^^^^^^^^^^^^^^^^^^^^^^^^^^^^^^^^^^^^^^^^^^^^^^^^\n../../.pythonlibs/lib/python3.11/site-packages/httpcore/_backends/auto.py:31: in connect_tcp\n    return await self._backend.connect_tcp(\n../../.pythonlibs/lib/python3.11/site-packages/httpcore/_backends/anyio.py:113: in connect_tcp\n    with map_exceptions(exc_map):\n/nix/store/7d088dip86hlzri9sk0h78b63yfmx0a0-python3-3.11.13/lib/python3.11/contextlib.py:158: in __exit__\n    self.gen.throw(typ, value, traceback)\n../../.pythonlibs/lib/python3.11/site-packages/httpcore/_exceptions.py:14: in map_exceptions\n    raise to_exc(exc) from exc\nE   httpcore.ConnectError: All connection attempts failed\n\nThe above exception was the direct cause of the following exception:\ntest_my_agents.py:77: in test_get_agent_details\n    response = await client.get(\"/api/my-agents/agent-1\")\n               ^^^^^^^^^^^^^^^^^^^^^^^^^^^^^^^^^^^^^^^^^^\n../../.pythonlibs/lib/python3.11/site-packages/httpx/_client.py:1768: in get\n    return await self.request(\n../../.pythonlibs/lib/python3.11/site-packages/httpx/_client.py:1540: in request\n    return await self.send(request, auth=auth, follow_redirects=follow_redirects)\n           ^^^^^^^^^^^^^^^^^^^^^^^^^^^^^^^^^^^^^^^^^^^^^^^^^^^^^^^^^^^^^^^^^^^^^^\n../../.pythonlibs/lib/python3.11/site-packages/httpx/_client.py:1629: in send\n    response = await self._send_handling_auth(\n../../.pythonlibs/lib/python3.11/site-packages/httpx/_client.py:1657: in _send_handling_auth\n    response = await self._send_handling_redirects(\n../../.pythonlibs/lib/python3.11/site-packages/httpx/_client.py:1694: in _send_handling_redirects\n    response = await self._send_single_request(request)\n               ^^^^^^^^^^^^^^^^^^^^^^^^^^^^^^^^^^^^^^^^\n../../.pythonlibs/lib/python3.11/site-packages/httpx/_client.py:1730: in _send_single_request\n    response = await transport.handle_async_request(request)\n               ^^^^^^^^^^^^^^^^^^^^^^^^^^^^^^^^^^^^^^^^^^^^^\n../../.pythonlibs/lib/python3.11/site-packages/httpx/_transports/default.py:393: in handle_async_request\n    with map_httpcore_exceptions():\n/nix/store/7d088dip86hlzri9sk0h78b63yfmx0a0-python3-3.11.13/lib/python3.11/contextlib.py:158: in __exit__\n    self.gen.throw(typ, value, traceback)\n../../.pythonlibs/lib/python3.11/site-packages/httpx/_transports/default.py:118: in map_httpcore_exceptions\n    raise mapped_exc(message) from exc\nE   httpx.ConnectError: All connection attempts failed\n_______________ TestMyAgentsService.test_agent_status_operations _______________\n../../.pythonlibs/lib/python3.11/site-packages/httpx/_transports/default.py:101: in map_httpcore_exceptions\n    yield\n../../.pythonlibs/lib/python3.11/site-packages/httpx/_transports/default.py:394: in handle_async_request\n    resp = await self._pool.handle_async_request(req)\n           ^^^^^^^^^^^^^^^^^^^^^^^^^^^^^^^^^^^^^^^^^^\n../../.pythonlibs/lib/python3.11/site-packages/httpcore/_async/connection_pool.py:256: in handle_async_request\n    raise exc from None\n../../.pythonlibs/lib/python3.11/site-packages/httpcore/_async/connection_pool.py:236: in handle_async_request\n    response = await connection.handle_async_request(\n../../.pythonlibs/lib/python3.11/site-packages/httpcore/_async/connection.py:101: in handle_async_request\n    raise exc\n../../.pythonlibs/lib/python3.11/site-packages/httpcore/_async/connection.py:78: in handle_async_request\n    stream = await self._connect(request)\n             ^^^^^^^^^^^^^^^^^^^^^^^^^^^^\n../../.pythonlibs/lib/python3.11/site-packages/httpcore/_async/connection.py:124: in _connect\n    stream = await self._network_backend.connect_tcp(**kwargs)\n             ^^^^^^^^^^^^^^^^^^^^^^^^^^^^^^^^^^^^^^^^^^^^^^^^^\n../../.pythonlibs/lib/python3.11/site-packages/httpcore/_backends/auto.py:31: in connect_tcp\n    return await self._backend.connect_tcp(\n../../.pythonlibs/lib/python3.11/site-packages/httpcore/_backends/anyio.py:113: in connect_tcp\n    with map_exceptions(exc_map):\n/nix/store/7d088dip86hlzri9sk0h78b63yfmx0a0-python3-3.11.13/lib/python3.11/contextlib.py:158: in __exit__\n    self.gen.throw(typ, value, traceback)\n../../.pythonlibs/lib/python3.11/site-packages/httpcore/_exceptions.py:14: in map_exceptions\n    raise to_exc(exc) from exc\nE   httpcore.ConnectError: All connection attempts failed\n\nThe above exception was the direct cause of the following exception:\ntest_my_agents.py:91: in test_agent_status_operations\n    response = await client.post(f\"/api/my-agents/{agent_id}/enable\")\n               ^^^^^^^^^^^^^^^^^^^^^^^^^^^^^^^^^^^^^^^^^^^^^^^^^^^^^^\n../../.pythonlibs/lib/python3.11/site-packages/httpx/_client.py:1859: in post\n    return await self.request(\n../../.pythonlibs/lib/python3.11/site-packages/httpx/_client.py:1540: in request\n    return await self.send(request, auth=auth, follow_redirects=follow_redirects)\n           ^^^^^^^^^^^^^^^^^^^^^^^^^^^^^^^^^^^^^^^^^^^^^^^^^^^^^^^^^^^^^^^^^^^^^^\n../../.pythonlibs/lib/python3.11/site-packages/httpx/_client.py:1629: in send\n    response = await self._send_handling_auth(\n../../.pythonlibs/lib/python3.11/site-packages/httpx/_client.py:1657: in _send_handling_auth\n    response = await self._send_handling_redirects(\n../../.pythonlibs/lib/python3.11/site-packages/httpx/_client.py:1694: in _send_handling_redirects\n    response = await self._send_single_request(request)\n               ^^^^^^^^^^^^^^^^^^^^^^^^^^^^^^^^^^^^^^^^\n../../.pythonlibs/lib/python3.11/site-packages/httpx/_client.py:1730: in _send_single_request\n    response = await transport.handle_async_request(request)\n               ^^^^^^^^^^^^^^^^^^^^^^^^^^^^^^^^^^^^^^^^^^^^^\n../../.pythonlibs/lib/python3.11/site-packages/httpx/_transports/default.py:393: in handle_async_request\n    with map_httpcore_exceptions():\n/nix/store/7d088dip86hlzri9sk0h78b63yfmx0a0-python3-3.11.13/lib/python3.11/contextlib.py:158: in __exit__\n    self.gen.throw(typ, value, traceback)\n../../.pythonlibs/lib/python3.11/site-packages/httpx/_transports/default.py:118: in map_httpcore_exceptions\n    raise mapped_exc(message) from exc\nE   httpx.ConnectError: All connection attempts failed\n___________________ TestMyAgentsService.test_bulk_operations ___________________\n../../.pythonlibs/lib/python3.11/site-packages/httpx/_transports/default.py:101: in map_httpcore_exceptions\n    yield\n../../.pythonlibs/lib/python3.11/site-packages/httpx/_transports/default.py:394: in handle_async_request\n    resp = await self._pool.handle_async_request(req)\n           ^^^^^^^^^^^^^^^^^^^^^^^^^^^^^^^^^^^^^^^^^^\n../../.pythonlibs/lib/python3.11/site-packages/httpcore/_async/connection_pool.py:256: in handle_async_request\n    raise exc from None\n../../.pythonlibs/lib/python3.11/site-packages/httpcore/_async/connection_pool.py:236: in handle_async_request\n    response = await connection.handle_async_request(\n../../.pythonlibs/lib/python3.11/site-packages/httpcore/_async/connection.py:101: in handle_async_request\n    raise exc\n../../.pythonlibs/lib/python3.11/site-packages/httpcore/_async/connection.py:78: in handle_async_request\n    stream = await self._connect(request)\n             ^^^^^^^^^^^^^^^^^^^^^^^^^^^^\n../../.pythonlibs/lib/python3.11/site-packages/httpcore/_async/connection.py:124: in _connect\n    stream = await self._network_backend.connect_tcp(**kwargs)\n             ^^^^^^^^^^^^^^^^^^^^^^^^^^^^^^^^^^^^^^^^^^^^^^^^^\n../../.pythonlibs/lib/python3.11/site-packages/httpcore/_backends/auto.py:31: in connect_tcp\n    return await self._backend.connect_tcp(\n../../.pythonlibs/lib/python3.11/site-packages/httpcore/_backends/anyio.py:113: in connect_tcp\n    with map_exceptions(exc_map):\n/nix/store/7d088dip86hlzri9sk0h78b63yfmx0a0-python3-3.11.13/lib/python3.11/contextlib.py:158: in __exit__\n    self.gen.throw(typ, value, traceback)\n../../.pythonlibs/lib/python3.11/site-packages/httpcore/_exceptions.py:14: in map_exceptions\n    raise to_exc(exc) from exc\nE   httpcore.ConnectError: All connection attempts failed\n\nThe above exception was the direct cause of the following exception:\ntest_my_agents.py:111: in test_bulk_operations\n    response = await client.post(\"/api/my-agents/bulk\", json=bulk_data)\n               ^^^^^^^^^^^^^^^^^^^^^^^^^^^^^^^^^^^^^^^^^^^^^^^^^^^^^^^^\n../../.pythonlibs/lib/python3.11/site-packages/httpx/_client.py:1859: in post\n    return await self.request(\n../../.pythonlibs/lib/python3.11/site-packages/httpx/_client.py:1540: in request\n    return await self.send(request, auth=auth, follow_redirects=follow_redirects)\n           ^^^^^^^^^^^^^^^^^^^^^^^^^^^^^^^^^^^^^^^^^^^^^^^^^^^^^^^^^^^^^^^^^^^^^^\n../../.pythonlibs/lib/python3.11/site-packages/httpx/_client.py:1629: in send\n    response = await self._send_handling_auth(\n../../.pythonlibs/lib/python3.11/site-packages/httpx/_client.py:1657: in _send_handling_auth\n    response = await self._send_handling_redirects(\n../../.pythonlibs/lib/python3.11/site-packages/httpx/_client.py:1694: in _send_handling_redirects\n    response = await self._send_single_request(request)\n               ^^^^^^^^^^^^^^^^^^^^^^^^^^^^^^^^^^^^^^^^\n../../.pythonlibs/lib/python3.11/site-packages/httpx/_client.py:1730: in _send_single_request\n    response = await transport.handle_async_request(request)\n               ^^^^^^^^^^^^^^^^^^^^^^^^^^^^^^^^^^^^^^^^^^^^^\n../../.pythonlibs/lib/python3.11/site-packages/httpx/_transports/default.py:393: in handle_async_request\n    with map_httpcore_exceptions():\n/nix/store/7d088dip86hlzri9sk0h78b63yfmx0a0-python3-3.11.13/lib/python3.11/contextlib.py:158: in __exit__\n    self.gen.throw(typ, value, traceback)\n../../.pythonlibs/lib/python3.11/site-packages/httpx/_transports/default.py:118: in map_httpcore_exceptions\n    raise mapped_exc(message) from exc\nE   httpx.ConnectError: All connection attempts failed\n____________________ TestMyAgentsService.test_agent_metrics ____________________\n../../.pythonlibs/lib/python3.11/site-packages/httpx/_transports/default.py:101: in map_httpcore_exceptions\n    yield\n../../.pythonlibs/lib/python3.11/site-packages/httpx/_transports/default.py:394: in handle_async_request\n    resp = await self._pool.handle_async_request(req)\n           ^^^^^^^^^^^^^^^^^^^^^^^^^^^^^^^^^^^^^^^^^^\n../../.pythonlibs/lib/python3.11/site-packages/httpcore/_async/connection_pool.py:256: in handle_async_request\n    raise exc from None\n../../.pythonlibs/lib/python3.11/site-packages/httpcore/_async/connection_pool.py:236: in handle_async_request\n    response = await connection.handle_async_request(\n../../.pythonlibs/lib/python3.11/site-packages/httpcore/_async/connection.py:101: in handle_async_request\n    raise exc\n../../.pythonlibs/lib/python3.11/site-packages/httpcore/_async/connection.py:78: in handle_async_request\n    stream = await self._connect(request)\n             ^^^^^^^^^^^^^^^^^^^^^^^^^^^^\n../../.pythonlibs/lib/python3.11/site-packages/httpcore/_async/connection.py:124: in _connect\n    stream = await self._network_backend.connect_tcp(**kwargs)\n             ^^^^^^^^^^^^^^^^^^^^^^^^^^^^^^^^^^^^^^^^^^^^^^^^^\n../../.pythonlibs/lib/python3.11/site-packages/httpcore/_backends/auto.py:31: in connect_tcp\n    return await self._backend.connect_tcp(\n../../.pythonlibs/lib/python3.11/site-packages/httpcore/_backends/anyio.py:113: in connect_tcp\n    with map_exceptions(exc_map):\n/nix/store/7d088dip86hlzri9sk0h78b63yfmx0a0-python3-3.11.13/lib/python3.11/contextlib.py:158: in __exit__\n    self.gen.throw(typ, value, traceback)\n../../.pythonlibs/lib/python3.11/site-packages/httpcore/_exceptions.py:14: in map_exceptions\n    raise to_exc(exc) from exc\nE   httpcore.ConnectError: All connection attempts failed\n\nThe above exception was the direct cause of the following exception:\ntest_my_agents.py:125: in test_agent_metrics\n    response = await client.get(f\"/api/my-agents/{agent_id}/metrics\")\n               ^^^^^^^^^^^^^^^^^^^^^^^^^^^^^^^^^^^^^^^^^^^^^^^^^^^^^^\n../../.pythonlibs/lib/python3.11/site-packages/httpx/_client.py:1768: in get\n    return await self.request(\n../../.pythonlibs/lib/python3.11/site-packages/httpx/_client.py:1540: in request\n    return await self.send(request, auth=auth, follow_redirects=follow_redirects)\n           ^^^^^^^^^^^^^^^^^^^^^^^^^^^^^^^^^^^^^^^^^^^^^^^^^^^^^^^^^^^^^^^^^^^^^^\n../../.pythonlibs/lib/python3.11/site-packages/httpx/_client.py:1629: in send\n    response = await self._send_handling_auth(\n../../.pythonlibs/lib/python3.11/site-packages/httpx/_client.py:1657: in _send_handling_auth\n    response = await self._send_handling_redirects(\n../../.pythonlibs/lib/python3.11/site-packages/httpx/_client.py:1694: in _send_handling_redirects\n    response = await self._send_single_request(request)\n               ^^^^^^^^^^^^^^^^^^^^^^^^^^^^^^^^^^^^^^^^\n../../.pythonlibs/lib/python3.11/site-packages/httpx/_client.py:1730: in _send_single_request\n    response = await transport.handle_async_request(request)\n               ^^^^^^^^^^^^^^^^^^^^^^^^^^^^^^^^^^^^^^^^^^^^^\n../../.pythonlibs/lib/python3.11/site-packages/httpx/_transports/default.py:393: in handle_async_request\n    with map_httpcore_exceptions():\n/nix/store/7d088dip86hlzri9sk0h78b63yfmx0a0-python3-3.11.13/lib/python3.11/contextlib.py:158: in __exit__\n    self.gen.throw(typ, value, traceback)\n../../.pythonlibs/lib/python3.11/site-packages/httpx/_transports/default.py:118: in map_httpcore_exceptions\n    raise mapped_exc(message) from exc\nE   httpx.ConnectError: All connection attempts failed\n___________________ TestMyAgentsService.test_status_history ____________________\n../../.pythonlibs/lib/python3.11/site-packages/httpx/_transports/default.py:101: in map_httpcore_exceptions\n    yield\n../../.pythonlibs/lib/python3.11/site-packages/httpx/_transports/default.py:394: in handle_async_request\n    resp = await self._pool.handle_async_request(req)\n           ^^^^^^^^^^^^^^^^^^^^^^^^^^^^^^^^^^^^^^^^^^\n../../.pythonlibs/lib/python3.11/site-packages/httpcore/_async/connection_pool.py:256: in handle_async_request\n    raise exc from None\n../../.pythonlibs/lib/python3.11/site-packages/httpcore/_async/connection_pool.py:236: in handle_async_request\n    response = await connection.handle_async_request(\n../../.pythonlibs/lib/python3.11/site-packages/httpcore/_async/connection.py:101: in handle_async_request\n    raise exc\n../../.pythonlibs/lib/python3.11/site-packages/httpcore/_async/connection.py:78: in handle_async_request\n    stream = await self._connect(request)\n             ^^^^^^^^^^^^^^^^^^^^^^^^^^^^\n../../.pythonlibs/lib/python3.11/site-packages/httpcore/_async/connection.py:124: in _connect\n    stream = await self._network_backend.connect_tcp(**kwargs)\n             ^^^^^^^^^^^^^^^^^^^^^^^^^^^^^^^^^^^^^^^^^^^^^^^^^\n../../.pythonlibs/lib/python3.11/site-packages/httpcore/_backends/auto.py:31: in connect_tcp\n    return await self._backend.connect_tcp(\n../../.pythonlibs/lib/python3.11/site-packages/httpcore/_backends/anyio.py:113: in connect_tcp\n    with map_exceptions(exc_map):\n/nix/store/7d088dip86hlzri9sk0h78b63yfmx0a0-python3-3.11.13/lib/python3.11/contextlib.py:158: in __exit__\n    self.gen.throw(typ, value, traceback)\n../../.pythonlibs/lib/python3.11/site-packages/httpcore/_exceptions.py:14: in map_exceptions\n    raise to_exc(exc) from exc\nE   httpcore.ConnectError: All connection attempts failed\n\nThe above exception was the direct cause of the following exception:\ntest_my_agents.py:140: in test_status_history\n    response = await client.get(f\"/api/my-agents/{agent_id}/status-history\")\n               ^^^^^^^^^^^^^^^^^^^^^^^^^^^^^^^^^^^^^^^^^^^^^^^^^^^^^^^^^^^^^\n../../.pythonlibs/lib/python3.11/site-packages/httpx/_client.py:1768: in get\n    return await self.request(\n../../.pythonlibs/lib/python3.11/site-packages/httpx/_client.py:1540: in request\n    return await self.send(request, auth=auth, follow_redirects=follow_redirects)\n           ^^^^^^^^^^^^^^^^^^^^^^^^^^^^^^^^^^^^^^^^^^^^^^^^^^^^^^^^^^^^^^^^^^^^^^\n../../.pythonlibs/lib/python3.11/site-packages/httpx/_client.py:1629: in send\n    response = await self._send_handling_auth(\n../../.pythonlibs/lib/python3.11/site-packages/httpx/_client.py:1657: in _send_handling_auth\n    response = await self._send_handling_redirects(\n../../.pythonlibs/lib/python3.11/site-packages/httpx/_client.py:1694: in _send_handling_redirects\n    response = await self._send_single_request(request)\n               ^^^^^^^^^^^^^^^^^^^^^^^^^^^^^^^^^^^^^^^^\n../../.pythonlibs/lib/python3.11/site-packages/httpx/_client.py:1730: in _send_single_request\n    response = await transport.handle_async_request(request)\n               ^^^^^^^^^^^^^^^^^^^^^^^^^^^^^^^^^^^^^^^^^^^^^\n../../.pythonlibs/lib/python3.11/site-packages/httpx/_transports/default.py:393: in handle_async_request\n    with map_httpcore_exceptions():\n/nix/store/7d088dip86hlzri9sk0h78b63yfmx0a0-python3-3.11.13/lib/python3.11/contextlib.py:158: in __exit__\n    self.gen.throw(typ, value, traceback)\n../../.pythonlibs/lib/python3.11/site-packages/httpx/_transports/default.py:118: in map_httpcore_exceptions\n    raise mapped_exc(message) from exc\nE   httpx.ConnectError: All connection attempts failed\n____________________ TestMyAgentsService.test_agent_backups ____________________\n../../.pythonlibs/lib/python3.11/site-packages/httpx/_transports/default.py:101: in map_httpcore_exceptions\n    yield\n../../.pythonlibs/lib/python3.11/site-packages/httpx/_transports/default.py:394: in handle_async_request\n    resp = await self._pool.handle_async_request(req)\n           ^^^^^^^^^^^^^^^^^^^^^^^^^^^^^^^^^^^^^^^^^^\n../../.pythonlibs/lib/python3.11/site-packages/httpcore/_async/connection_pool.py:256: in handle_async_request\n    raise exc from None\n../../.pythonlibs/lib/python3.11/site-packages/httpcore/_async/connection_pool.py:236: in handle_async_request\n    response = await connection.handle_async_request(\n../../.pythonlibs/lib/python3.11/site-packages/httpcore/_async/connection.py:101: in handle_async_request\n    raise exc\n../../.pythonlibs/lib/python3.11/site-packages/httpcore/_async/connection.py:78: in handle_async_request\n    stream = await self._connect(request)\n             ^^^^^^^^^^^^^^^^^^^^^^^^^^^^\n../../.pythonlibs/lib/python3.11/site-packages/httpcore/_async/connection.py:124: in _connect\n    stream = await self._network_backend.connect_tcp(**kwargs)\n             ^^^^^^^^^^^^^^^^^^^^^^^^^^^^^^^^^^^^^^^^^^^^^^^^^\n../../.pythonlibs/lib/python3.11/site-packages/httpcore/_backends/auto.py:31: in connect_tcp\n    return await self._backend.connect_tcp(\n../../.pythonlibs/lib/python3.11/site-packages/httpcore/_backends/anyio.py:113: in connect_tcp\n    with map_exceptions(exc_map):\n/nix/store/7d088dip86hlzri9sk0h78b63yfmx0a0-python3-3.11.13/lib/python3.11/contextlib.py:158: in __exit__\n    self.gen.throw(typ, value, traceback)\n../../.pythonlibs/lib/python3.11/site-packages/httpcore/_exceptions.py:14: in map_exceptions\n    raise to_exc(exc) from exc\nE   httpcore.ConnectError: All connection attempts failed\n\nThe above exception was the direct cause of the following exception:\ntest_my_agents.py:153: in test_agent_backups\n    response = await client.get(f\"/api/my-agents/{agent_id}/backups\")\n               ^^^^^^^^^^^^^^^^^^^^^^^^^^^^^^^^^^^^^^^^^^^^^^^^^^^^^^\n../../.pythonlibs/lib/python3.11/site-packages/httpx/_client.py:1768: in get\n    return await self.request(\n../../.pythonlibs/lib/python3.11/site-packages/httpx/_client.py:1540: in request\n    return await self.send(request, auth=auth, follow_redirects=follow_redirects)\n           ^^^^^^^^^^^^^^^^^^^^^^^^^^^^^^^^^^^^^^^^^^^^^^^^^^^^^^^^^^^^^^^^^^^^^^\n../../.pythonlibs/lib/python3.11/site-packages/httpx/_client.py:1629: in send\n    response = await self._send_handling_auth(\n../../.pythonlibs/lib/python3.11/site-packages/httpx/_client.py:1657: in _send_handling_auth\n    response = await self._send_handling_redirects(\n../../.pythonlibs/lib/python3.11/site-packages/httpx/_client.py:1694: in _send_handling_redirects\n    response = await self._send_single_request(request)\n               ^^^^^^^^^^^^^^^^^^^^^^^^^^^^^^^^^^^^^^^^\n../../.pythonlibs/lib/python3.11/site-packages/httpx/_client.py:1730: in _send_single_request\n    response = await transport.handle_async_request(request)\n               ^^^^^^^^^^^^^^^^^^^^^^^^^^^^^^^^^^^^^^^^^^^^^\n../../.pythonlibs/lib/python3.11/site-packages/httpx/_transports/default.py:393: in handle_async_request\n    with map_httpcore_exceptions():\n/nix/store/7d088dip86hlzri9sk0h78b63yfmx0a0-python3-3.11.13/lib/python3.11/contextlib.py:158: in __exit__\n    self.gen.throw(typ, value, traceback)\n../../.pythonlibs/lib/python3.11/site-packages/httpx/_transports/default.py:118: in map_httpcore_exceptions\n    raise mapped_exc(message) from exc\nE   httpx.ConnectError: All connection attempts failed\n____________________ TestMyAgentsService.test_update_agent _____________________\n../../.pythonlibs/lib/python3.11/site-packages/httpx/_transports/default.py:101: in map_httpcore_exceptions\n    yield\n../../.pythonlibs/lib/python3.11/site-packages/httpx/_transports/default.py:394: in handle_async_request\n    resp = await self._pool.handle_async_request(req)\n           ^^^^^^^^^^^^^^^^^^^^^^^^^^^^^^^^^^^^^^^^^^\n../../.pythonlibs/lib/python3.11/site-packages/httpcore/_async/connection_pool.py:256: in handle_async_request\n    raise exc from None\n../../.pythonlibs/lib/python3.11/site-packages/httpcore/_async/connection_pool.py:236: in handle_async_request\n    response = await connection.handle_async_request(\n../../.pythonlibs/lib/python3.11/site-packages/httpcore/_async/connection.py:101: in handle_async_request\n    raise exc\n../../.pythonlibs/lib/python3.11/site-packages/httpcore/_async/connection.py:78: in handle_async_request\n    stream = await self._connect(request)\n             ^^^^^^^^^^^^^^^^^^^^^^^^^^^^\n../../.pythonlibs/lib/python3.11/site-packages/httpcore/_async/connection.py:124: in _connect\n    stream = await self._network_backend.connect_tcp(**kwargs)\n             ^^^^^^^^^^^^^^^^^^^^^^^^^^^^^^^^^^^^^^^^^^^^^^^^^\n../../.pythonlibs/lib/python3.11/site-packages/httpcore/_backends/auto.py:31: in connect_tcp\n    return await self._backend.connect_tcp(\n../../.pythonlibs/lib/python3.11/site-packages/httpcore/_backends/anyio.py:113: in connect_tcp\n    with map_exceptions(exc_map):\n/nix/store/7d088dip86hlzri9sk0h78b63yfmx0a0-python3-3.11.13/lib/python3.11/contextlib.py:158: in __exit__\n    self.gen.throw(typ, value, traceback)\n../../.pythonlibs/lib/python3.11/site-packages/httpcore/_exceptions.py:14: in map_exceptions\n    raise to_exc(exc) from exc\nE   httpcore.ConnectError: All connection attempts failed\n\nThe above exception was the direct cause of the following exception:\ntest_my_agents.py:164: in test_update_agent\n    response = await client.patch(f\"/api/my-agents/{agent_id}\", json=sample_agent_update)\n               ^^^^^^^^^^^^^^^^^^^^^^^^^^^^^^^^^^^^^^^^^^^^^^^^^^^^^^^^^^^^^^^^^^^^^^^^^^\n../../.pythonlibs/lib/python3.11/site-packages/httpx/_client.py:1933: in patch\n    return await self.request(\n../../.pythonlibs/lib/python3.11/site-packages/httpx/_client.py:1540: in request\n    return await self.send(request, auth=auth, follow_redirects=follow_redirects)\n           ^^^^^^^^^^^^^^^^^^^^^^^^^^^^^^^^^^^^^^^^^^^^^^^^^^^^^^^^^^^^^^^^^^^^^^\n../../.pythonlibs/lib/python3.11/site-packages/httpx/_client.py:1629: in send\n    response = await self._send_handling_auth(\n../../.pythonlibs/lib/python3.11/site-packages/httpx/_client.py:1657: in _send_handling_auth\n    response = await self._send_handling_redirects(\n../../.pythonlibs/lib/python3.11/site-packages/httpx/_client.py:1694: in _send_handling_redirects\n    response = await self._send_single_request(request)\n               ^^^^^^^^^^^^^^^^^^^^^^^^^^^^^^^^^^^^^^^^\n../../.pythonlibs/lib/python3.11/site-packages/httpx/_client.py:1730: in _send_single_request\n    response = await transport.handle_async_request(request)\n               ^^^^^^^^^^^^^^^^^^^^^^^^^^^^^^^^^^^^^^^^^^^^^\n../../.pythonlibs/lib/python3.11/site-packages/httpx/_transports/default.py:393: in handle_async_request\n    with map_httpcore_exceptions():\n/nix/store/7d088dip86hlzri9sk0h78b63yfmx0a0-python3-3.11.13/lib/python3.11/contextlib.py:158: in __exit__\n    self.gen.throw(typ, value, traceback)\n../../.pythonlibs/lib/python3.11/site-packages/httpx/_transports/default.py:118: in map_httpcore_exceptions\n    raise mapped_exc(message) from exc\nE   httpx.ConnectError: All connection attempts failed\n______________ TestMyAgentsService.test_agent_archive_and_delete _______________\n../../.pythonlibs/lib/python3.11/site-packages/httpx/_transports/default.py:101: in map_httpcore_exceptions\n    yield\n../../.pythonlibs/lib/python3.11/site-packages/httpx/_transports/default.py:394: in handle_async_request\n    resp = await self._pool.handle_async_request(req)\n           ^^^^^^^^^^^^^^^^^^^^^^^^^^^^^^^^^^^^^^^^^^\n../../.pythonlibs/lib/python3.11/site-packages/httpcore/_async/connection_pool.py:256: in handle_async_request\n    raise exc from None\n../../.pythonlibs/lib/python3.11/site-packages/httpcore/_async/connection_pool.py:236: in handle_async_request\n    response = await connection.handle_async_request(\n../../.pythonlibs/lib/python3.11/site-packages/httpcore/_async/connection.py:101: in handle_async_request\n    raise exc\n../../.pythonlibs/lib/python3.11/site-packages/httpcore/_async/connection.py:78: in handle_async_request\n    stream = await self._connect(request)\n             ^^^^^^^^^^^^^^^^^^^^^^^^^^^^\n../../.pythonlibs/lib/python3.11/site-packages/httpcore/_async/connection.py:124: in _connect\n    stream = await self._network_backend.connect_tcp(**kwargs)\n             ^^^^^^^^^^^^^^^^^^^^^^^^^^^^^^^^^^^^^^^^^^^^^^^^^\n../../.pythonlibs/lib/python3.11/site-packages/httpcore/_backends/auto.py:31: in connect_tcp\n    return await self._backend.connect_tcp(\n../../.pythonlibs/lib/python3.11/site-packages/httpcore/_backends/anyio.py:113: in connect_tcp\n    with map_exceptions(exc_map):\n/nix/store/7d088dip86hlzri9sk0h78b63yfmx0a0-python3-3.11.13/lib/python3.11/contextlib.py:158: in __exit__\n    self.gen.throw(typ, value, traceback)\n../../.pythonlibs/lib/python3.11/site-packages/httpcore/_exceptions.py:14: in map_exceptions\n    raise to_exc(exc) from exc\nE   httpcore.ConnectError: All connection attempts failed\n\nThe above exception was the direct cause of the following exception:\ntest_my_agents.py:174: in test_agent_archive_and_delete\n    response = await client.post(f\"/api/my-agents/{agent_id}/archive\")\n               ^^^^^^^^^^^^^^^^^^^^^^^^^^^^^^^^^^^^^^^^^^^^^^^^^^^^^^^\n../../.pythonlibs/lib/python3.11/site-packages/httpx/_client.py:1859: in post\n    return await self.request(\n../../.pythonlibs/lib/python3.11/site-packages/httpx/_client.py:1540: in request\n    return await self.send(request, auth=auth, follow_redirects=follow_redirects)\n           ^^^^^^^^^^^^^^^^^^^^^^^^^^^^^^^^^^^^^^^^^^^^^^^^^^^^^^^^^^^^^^^^^^^^^^\n../../.pythonlibs/lib/python3.11/site-packages/httpx/_client.py:1629: in send\n    response = await self._send_handling_auth(\n../../.pythonlibs/lib/python3.11/site-packages/httpx/_client.py:1657: in _send_handling_auth\n    response = await self._send_handling_redirects(\n../../.pythonlibs/lib/python3.11/site-packages/httpx/_client.py:1694: in _send_handling_redirects\n    response = await self._send_single_request(request)\n               ^^^^^^^^^^^^^^^^^^^^^^^^^^^^^^^^^^^^^^^^\n../../.pythonlibs/lib/python3.11/site-packages/httpx/_client.py:1730: in _send_single_request\n    response = await transport.handle_async_request(request)\n               ^^^^^^^^^^^^^^^^^^^^^^^^^^^^^^^^^^^^^^^^^^^^^\n../../.pythonlibs/lib/python3.11/site-packages/httpx/_transports/default.py:393: in handle_async_request\n    with map_httpcore_exceptions():\n/nix/store/7d088dip86hlzri9sk0h78b63yfmx0a0-python3-3.11.13/lib/python3.11/contextlib.py:158: in __exit__\n    self.gen.throw(typ, value, traceback)\n../../.pythonlibs/lib/python3.11/site-packages/httpx/_transports/default.py:118: in map_httpcore_exceptions\n    raise mapped_exc(message) from exc\nE   httpx.ConnectError: All connection attempts failed\n___________________ TestMyAgentsService.test_error_handling ____________________\n../../.pythonlibs/lib/python3.11/site-packages/httpx/_transports/default.py:101: in map_httpcore_exceptions\n    yield\n../../.pythonlibs/lib/python3.11/site-packages/httpx/_transports/default.py:394: in handle_async_request\n    resp = await self._pool.handle_async_request(req)\n           ^^^^^^^^^^^^^^^^^^^^^^^^^^^^^^^^^^^^^^^^^^\n../../.pythonlibs/lib/python3.11/site-packages/httpcore/_async/connection_pool.py:256: in handle_async_request\n    raise exc from None\n../../.pythonlibs/lib/python3.11/site-packages/httpcore/_async/connection_pool.py:236: in handle_async_request\n    response = await connection.handle_async_request(\n../../.pythonlibs/lib/python3.11/site-packages/httpcore/_async/connection.py:101: in handle_async_request\n    raise exc\n../../.pythonlibs/lib/python3.11/site-packages/httpcore/_async/connection.py:78: in handle_async_request\n    stream = await self._connect(request)\n             ^^^^^^^^^^^^^^^^^^^^^^^^^^^^\n../../.pythonlibs/lib/python3.11/site-packages/httpcore/_async/connection.py:124: in _connect\n    stream = await self._network_backend.connect_tcp(**kwargs)\n             ^^^^^^^^^^^^^^^^^^^^^^^^^^^^^^^^^^^^^^^^^^^^^^^^^\n../../.pythonlibs/lib/python3.11/site-packages/httpcore/_backends/auto.py:31: in connect_tcp\n    return await self._backend.connect_tcp(\n../../.pythonlibs/lib/python3.11/site-packages/httpcore/_backends/anyio.py:113: in connect_tcp\n    with map_exceptions(exc_map):\n/nix/store/7d088dip86hlzri9sk0h78b63yfmx0a0-python3-3.11.13/lib/python3.11/contextlib.py:158: in __exit__\n    self.gen.throw(typ, value, traceback)\n../../.pythonlibs/lib/python3.11/site-packages/httpcore/_exceptions.py:14: in map_exceptions\n    raise to_exc(exc) from exc\nE   httpcore.ConnectError: All connection attempts failed\n\nThe above exception was the direct cause of the following exception:\ntest_my_agents.py:185: in test_error_handling\n    response = await client.get(\"/api/my-agents/invalid-agent-id\")\n               ^^^^^^^^^^^^^^^^^^^^^^^^^^^^^^^^^^^^^^^^^^^^^^^^^^^\n../../.pythonlibs/lib/python3.11/site-packages/httpx/_client.py:1768: in get\n    return await self.request(\n../../.pythonlibs/lib/python3.11/site-packages/httpx/_client.py:1540: in request\n    return await self.send(request, auth=auth, follow_redirects=follow_redirects)\n           ^^^^^^^^^^^^^^^^^^^^^^^^^^^^^^^^^^^^^^^^^^^^^^^^^^^^^^^^^^^^^^^^^^^^^^\n../../.pythonlibs/lib/python3.11/site-packages/httpx/_client.py:1629: in send\n    response = await self._send_handling_auth(\n../../.pythonlibs/lib/python3.11/site-packages/httpx/_client.py:1657: in _send_handling_auth\n    response = await self._send_handling_redirects(\n../../.pythonlibs/lib/python3.11/site-packages/httpx/_client.py:1694: in _send_handling_redirects\n    response = await self._send_single_request(request)\n               ^^^^^^^^^^^^^^^^^^^^^^^^^^^^^^^^^^^^^^^^\n../../.pythonlibs/lib/python3.11/site-packages/httpx/_client.py:1730: in _send_single_request\n    response = await transport.handle_async_request(request)\n               ^^^^^^^^^^^^^^^^^^^^^^^^^^^^^^^^^^^^^^^^^^^^^\n../../.pythonlibs/lib/python3.11/site-packages/httpx/_transports/default.py:393: in handle_async_request\n    with map_httpcore_exceptions():\n/nix/store/7d088dip86hlzri9sk0h78b63yfmx0a0-python3-3.11.13/lib/python3.11/contextlib.py:158: in __exit__\n    self.gen.throw(typ, value, traceback)\n../../.pythonlibs/lib/python3.11/site-packages/httpx/_transports/default.py:118: in map_httpcore_exceptions\n    raise mapped_exc(message) from exc\nE   httpx.ConnectError: All connection attempts failed\n______________ TestMyAgentsService.test_pagination_and_filtering _______________\n../../.pythonlibs/lib/python3.11/site-packages/httpx/_transports/default.py:101: in map_httpcore_exceptions\n    yield\n../../.pythonlibs/lib/python3.11/site-packages/httpx/_transports/default.py:394: in handle_async_request\n    resp = await self._pool.handle_async_request(req)\n           ^^^^^^^^^^^^^^^^^^^^^^^^^^^^^^^^^^^^^^^^^^\n../../.pythonlibs/lib/python3.11/site-packages/httpcore/_async/connection_pool.py:256: in handle_async_request\n    raise exc from None\n../../.pythonlibs/lib/python3.11/site-packages/httpcore/_async/connection_pool.py:236: in handle_async_request\n    response = await connection.handle_async_request(\n../../.pythonlibs/lib/python3.11/site-packages/httpcore/_async/connection.py:101: in handle_async_request\n    raise exc\n../../.pythonlibs/lib/python3.11/site-packages/httpcore/_async/connection.py:78: in handle_async_request\n    stream = await self._connect(request)\n             ^^^^^^^^^^^^^^^^^^^^^^^^^^^^\n../../.pythonlibs/lib/python3.11/site-packages/httpcore/_async/connection.py:124: in _connect\n    stream = await self._network_backend.connect_tcp(**kwargs)\n             ^^^^^^^^^^^^^^^^^^^^^^^^^^^^^^^^^^^^^^^^^^^^^^^^^\n../../.pythonlibs/lib/python3.11/site-packages/httpcore/_backends/auto.py:31: in connect_tcp\n    return await self._backend.connect_tcp(\n../../.pythonlibs/lib/python3.11/site-packages/httpcore/_backends/anyio.py:113: in connect_tcp\n    with map_exceptions(exc_map):\n/nix/store/7d088dip86hlzri9sk0h78b63yfmx0a0-python3-3.11.13/lib/python3.11/contextlib.py:158: in __exit__\n    self.gen.throw(typ, value, traceback)\n../../.pythonlibs/lib/python3.11/site-packages/httpcore/_exceptions.py:14: in map_exceptions\n    raise to_exc(exc) from exc\nE   httpcore.ConnectError: All connection attempts failed\n\nThe above exception was the direct cause of the following exception:\ntest_my_agents.py:208: in test_pagination_and_filtering\n    response = await client.get(f\"/api/my-agents?{filter_param}\")\n               ^^^^^^^^^^^^^^^^^^^^^^^^^^^^^^^^^^^^^^^^^^^^^^^^^^\n../../.pythonlibs/lib/python3.11/site-packages/httpx/_client.py:1768: in get\n    return await self.request(\n../../.pythonlibs/lib/python3.11/site-packages/httpx/_client.py:1540: in request\n    return await self.send(request, auth=auth, follow_redirects=follow_redirects)\n           ^^^^^^^^^^^^^^^^^^^^^^^^^^^^^^^^^^^^^^^^^^^^^^^^^^^^^^^^^^^^^^^^^^^^^^\n../../.pythonlibs/lib/python3.11/site-packages/httpx/_client.py:1629: in send\n    response = await self._send_handling_auth(\n../../.pythonlibs/lib/python3.11/site-packages/httpx/_client.py:1657: in _send_handling_auth\n    response = await self._send_handling_redirects(\n../../.pythonlibs/lib/python3.11/site-packages/httpx/_client.py:1694: in _send_handling_redirects\n    response = await self._send_single_request(request)\n               ^^^^^^^^^^^^^^^^^^^^^^^^^^^^^^^^^^^^^^^^\n../../.pythonlibs/lib/python3.11/site-packages/httpx/_client.py:1730: in _send_single_request\n    response = await transport.handle_async_request(request)\n               ^^^^^^^^^^^^^^^^^^^^^^^^^^^^^^^^^^^^^^^^^^^^^\n../../.pythonlibs/lib/python3.11/site-packages/httpx/_transports/default.py:393: in handle_async_request\n    with map_httpcore_exceptions():\n/nix/store/7d088dip86hlzri9sk0h78b63yfmx0a0-python3-3.11.13/lib/python3.11/contextlib.py:158: in __exit__\n    self.gen.throw(typ, value, traceback)\n../../.pythonlibs/lib/python3.11/site-packages/httpx/_transports/default.py:118: in map_httpcore_exceptions\n    raise mapped_exc(message) from exc\nE   httpx.ConnectError: All connection attempts failed\n_______________________ test_cross_service_communication _______________________\n../../.pythonlibs/lib/python3.11/site-packages/httpx/_transports/default.py:101: in map_httpcore_exceptions\n    yield\n../../.pythonlibs/lib/python3.11/site-packages/httpx/_transports/default.py:394: in handle_async_request\n    resp = await self._pool.handle_async_request(req)\n           ^^^^^^^^^^^^^^^^^^^^^^^^^^^^^^^^^^^^^^^^^^\n../../.pythonlibs/lib/python3.11/site-packages/httpcore/_async/connection_pool.py:256: in handle_async_request\n    raise exc from None\n../../.pythonlibs/lib/python3.11/site-packages/httpcore/_async/connection_pool.py:236: in handle_async_request\n    response = await connection.handle_async_request(\n../../.pythonlibs/lib/python3.11/site-packages/httpcore/_async/connection.py:101: in handle_async_request\n    raise exc\n../../.pythonlibs/lib/python3.11/site-packages/httpcore/_async/connection.py:78: in handle_async_request\n    stream = await self._connect(request)\n             ^^^^^^^^^^^^^^^^^^^^^^^^^^^^\n../../.pythonlibs/lib/python3.11/site-packages/httpcore/_async/connection.py:124: in _connect\n    stream = await self._network_backend.connect_tcp(**kwargs)\n             ^^^^^^^^^^^^^^^^^^^^^^^^^^^^^^^^^^^^^^^^^^^^^^^^^\n../../.pythonlibs/lib/python3.11/site-packages/httpcore/_backends/auto.py:31: in connect_tcp\n    return await self._backend.connect_tcp(\n../../.pythonlibs/lib/python3.11/site-packages/httpcore/_backends/anyio.py:113: in connect_tcp\n    with map_exceptions(exc_map):\n/nix/store/7d088dip86hlzri9sk0h78b63yfmx0a0-python3-3.11.13/lib/python3.11/contextlib.py:158: in __exit__\n    self.gen.throw(typ, value, traceback)\n../../.pythonlibs/lib/python3.11/site-packages/httpcore/_exceptions.py:14: in map_exceptions\n    raise to_exc(exc) from exc\nE   httpcore.ConnectError: All connection attempts failed\n\nThe above exception was the direct cause of the following exception:\ntest_my_agents.py:217: in test_cross_service_communication\n    response = await client.get(\"/health\")\n               ^^^^^^^^^^^^^^^^^^^^^^^^^^^\n../../.pythonlibs/lib/python3.11/site-packages/httpx/_client.py:1768: in get\n    return await self.request(\n../../.pythonlibs/lib/python3.11/site-packages/httpx/_client.py:1540: in request\n    return await self.send(request, auth=auth, follow_redirects=follow_redirects)\n           ^^^^^^^^^^^^^^^^^^^^^^^^^^^^^^^^^^^^^^^^^^^^^^^^^^^^^^^^^^^^^^^^^^^^^^\n../../.pythonlibs/lib/python3.11/site-packages/httpx/_client.py:1629: in send\n    response = await self._send_handling_auth(\n../../.pythonlibs/lib/python3.11/site-packages/httpx/_client.py:1657: in _send_handling_auth\n    response = await self._send_handling_redirects(\n../../.pythonlibs/lib/python3.11/site-packages/httpx/_client.py:1694: in _send_handling_redirects\n    response = await self._send_single_request(request)\n               ^^^^^^^^^^^^^^^^^^^^^^^^^^^^^^^^^^^^^^^^\n../../.pythonlibs/lib/python3.11/site-packages/httpx/_client.py:1730: in _send_single_request\n    response = await transport.handle_async_request(request)\n               ^^^^^^^^^^^^^^^^^^^^^^^^^^^^^^^^^^^^^^^^^^^^^\n../../.pythonlibs/lib/python3.11/site-packages/httpx/_transports/default.py:393: in handle_async_request\n    with map_httpcore_exceptions():\n/nix/store/7d088dip86hlzri9sk0h78b63yfmx0a0-python3-3.11.13/lib/python3.11/contextlib.py:158: in __exit__\n    self.gen.throw(typ, value, traceback)\n../../.pythonlibs/lib/python3.11/site-packages/httpx/_transports/default.py:118: in map_httpcore_exceptions\n    raise mapped_exc(message) from exc\nE   httpx.ConnectError: All connection attempts failed\n=========================== short test summary info ============================\nFAILED test_my_agents.py::TestMyAgentsService::test_health_endpoint - httpx.C...\nFAILED test_my_agents.py::TestMyAgentsService::test_get_agents_dashboard - ht...\nFAILED test_my_agents.py::TestMyAgentsService::test_get_all_agents - httpx.Co...\nFAILED test_my_agents.py::TestMyAgentsService::test_get_agent_details - httpx...\nFAILED test_my_agents.py::TestMyAgentsService::test_agent_status_operations\nFAILED test_my_agents.py::TestMyAgentsService::test_bulk_operations - httpx.C...\nFAILED test_my_agents.py::TestMyAgentsService::test_agent_metrics - httpx.Con...\nFAILED test_my_agents.py::TestMyAgentsService::test_status_history - httpx.Co...\nFAILED test_my_agents.py::TestMyAgentsService::test_agent_backups - httpx.Con...\nFAILED test_my_agents.py::TestMyAgentsService::test_update_agent - httpx.Conn...\nFAILED test_my_agents.py::TestMyAgentsService::test_agent_archive_and_delete\nFAILED test_my_agents.py::TestMyAgentsService::test_error_handling - httpx.Co...\nFAILED test_my_agents.py::TestMyAgentsService::test_pagination_and_filtering\nFAILED test_my_agents.py::test_cross_service_communication - httpx.ConnectErr...\n============================== 14 failed in 2.43s ==============================\n",
      "errors": ""
    },
    "analytics": {
      "return_code": 1,
      "passed": false,
      "failed": true,
      "output": "============================= test session starts ==============================\nplatform linux -- Python 3.11.13, pytest-8.4.1, pluggy-1.6.0 -- /home/runner/workspace/.pythonlibs/bin/python3\ncachedir: .pytest_cache\nrootdir: /home/runner/workspace\nconfigfile: pyproject.toml\nplugins: anyio-4.9.0, asyncio-1.1.0\nasyncio: mode=Mode.AUTO, asyncio_default_fixture_loop_scope=None, asyncio_default_test_loop_scope=function\ncollecting ... collected 5 items\n\ntest_analytics.py::TestAnalyticsService::test_health_endpoint FAILED     [ 20%]\ntest_analytics.py::TestAnalyticsService::test_track_conversation FAILED  [ 40%]\ntest_analytics.py::TestAnalyticsService::test_get_agent_performance FAILED [ 60%]\ntest_analytics.py::TestAnalyticsService::test_get_usage_metrics FAILED   [ 80%]\ntest_analytics.py::TestAnalyticsService::test_conversation_history FAILED [100%]\n\n=================================== FAILURES ===================================\n__________________ TestAnalyticsService.test_health_endpoint ___________________\n../../.pythonlibs/lib/python3.11/site-packages/httpx/_transports/default.py:101: in map_httpcore_exceptions\n    yield\n../../.pythonlibs/lib/python3.11/site-packages/httpx/_transports/default.py:394: in handle_async_request\n    resp = await self._pool.handle_async_request(req)\n           ^^^^^^^^^^^^^^^^^^^^^^^^^^^^^^^^^^^^^^^^^^\n../../.pythonlibs/lib/python3.11/site-packages/httpcore/_async/connection_pool.py:256: in handle_async_request\n    raise exc from None\n../../.pythonlibs/lib/python3.11/site-packages/httpcore/_async/connection_pool.py:236: in handle_async_request\n    response = await connection.handle_async_request(\n../../.pythonlibs/lib/python3.11/site-packages/httpcore/_async/connection.py:101: in handle_async_request\n    raise exc\n../../.pythonlibs/lib/python3.11/site-packages/httpcore/_async/connection.py:78: in handle_async_request\n    stream = await self._connect(request)\n             ^^^^^^^^^^^^^^^^^^^^^^^^^^^^\n../../.pythonlibs/lib/python3.11/site-packages/httpcore/_async/connection.py:124: in _connect\n    stream = await self._network_backend.connect_tcp(**kwargs)\n             ^^^^^^^^^^^^^^^^^^^^^^^^^^^^^^^^^^^^^^^^^^^^^^^^^\n../../.pythonlibs/lib/python3.11/site-packages/httpcore/_backends/auto.py:31: in connect_tcp\n    return await self._backend.connect_tcp(\n../../.pythonlibs/lib/python3.11/site-packages/httpcore/_backends/anyio.py:113: in connect_tcp\n    with map_exceptions(exc_map):\n/nix/store/7d088dip86hlzri9sk0h78b63yfmx0a0-python3-3.11.13/lib/python3.11/contextlib.py:158: in __exit__\n    self.gen.throw(typ, value, traceback)\n../../.pythonlibs/lib/python3.11/site-packages/httpcore/_exceptions.py:14: in map_exceptions\n    raise to_exc(exc) from exc\nE   httpcore.ConnectError: All connection attempts failed\n\nThe above exception was the direct cause of the following exception:\ntest_analytics.py:36: in test_health_endpoint\n    response = await client.get(\"/health\")\n               ^^^^^^^^^^^^^^^^^^^^^^^^^^^\n../../.pythonlibs/lib/python3.11/site-packages/httpx/_client.py:1768: in get\n    return await self.request(\n../../.pythonlibs/lib/python3.11/site-packages/httpx/_client.py:1540: in request\n    return await self.send(request, auth=auth, follow_redirects=follow_redirects)\n           ^^^^^^^^^^^^^^^^^^^^^^^^^^^^^^^^^^^^^^^^^^^^^^^^^^^^^^^^^^^^^^^^^^^^^^\n../../.pythonlibs/lib/python3.11/site-packages/httpx/_client.py:1629: in send\n    response = await self._send_handling_auth(\n../../.pythonlibs/lib/python3.11/site-packages/httpx/_client.py:1657: in _send_handling_auth\n    response = await self._send_handling_redirects(\n../../.pythonlibs/lib/python3.11/site-packages/httpx/_client.py:1694: in _send_handling_redirects\n    response = await self._send_single_request(request)\n               ^^^^^^^^^^^^^^^^^^^^^^^^^^^^^^^^^^^^^^^^\n../../.pythonlibs/lib/python3.11/site-packages/httpx/_client.py:1730: in _send_single_request\n    response = await transport.handle_async_request(request)\n               ^^^^^^^^^^^^^^^^^^^^^^^^^^^^^^^^^^^^^^^^^^^^^\n../../.pythonlibs/lib/python3.11/site-packages/httpx/_transports/default.py:393: in handle_async_request\n    with map_httpcore_exceptions():\n/nix/store/7d088dip86hlzri9sk0h78b63yfmx0a0-python3-3.11.13/lib/python3.11/contextlib.py:158: in __exit__\n    self.gen.throw(typ, value, traceback)\n../../.pythonlibs/lib/python3.11/site-packages/httpx/_transports/default.py:118: in map_httpcore_exceptions\n    raise mapped_exc(message) from exc\nE   httpx.ConnectError: All connection attempts failed\n_________________ TestAnalyticsService.test_track_conversation _________________\n../../.pythonlibs/lib/python3.11/site-packages/httpx/_transports/default.py:101: in map_httpcore_exceptions\n    yield\n../../.pythonlibs/lib/python3.11/site-packages/httpx/_transports/default.py:394: in handle_async_request\n    resp = await self._pool.handle_async_request(req)\n           ^^^^^^^^^^^^^^^^^^^^^^^^^^^^^^^^^^^^^^^^^^\n../../.pythonlibs/lib/python3.11/site-packages/httpcore/_async/connection_pool.py:256: in handle_async_request\n    raise exc from None\n../../.pythonlibs/lib/python3.11/site-packages/httpcore/_async/connection_pool.py:236: in handle_async_request\n    response = await connection.handle_async_request(\n../../.pythonlibs/lib/python3.11/site-packages/httpcore/_async/connection.py:101: in handle_async_request\n    raise exc\n../../.pythonlibs/lib/python3.11/site-packages/httpcore/_async/connection.py:78: in handle_async_request\n    stream = await self._connect(request)\n             ^^^^^^^^^^^^^^^^^^^^^^^^^^^^\n../../.pythonlibs/lib/python3.11/site-packages/httpcore/_async/connection.py:124: in _connect\n    stream = await self._network_backend.connect_tcp(**kwargs)\n             ^^^^^^^^^^^^^^^^^^^^^^^^^^^^^^^^^^^^^^^^^^^^^^^^^\n../../.pythonlibs/lib/python3.11/site-packages/httpcore/_backends/auto.py:31: in connect_tcp\n    return await self._backend.connect_tcp(\n../../.pythonlibs/lib/python3.11/site-packages/httpcore/_backends/anyio.py:113: in connect_tcp\n    with map_exceptions(exc_map):\n/nix/store/7d088dip86hlzri9sk0h78b63yfmx0a0-python3-3.11.13/lib/python3.11/contextlib.py:158: in __exit__\n    self.gen.throw(typ, value, traceback)\n../../.pythonlibs/lib/python3.11/site-packages/httpcore/_exceptions.py:14: in map_exceptions\n    raise to_exc(exc) from exc\nE   httpcore.ConnectError: All connection attempts failed\n\nThe above exception was the direct cause of the following exception:\ntest_analytics.py:45: in test_track_conversation\n    response = await client.post(\"/api/analytics/conversations\", json=sample_conversation_data)\n               ^^^^^^^^^^^^^^^^^^^^^^^^^^^^^^^^^^^^^^^^^^^^^^^^^^^^^^^^^^^^^^^^^^^^^^^^^^^^^^^^\n../../.pythonlibs/lib/python3.11/site-packages/httpx/_client.py:1859: in post\n    return await self.request(\n../../.pythonlibs/lib/python3.11/site-packages/httpx/_client.py:1540: in request\n    return await self.send(request, auth=auth, follow_redirects=follow_redirects)\n           ^^^^^^^^^^^^^^^^^^^^^^^^^^^^^^^^^^^^^^^^^^^^^^^^^^^^^^^^^^^^^^^^^^^^^^\n../../.pythonlibs/lib/python3.11/site-packages/httpx/_client.py:1629: in send\n    response = await self._send_handling_auth(\n../../.pythonlibs/lib/python3.11/site-packages/httpx/_client.py:1657: in _send_handling_auth\n    response = await self._send_handling_redirects(\n../../.pythonlibs/lib/python3.11/site-packages/httpx/_client.py:1694: in _send_handling_redirects\n    response = await self._send_single_request(request)\n               ^^^^^^^^^^^^^^^^^^^^^^^^^^^^^^^^^^^^^^^^\n../../.pythonlibs/lib/python3.11/site-packages/httpx/_client.py:1730: in _send_single_request\n    response = await transport.handle_async_request(request)\n               ^^^^^^^^^^^^^^^^^^^^^^^^^^^^^^^^^^^^^^^^^^^^^\n../../.pythonlibs/lib/python3.11/site-packages/httpx/_transports/default.py:393: in handle_async_request\n    with map_httpcore_exceptions():\n/nix/store/7d088dip86hlzri9sk0h78b63yfmx0a0-python3-3.11.13/lib/python3.11/contextlib.py:158: in __exit__\n    self.gen.throw(typ, value, traceback)\n../../.pythonlibs/lib/python3.11/site-packages/httpx/_transports/default.py:118: in map_httpcore_exceptions\n    raise mapped_exc(message) from exc\nE   httpx.ConnectError: All connection attempts failed\n_______________ TestAnalyticsService.test_get_agent_performance ________________\n../../.pythonlibs/lib/python3.11/site-packages/httpx/_transports/default.py:101: in map_httpcore_exceptions\n    yield\n../../.pythonlibs/lib/python3.11/site-packages/httpx/_transports/default.py:394: in handle_async_request\n    resp = await self._pool.handle_async_request(req)\n           ^^^^^^^^^^^^^^^^^^^^^^^^^^^^^^^^^^^^^^^^^^\n../../.pythonlibs/lib/python3.11/site-packages/httpcore/_async/connection_pool.py:256: in handle_async_request\n    raise exc from None\n../../.pythonlibs/lib/python3.11/site-packages/httpcore/_async/connection_pool.py:236: in handle_async_request\n    response = await connection.handle_async_request(\n../../.pythonlibs/lib/python3.11/site-packages/httpcore/_async/connection.py:101: in handle_async_request\n    raise exc\n../../.pythonlibs/lib/python3.11/site-packages/httpcore/_async/connection.py:78: in handle_async_request\n    stream = await self._connect(request)\n             ^^^^^^^^^^^^^^^^^^^^^^^^^^^^\n../../.pythonlibs/lib/python3.11/site-packages/httpcore/_async/connection.py:124: in _connect\n    stream = await self._network_backend.connect_tcp(**kwargs)\n             ^^^^^^^^^^^^^^^^^^^^^^^^^^^^^^^^^^^^^^^^^^^^^^^^^\n../../.pythonlibs/lib/python3.11/site-packages/httpcore/_backends/auto.py:31: in connect_tcp\n    return await self._backend.connect_tcp(\n../../.pythonlibs/lib/python3.11/site-packages/httpcore/_backends/anyio.py:113: in connect_tcp\n    with map_exceptions(exc_map):\n/nix/store/7d088dip86hlzri9sk0h78b63yfmx0a0-python3-3.11.13/lib/python3.11/contextlib.py:158: in __exit__\n    self.gen.throw(typ, value, traceback)\n../../.pythonlibs/lib/python3.11/site-packages/httpcore/_exceptions.py:14: in map_exceptions\n    raise to_exc(exc) from exc\nE   httpcore.ConnectError: All connection attempts failed\n\nThe above exception was the direct cause of the following exception:\ntest_analytics.py:56: in test_get_agent_performance\n    response = await client.get(f\"/api/analytics/agents/{agent_id}/performance\")\n               ^^^^^^^^^^^^^^^^^^^^^^^^^^^^^^^^^^^^^^^^^^^^^^^^^^^^^^^^^^^^^^^^^\n../../.pythonlibs/lib/python3.11/site-packages/httpx/_client.py:1768: in get\n    return await self.request(\n../../.pythonlibs/lib/python3.11/site-packages/httpx/_client.py:1540: in request\n    return await self.send(request, auth=auth, follow_redirects=follow_redirects)\n           ^^^^^^^^^^^^^^^^^^^^^^^^^^^^^^^^^^^^^^^^^^^^^^^^^^^^^^^^^^^^^^^^^^^^^^\n../../.pythonlibs/lib/python3.11/site-packages/httpx/_client.py:1629: in send\n    response = await self._send_handling_auth(\n../../.pythonlibs/lib/python3.11/site-packages/httpx/_client.py:1657: in _send_handling_auth\n    response = await self._send_handling_redirects(\n../../.pythonlibs/lib/python3.11/site-packages/httpx/_client.py:1694: in _send_handling_redirects\n    response = await self._send_single_request(request)\n               ^^^^^^^^^^^^^^^^^^^^^^^^^^^^^^^^^^^^^^^^\n../../.pythonlibs/lib/python3.11/site-packages/httpx/_client.py:1730: in _send_single_request\n    response = await transport.handle_async_request(request)\n               ^^^^^^^^^^^^^^^^^^^^^^^^^^^^^^^^^^^^^^^^^^^^^\n../../.pythonlibs/lib/python3.11/site-packages/httpx/_transports/default.py:393: in handle_async_request\n    with map_httpcore_exceptions():\n/nix/store/7d088dip86hlzri9sk0h78b63yfmx0a0-python3-3.11.13/lib/python3.11/contextlib.py:158: in __exit__\n    self.gen.throw(typ, value, traceback)\n../../.pythonlibs/lib/python3.11/site-packages/httpx/_transports/default.py:118: in map_httpcore_exceptions\n    raise mapped_exc(message) from exc\nE   httpx.ConnectError: All connection attempts failed\n_________________ TestAnalyticsService.test_get_usage_metrics __________________\n../../.pythonlibs/lib/python3.11/site-packages/httpx/_transports/default.py:101: in map_httpcore_exceptions\n    yield\n../../.pythonlibs/lib/python3.11/site-packages/httpx/_transports/default.py:394: in handle_async_request\n    resp = await self._pool.handle_async_request(req)\n           ^^^^^^^^^^^^^^^^^^^^^^^^^^^^^^^^^^^^^^^^^^\n../../.pythonlibs/lib/python3.11/site-packages/httpcore/_async/connection_pool.py:256: in handle_async_request\n    raise exc from None\n../../.pythonlibs/lib/python3.11/site-packages/httpcore/_async/connection_pool.py:236: in handle_async_request\n    response = await connection.handle_async_request(\n../../.pythonlibs/lib/python3.11/site-packages/httpcore/_async/connection.py:101: in handle_async_request\n    raise exc\n../../.pythonlibs/lib/python3.11/site-packages/httpcore/_async/connection.py:78: in handle_async_request\n    stream = await self._connect(request)\n             ^^^^^^^^^^^^^^^^^^^^^^^^^^^^\n../../.pythonlibs/lib/python3.11/site-packages/httpcore/_async/connection.py:124: in _connect\n    stream = await self._network_backend.connect_tcp(**kwargs)\n             ^^^^^^^^^^^^^^^^^^^^^^^^^^^^^^^^^^^^^^^^^^^^^^^^^\n../../.pythonlibs/lib/python3.11/site-packages/httpcore/_backends/auto.py:31: in connect_tcp\n    return await self._backend.connect_tcp(\n../../.pythonlibs/lib/python3.11/site-packages/httpcore/_backends/anyio.py:113: in connect_tcp\n    with map_exceptions(exc_map):\n/nix/store/7d088dip86hlzri9sk0h78b63yfmx0a0-python3-3.11.13/lib/python3.11/contextlib.py:158: in __exit__\n    self.gen.throw(typ, value, traceback)\n../../.pythonlibs/lib/python3.11/site-packages/httpcore/_exceptions.py:14: in map_exceptions\n    raise to_exc(exc) from exc\nE   httpcore.ConnectError: All connection attempts failed\n\nThe above exception was the direct cause of the following exception:\ntest_analytics.py:66: in test_get_usage_metrics\n    response = await client.get(\"/api/analytics/usage\")\n               ^^^^^^^^^^^^^^^^^^^^^^^^^^^^^^^^^^^^^^^^\n../../.pythonlibs/lib/python3.11/site-packages/httpx/_client.py:1768: in get\n    return await self.request(\n../../.pythonlibs/lib/python3.11/site-packages/httpx/_client.py:1540: in request\n    return await self.send(request, auth=auth, follow_redirects=follow_redirects)\n           ^^^^^^^^^^^^^^^^^^^^^^^^^^^^^^^^^^^^^^^^^^^^^^^^^^^^^^^^^^^^^^^^^^^^^^\n../../.pythonlibs/lib/python3.11/site-packages/httpx/_client.py:1629: in send\n    response = await self._send_handling_auth(\n../../.pythonlibs/lib/python3.11/site-packages/httpx/_client.py:1657: in _send_handling_auth\n    response = await self._send_handling_redirects(\n../../.pythonlibs/lib/python3.11/site-packages/httpx/_client.py:1694: in _send_handling_redirects\n    response = await self._send_single_request(request)\n               ^^^^^^^^^^^^^^^^^^^^^^^^^^^^^^^^^^^^^^^^\n../../.pythonlibs/lib/python3.11/site-packages/httpx/_client.py:1730: in _send_single_request\n    response = await transport.handle_async_request(request)\n               ^^^^^^^^^^^^^^^^^^^^^^^^^^^^^^^^^^^^^^^^^^^^^\n../../.pythonlibs/lib/python3.11/site-packages/httpx/_transports/default.py:393: in handle_async_request\n    with map_httpcore_exceptions():\n/nix/store/7d088dip86hlzri9sk0h78b63yfmx0a0-python3-3.11.13/lib/python3.11/contextlib.py:158: in __exit__\n    self.gen.throw(typ, value, traceback)\n../../.pythonlibs/lib/python3.11/site-packages/httpx/_transports/default.py:118: in map_httpcore_exceptions\n    raise mapped_exc(message) from exc\nE   httpx.ConnectError: All connection attempts failed\n________________ TestAnalyticsService.test_conversation_history ________________\n../../.pythonlibs/lib/python3.11/site-packages/httpx/_transports/default.py:101: in map_httpcore_exceptions\n    yield\n../../.pythonlibs/lib/python3.11/site-packages/httpx/_transports/default.py:394: in handle_async_request\n    resp = await self._pool.handle_async_request(req)\n           ^^^^^^^^^^^^^^^^^^^^^^^^^^^^^^^^^^^^^^^^^^\n../../.pythonlibs/lib/python3.11/site-packages/httpcore/_async/connection_pool.py:256: in handle_async_request\n    raise exc from None\n../../.pythonlibs/lib/python3.11/site-packages/httpcore/_async/connection_pool.py:236: in handle_async_request\n    response = await connection.handle_async_request(\n../../.pythonlibs/lib/python3.11/site-packages/httpcore/_async/connection.py:101: in handle_async_request\n    raise exc\n../../.pythonlibs/lib/python3.11/site-packages/httpcore/_async/connection.py:78: in handle_async_request\n    stream = await self._connect(request)\n             ^^^^^^^^^^^^^^^^^^^^^^^^^^^^\n../../.pythonlibs/lib/python3.11/site-packages/httpcore/_async/connection.py:124: in _connect\n    stream = await self._network_backend.connect_tcp(**kwargs)\n             ^^^^^^^^^^^^^^^^^^^^^^^^^^^^^^^^^^^^^^^^^^^^^^^^^\n../../.pythonlibs/lib/python3.11/site-packages/httpcore/_backends/auto.py:31: in connect_tcp\n    return await self._backend.connect_tcp(\n../../.pythonlibs/lib/python3.11/site-packages/httpcore/_backends/anyio.py:113: in connect_tcp\n    with map_exceptions(exc_map):\n/nix/store/7d088dip86hlzri9sk0h78b63yfmx0a0-python3-3.11.13/lib/python3.11/contextlib.py:158: in __exit__\n    self.gen.throw(typ, value, traceback)\n../../.pythonlibs/lib/python3.11/site-packages/httpcore/_exceptions.py:14: in map_exceptions\n    raise to_exc(exc) from exc\nE   httpcore.ConnectError: All connection attempts failed\n\nThe above exception was the direct cause of the following exception:\ntest_analytics.py:74: in test_conversation_history\n    response = await client.get(\"/api/analytics/conversations\")\n               ^^^^^^^^^^^^^^^^^^^^^^^^^^^^^^^^^^^^^^^^^^^^^^^^\n../../.pythonlibs/lib/python3.11/site-packages/httpx/_client.py:1768: in get\n    return await self.request(\n../../.pythonlibs/lib/python3.11/site-packages/httpx/_client.py:1540: in request\n    return await self.send(request, auth=auth, follow_redirects=follow_redirects)\n           ^^^^^^^^^^^^^^^^^^^^^^^^^^^^^^^^^^^^^^^^^^^^^^^^^^^^^^^^^^^^^^^^^^^^^^\n../../.pythonlibs/lib/python3.11/site-packages/httpx/_client.py:1629: in send\n    response = await self._send_handling_auth(\n../../.pythonlibs/lib/python3.11/site-packages/httpx/_client.py:1657: in _send_handling_auth\n    response = await self._send_handling_redirects(\n../../.pythonlibs/lib/python3.11/site-packages/httpx/_client.py:1694: in _send_handling_redirects\n    response = await self._send_single_request(request)\n               ^^^^^^^^^^^^^^^^^^^^^^^^^^^^^^^^^^^^^^^^\n../../.pythonlibs/lib/python3.11/site-packages/httpx/_client.py:1730: in _send_single_request\n    response = await transport.handle_async_request(request)\n               ^^^^^^^^^^^^^^^^^^^^^^^^^^^^^^^^^^^^^^^^^^^^^\n../../.pythonlibs/lib/python3.11/site-packages/httpx/_transports/default.py:393: in handle_async_request\n    with map_httpcore_exceptions():\n/nix/store/7d088dip86hlzri9sk0h78b63yfmx0a0-python3-3.11.13/lib/python3.11/contextlib.py:158: in __exit__\n    self.gen.throw(typ, value, traceback)\n../../.pythonlibs/lib/python3.11/site-packages/httpx/_transports/default.py:118: in map_httpcore_exceptions\n    raise mapped_exc(message) from exc\nE   httpx.ConnectError: All connection attempts failed\n=========================== short test summary info ============================\nFAILED test_analytics.py::TestAnalyticsService::test_health_endpoint - httpx....\nFAILED test_analytics.py::TestAnalyticsService::test_track_conversation - htt...\nFAILED test_analytics.py::TestAnalyticsService::test_get_agent_performance - ...\nFAILED test_analytics.py::TestAnalyticsService::test_get_usage_metrics - http...\nFAILED test_analytics.py::TestAnalyticsService::test_conversation_history - h...\n============================== 5 failed in 1.13s ===============================\n",
      "errors": ""
    },
    "billing": {
      "return_code": 1,
      "passed": false,
      "failed": true,
      "output": "============================= test session starts ==============================\nplatform linux -- Python 3.11.13, pytest-8.4.1, pluggy-1.6.0 -- /home/runner/workspace/.pythonlibs/bin/python3\ncachedir: .pytest_cache\nrootdir: /home/runner/workspace\nconfigfile: pyproject.toml\nplugins: anyio-4.9.0, asyncio-1.1.0\nasyncio: mode=Mode.AUTO, asyncio_default_fixture_loop_scope=None, asyncio_default_test_loop_scope=function\ncollecting ... collected 4 items\n\ntest_billing.py::TestBillingService::test_health_endpoint FAILED         [ 25%]\ntest_billing.py::TestBillingService::test_track_usage FAILED             [ 50%]\ntest_billing.py::TestBillingService::test_get_billing_summary FAILED     [ 75%]\ntest_billing.py::TestBillingService::test_cost_estimation FAILED         [100%]\n\n=================================== FAILURES ===================================\n___________________ TestBillingService.test_health_endpoint ____________________\n../../.pythonlibs/lib/python3.11/site-packages/httpx/_transports/default.py:101: in map_httpcore_exceptions\n    yield\n../../.pythonlibs/lib/python3.11/site-packages/httpx/_transports/default.py:394: in handle_async_request\n    resp = await self._pool.handle_async_request(req)\n           ^^^^^^^^^^^^^^^^^^^^^^^^^^^^^^^^^^^^^^^^^^\n../../.pythonlibs/lib/python3.11/site-packages/httpcore/_async/connection_pool.py:256: in handle_async_request\n    raise exc from None\n../../.pythonlibs/lib/python3.11/site-packages/httpcore/_async/connection_pool.py:236: in handle_async_request\n    response = await connection.handle_async_request(\n../../.pythonlibs/lib/python3.11/site-packages/httpcore/_async/connection.py:101: in handle_async_request\n    raise exc\n../../.pythonlibs/lib/python3.11/site-packages/httpcore/_async/connection.py:78: in handle_async_request\n    stream = await self._connect(request)\n             ^^^^^^^^^^^^^^^^^^^^^^^^^^^^\n../../.pythonlibs/lib/python3.11/site-packages/httpcore/_async/connection.py:124: in _connect\n    stream = await self._network_backend.connect_tcp(**kwargs)\n             ^^^^^^^^^^^^^^^^^^^^^^^^^^^^^^^^^^^^^^^^^^^^^^^^^\n../../.pythonlibs/lib/python3.11/site-packages/httpcore/_backends/auto.py:31: in connect_tcp\n    return await self._backend.connect_tcp(\n../../.pythonlibs/lib/python3.11/site-packages/httpcore/_backends/anyio.py:113: in connect_tcp\n    with map_exceptions(exc_map):\n/nix/store/7d088dip86hlzri9sk0h78b63yfmx0a0-python3-3.11.13/lib/python3.11/contextlib.py:158: in __exit__\n    self.gen.throw(typ, value, traceback)\n../../.pythonlibs/lib/python3.11/site-packages/httpcore/_exceptions.py:14: in map_exceptions\n    raise to_exc(exc) from exc\nE   httpcore.ConnectError: All connection attempts failed\n\nThe above exception was the direct cause of the following exception:\ntest_billing.py:32: in test_health_endpoint\n    response = await client.get(\"/health\")\n               ^^^^^^^^^^^^^^^^^^^^^^^^^^^\n../../.pythonlibs/lib/python3.11/site-packages/httpx/_client.py:1768: in get\n    return await self.request(\n../../.pythonlibs/lib/python3.11/site-packages/httpx/_client.py:1540: in request\n    return await self.send(request, auth=auth, follow_redirects=follow_redirects)\n           ^^^^^^^^^^^^^^^^^^^^^^^^^^^^^^^^^^^^^^^^^^^^^^^^^^^^^^^^^^^^^^^^^^^^^^\n../../.pythonlibs/lib/python3.11/site-packages/httpx/_client.py:1629: in send\n    response = await self._send_handling_auth(\n../../.pythonlibs/lib/python3.11/site-packages/httpx/_client.py:1657: in _send_handling_auth\n    response = await self._send_handling_redirects(\n../../.pythonlibs/lib/python3.11/site-packages/httpx/_client.py:1694: in _send_handling_redirects\n    response = await self._send_single_request(request)\n               ^^^^^^^^^^^^^^^^^^^^^^^^^^^^^^^^^^^^^^^^\n../../.pythonlibs/lib/python3.11/site-packages/httpx/_client.py:1730: in _send_single_request\n    response = await transport.handle_async_request(request)\n               ^^^^^^^^^^^^^^^^^^^^^^^^^^^^^^^^^^^^^^^^^^^^^\n../../.pythonlibs/lib/python3.11/site-packages/httpx/_transports/default.py:393: in handle_async_request\n    with map_httpcore_exceptions():\n/nix/store/7d088dip86hlzri9sk0h78b63yfmx0a0-python3-3.11.13/lib/python3.11/contextlib.py:158: in __exit__\n    self.gen.throw(typ, value, traceback)\n../../.pythonlibs/lib/python3.11/site-packages/httpx/_transports/default.py:118: in map_httpcore_exceptions\n    raise mapped_exc(message) from exc\nE   httpx.ConnectError: All connection attempts failed\n_____________________ TestBillingService.test_track_usage ______________________\n../../.pythonlibs/lib/python3.11/site-packages/httpx/_transports/default.py:101: in map_httpcore_exceptions\n    yield\n../../.pythonlibs/lib/python3.11/site-packages/httpx/_transports/default.py:394: in handle_async_request\n    resp = await self._pool.handle_async_request(req)\n           ^^^^^^^^^^^^^^^^^^^^^^^^^^^^^^^^^^^^^^^^^^\n../../.pythonlibs/lib/python3.11/site-packages/httpcore/_async/connection_pool.py:256: in handle_async_request\n    raise exc from None\n../../.pythonlibs/lib/python3.11/site-packages/httpcore/_async/connection_pool.py:236: in handle_async_request\n    response = await connection.handle_async_request(\n../../.pythonlibs/lib/python3.11/site-packages/httpcore/_async/connection.py:101: in handle_async_request\n    raise exc\n../../.pythonlibs/lib/python3.11/site-packages/httpcore/_async/connection.py:78: in handle_async_request\n    stream = await self._connect(request)\n             ^^^^^^^^^^^^^^^^^^^^^^^^^^^^\n../../.pythonlibs/lib/python3.11/site-packages/httpcore/_async/connection.py:124: in _connect\n    stream = await self._network_backend.connect_tcp(**kwargs)\n             ^^^^^^^^^^^^^^^^^^^^^^^^^^^^^^^^^^^^^^^^^^^^^^^^^\n../../.pythonlibs/lib/python3.11/site-packages/httpcore/_backends/auto.py:31: in connect_tcp\n    return await self._backend.connect_tcp(\n../../.pythonlibs/lib/python3.11/site-packages/httpcore/_backends/anyio.py:113: in connect_tcp\n    with map_exceptions(exc_map):\n/nix/store/7d088dip86hlzri9sk0h78b63yfmx0a0-python3-3.11.13/lib/python3.11/contextlib.py:158: in __exit__\n    self.gen.throw(typ, value, traceback)\n../../.pythonlibs/lib/python3.11/site-packages/httpcore/_exceptions.py:14: in map_exceptions\n    raise to_exc(exc) from exc\nE   httpcore.ConnectError: All connection attempts failed\n\nThe above exception was the direct cause of the following exception:\ntest_billing.py:41: in test_track_usage\n    response = await client.post(\"/api/billing/usage\", json=sample_usage_data)\n               ^^^^^^^^^^^^^^^^^^^^^^^^^^^^^^^^^^^^^^^^^^^^^^^^^^^^^^^^^^^^^^^\n../../.pythonlibs/lib/python3.11/site-packages/httpx/_client.py:1859: in post\n    return await self.request(\n../../.pythonlibs/lib/python3.11/site-packages/httpx/_client.py:1540: in request\n    return await self.send(request, auth=auth, follow_redirects=follow_redirects)\n           ^^^^^^^^^^^^^^^^^^^^^^^^^^^^^^^^^^^^^^^^^^^^^^^^^^^^^^^^^^^^^^^^^^^^^^\n../../.pythonlibs/lib/python3.11/site-packages/httpx/_client.py:1629: in send\n    response = await self._send_handling_auth(\n../../.pythonlibs/lib/python3.11/site-packages/httpx/_client.py:1657: in _send_handling_auth\n    response = await self._send_handling_redirects(\n../../.pythonlibs/lib/python3.11/site-packages/httpx/_client.py:1694: in _send_handling_redirects\n    response = await self._send_single_request(request)\n               ^^^^^^^^^^^^^^^^^^^^^^^^^^^^^^^^^^^^^^^^\n../../.pythonlibs/lib/python3.11/site-packages/httpx/_client.py:1730: in _send_single_request\n    response = await transport.handle_async_request(request)\n               ^^^^^^^^^^^^^^^^^^^^^^^^^^^^^^^^^^^^^^^^^^^^^\n../../.pythonlibs/lib/python3.11/site-packages/httpx/_transports/default.py:393: in handle_async_request\n    with map_httpcore_exceptions():\n/nix/store/7d088dip86hlzri9sk0h78b63yfmx0a0-python3-3.11.13/lib/python3.11/contextlib.py:158: in __exit__\n    self.gen.throw(typ, value, traceback)\n../../.pythonlibs/lib/python3.11/site-packages/httpx/_transports/default.py:118: in map_httpcore_exceptions\n    raise mapped_exc(message) from exc\nE   httpx.ConnectError: All connection attempts failed\n_________________ TestBillingService.test_get_billing_summary __________________\n../../.pythonlibs/lib/python3.11/site-packages/httpx/_transports/default.py:101: in map_httpcore_exceptions\n    yield\n../../.pythonlibs/lib/python3.11/site-packages/httpx/_transports/default.py:394: in handle_async_request\n    resp = await self._pool.handle_async_request(req)\n           ^^^^^^^^^^^^^^^^^^^^^^^^^^^^^^^^^^^^^^^^^^\n../../.pythonlibs/lib/python3.11/site-packages/httpcore/_async/connection_pool.py:256: in handle_async_request\n    raise exc from None\n../../.pythonlibs/lib/python3.11/site-packages/httpcore/_async/connection_pool.py:236: in handle_async_request\n    response = await connection.handle_async_request(\n../../.pythonlibs/lib/python3.11/site-packages/httpcore/_async/connection.py:101: in handle_async_request\n    raise exc\n../../.pythonlibs/lib/python3.11/site-packages/httpcore/_async/connection.py:78: in handle_async_request\n    stream = await self._connect(request)\n             ^^^^^^^^^^^^^^^^^^^^^^^^^^^^\n../../.pythonlibs/lib/python3.11/site-packages/httpcore/_async/connection.py:124: in _connect\n    stream = await self._network_backend.connect_tcp(**kwargs)\n             ^^^^^^^^^^^^^^^^^^^^^^^^^^^^^^^^^^^^^^^^^^^^^^^^^\n../../.pythonlibs/lib/python3.11/site-packages/httpcore/_backends/auto.py:31: in connect_tcp\n    return await self._backend.connect_tcp(\n../../.pythonlibs/lib/python3.11/site-packages/httpcore/_backends/anyio.py:113: in connect_tcp\n    with map_exceptions(exc_map):\n/nix/store/7d088dip86hlzri9sk0h78b63yfmx0a0-python3-3.11.13/lib/python3.11/contextlib.py:158: in __exit__\n    self.gen.throw(typ, value, traceback)\n../../.pythonlibs/lib/python3.11/site-packages/httpcore/_exceptions.py:14: in map_exceptions\n    raise to_exc(exc) from exc\nE   httpcore.ConnectError: All connection attempts failed\n\nThe above exception was the direct cause of the following exception:\ntest_billing.py:47: in test_get_billing_summary\n    response = await client.get(\"/api/billing/summary\")\n               ^^^^^^^^^^^^^^^^^^^^^^^^^^^^^^^^^^^^^^^^\n../../.pythonlibs/lib/python3.11/site-packages/httpx/_client.py:1768: in get\n    return await self.request(\n../../.pythonlibs/lib/python3.11/site-packages/httpx/_client.py:1540: in request\n    return await self.send(request, auth=auth, follow_redirects=follow_redirects)\n           ^^^^^^^^^^^^^^^^^^^^^^^^^^^^^^^^^^^^^^^^^^^^^^^^^^^^^^^^^^^^^^^^^^^^^^\n../../.pythonlibs/lib/python3.11/site-packages/httpx/_client.py:1629: in send\n    response = await self._send_handling_auth(\n../../.pythonlibs/lib/python3.11/site-packages/httpx/_client.py:1657: in _send_handling_auth\n    response = await self._send_handling_redirects(\n../../.pythonlibs/lib/python3.11/site-packages/httpx/_client.py:1694: in _send_handling_redirects\n    response = await self._send_single_request(request)\n               ^^^^^^^^^^^^^^^^^^^^^^^^^^^^^^^^^^^^^^^^\n../../.pythonlibs/lib/python3.11/site-packages/httpx/_client.py:1730: in _send_single_request\n    response = await transport.handle_async_request(request)\n               ^^^^^^^^^^^^^^^^^^^^^^^^^^^^^^^^^^^^^^^^^^^^^\n../../.pythonlibs/lib/python3.11/site-packages/httpx/_transports/default.py:393: in handle_async_request\n    with map_httpcore_exceptions():\n/nix/store/7d088dip86hlzri9sk0h78b63yfmx0a0-python3-3.11.13/lib/python3.11/contextlib.py:158: in __exit__\n    self.gen.throw(typ, value, traceback)\n../../.pythonlibs/lib/python3.11/site-packages/httpx/_transports/default.py:118: in map_httpcore_exceptions\n    raise mapped_exc(message) from exc\nE   httpx.ConnectError: All connection attempts failed\n___________________ TestBillingService.test_cost_estimation ____________________\n../../.pythonlibs/lib/python3.11/site-packages/httpx/_transports/default.py:101: in map_httpcore_exceptions\n    yield\n../../.pythonlibs/lib/python3.11/site-packages/httpx/_transports/default.py:394: in handle_async_request\n    resp = await self._pool.handle_async_request(req)\n           ^^^^^^^^^^^^^^^^^^^^^^^^^^^^^^^^^^^^^^^^^^\n../../.pythonlibs/lib/python3.11/site-packages/httpcore/_async/connection_pool.py:256: in handle_async_request\n    raise exc from None\n../../.pythonlibs/lib/python3.11/site-packages/httpcore/_async/connection_pool.py:236: in handle_async_request\n    response = await connection.handle_async_request(\n../../.pythonlibs/lib/python3.11/site-packages/httpcore/_async/connection.py:101: in handle_async_request\n    raise exc\n../../.pythonlibs/lib/python3.11/site-packages/httpcore/_async/connection.py:78: in handle_async_request\n    stream = await self._connect(request)\n             ^^^^^^^^^^^^^^^^^^^^^^^^^^^^\n../../.pythonlibs/lib/python3.11/site-packages/httpcore/_async/connection.py:124: in _connect\n    stream = await self._network_backend.connect_tcp(**kwargs)\n             ^^^^^^^^^^^^^^^^^^^^^^^^^^^^^^^^^^^^^^^^^^^^^^^^^\n../../.pythonlibs/lib/python3.11/site-packages/httpcore/_backends/auto.py:31: in connect_tcp\n    return await self._backend.connect_tcp(\n../../.pythonlibs/lib/python3.11/site-packages/httpcore/_backends/anyio.py:113: in connect_tcp\n    with map_exceptions(exc_map):\n/nix/store/7d088dip86hlzri9sk0h78b63yfmx0a0-python3-3.11.13/lib/python3.11/contextlib.py:158: in __exit__\n    self.gen.throw(typ, value, traceback)\n../../.pythonlibs/lib/python3.11/site-packages/httpcore/_exceptions.py:14: in map_exceptions\n    raise to_exc(exc) from exc\nE   httpcore.ConnectError: All connection attempts failed\n\nThe above exception was the direct cause of the following exception:\ntest_billing.py:59: in test_cost_estimation\n    response = await client.post(\"/api/billing/estimate\", json=estimation_data)\n               ^^^^^^^^^^^^^^^^^^^^^^^^^^^^^^^^^^^^^^^^^^^^^^^^^^^^^^^^^^^^^^^^\n../../.pythonlibs/lib/python3.11/site-packages/httpx/_client.py:1859: in post\n    return await self.request(\n../../.pythonlibs/lib/python3.11/site-packages/httpx/_client.py:1540: in request\n    return await self.send(request, auth=auth, follow_redirects=follow_redirects)\n           ^^^^^^^^^^^^^^^^^^^^^^^^^^^^^^^^^^^^^^^^^^^^^^^^^^^^^^^^^^^^^^^^^^^^^^\n../../.pythonlibs/lib/python3.11/site-packages/httpx/_client.py:1629: in send\n    response = await self._send_handling_auth(\n../../.pythonlibs/lib/python3.11/site-packages/httpx/_client.py:1657: in _send_handling_auth\n    response = await self._send_handling_redirects(\n../../.pythonlibs/lib/python3.11/site-packages/httpx/_client.py:1694: in _send_handling_redirects\n    response = await self._send_single_request(request)\n               ^^^^^^^^^^^^^^^^^^^^^^^^^^^^^^^^^^^^^^^^\n../../.pythonlibs/lib/python3.11/site-packages/httpx/_client.py:1730: in _send_single_request\n    response = await transport.handle_async_request(request)\n               ^^^^^^^^^^^^^^^^^^^^^^^^^^^^^^^^^^^^^^^^^^^^^\n../../.pythonlibs/lib/python3.11/site-packages/httpx/_transports/default.py:393: in handle_async_request\n    with map_httpcore_exceptions():\n/nix/store/7d088dip86hlzri9sk0h78b63yfmx0a0-python3-3.11.13/lib/python3.11/contextlib.py:158: in __exit__\n    self.gen.throw(typ, value, traceback)\n../../.pythonlibs/lib/python3.11/site-packages/httpx/_transports/default.py:118: in map_httpcore_exceptions\n    raise mapped_exc(message) from exc\nE   httpx.ConnectError: All connection attempts failed\n=========================== short test summary info ============================\nFAILED test_billing.py::TestBillingService::test_health_endpoint - httpx.Conn...\nFAILED test_billing.py::TestBillingService::test_track_usage - httpx.ConnectE...\nFAILED test_billing.py::TestBillingService::test_get_billing_summary - httpx....\nFAILED test_billing.py::TestBillingService::test_cost_estimation - httpx.Conn...\n============================== 4 failed in 0.95s ===============================\n",
      "errors": ""
    },
    "widget": {
      "return_code": 1,
      "passed": false,
      "failed": true,
      "output": "============================= test session starts ==============================\nplatform linux -- Python 3.11.13, pytest-8.4.1, pluggy-1.6.0 -- /home/runner/workspace/.pythonlibs/bin/python3\ncachedir: .pytest_cache\nrootdir: /home/runner/workspace\nconfigfile: pyproject.toml\nplugins: anyio-4.9.0, asyncio-1.1.0\nasyncio: mode=Mode.AUTO, asyncio_default_fixture_loop_scope=None, asyncio_default_test_loop_scope=function\ncollecting ... collected 5 items\n\ntest_widget.py::TestWidgetService::test_health_endpoint FAILED           [ 20%]\ntest_widget.py::TestWidgetService::test_create_widget FAILED             [ 40%]\ntest_widget.py::TestWidgetService::test_get_widgets FAILED               [ 60%]\ntest_widget.py::TestWidgetService::test_get_widget_templates FAILED      [ 80%]\ntest_widget.py::TestWidgetService::test_generate_embed_code FAILED       [100%]\n\n=================================== FAILURES ===================================\n____________________ TestWidgetService.test_health_endpoint ____________________\n../../.pythonlibs/lib/python3.11/site-packages/httpx/_transports/default.py:101: in map_httpcore_exceptions\n    yield\n../../.pythonlibs/lib/python3.11/site-packages/httpx/_transports/default.py:394: in handle_async_request\n    resp = await self._pool.handle_async_request(req)\n           ^^^^^^^^^^^^^^^^^^^^^^^^^^^^^^^^^^^^^^^^^^\n../../.pythonlibs/lib/python3.11/site-packages/httpcore/_async/connection_pool.py:256: in handle_async_request\n    raise exc from None\n../../.pythonlibs/lib/python3.11/site-packages/httpcore/_async/connection_pool.py:236: in handle_async_request\n    response = await connection.handle_async_request(\n../../.pythonlibs/lib/python3.11/site-packages/httpcore/_async/connection.py:101: in handle_async_request\n    raise exc\n../../.pythonlibs/lib/python3.11/site-packages/httpcore/_async/connection.py:78: in handle_async_request\n    stream = await self._connect(request)\n             ^^^^^^^^^^^^^^^^^^^^^^^^^^^^\n../../.pythonlibs/lib/python3.11/site-packages/httpcore/_async/connection.py:124: in _connect\n    stream = await self._network_backend.connect_tcp(**kwargs)\n             ^^^^^^^^^^^^^^^^^^^^^^^^^^^^^^^^^^^^^^^^^^^^^^^^^\n../../.pythonlibs/lib/python3.11/site-packages/httpcore/_backends/auto.py:31: in connect_tcp\n    return await self._backend.connect_tcp(\n../../.pythonlibs/lib/python3.11/site-packages/httpcore/_backends/anyio.py:113: in connect_tcp\n    with map_exceptions(exc_map):\n/nix/store/7d088dip86hlzri9sk0h78b63yfmx0a0-python3-3.11.13/lib/python3.11/contextlib.py:158: in __exit__\n    self.gen.throw(typ, value, traceback)\n../../.pythonlibs/lib/python3.11/site-packages/httpcore/_exceptions.py:14: in map_exceptions\n    raise to_exc(exc) from exc\nE   httpcore.ConnectError: All connection attempts failed\n\nThe above exception was the direct cause of the following exception:\ntest_widget.py:41: in test_health_endpoint\n    response = await client.get(\"/health\")\n               ^^^^^^^^^^^^^^^^^^^^^^^^^^^\n../../.pythonlibs/lib/python3.11/site-packages/httpx/_client.py:1768: in get\n    return await self.request(\n../../.pythonlibs/lib/python3.11/site-packages/httpx/_client.py:1540: in request\n    return await self.send(request, auth=auth, follow_redirects=follow_redirects)\n           ^^^^^^^^^^^^^^^^^^^^^^^^^^^^^^^^^^^^^^^^^^^^^^^^^^^^^^^^^^^^^^^^^^^^^^\n../../.pythonlibs/lib/python3.11/site-packages/httpx/_client.py:1629: in send\n    response = await self._send_handling_auth(\n../../.pythonlibs/lib/python3.11/site-packages/httpx/_client.py:1657: in _send_handling_auth\n    response = await self._send_handling_redirects(\n../../.pythonlibs/lib/python3.11/site-packages/httpx/_client.py:1694: in _send_handling_redirects\n    response = await self._send_single_request(request)\n               ^^^^^^^^^^^^^^^^^^^^^^^^^^^^^^^^^^^^^^^^\n../../.pythonlibs/lib/python3.11/site-packages/httpx/_client.py:1730: in _send_single_request\n    response = await transport.handle_async_request(request)\n               ^^^^^^^^^^^^^^^^^^^^^^^^^^^^^^^^^^^^^^^^^^^^^\n../../.pythonlibs/lib/python3.11/site-packages/httpx/_transports/default.py:393: in handle_async_request\n    with map_httpcore_exceptions():\n/nix/store/7d088dip86hlzri9sk0h78b63yfmx0a0-python3-3.11.13/lib/python3.11/contextlib.py:158: in __exit__\n    self.gen.throw(typ, value, traceback)\n../../.pythonlibs/lib/python3.11/site-packages/httpx/_transports/default.py:118: in map_httpcore_exceptions\n    raise mapped_exc(message) from exc\nE   httpx.ConnectError: All connection attempts failed\n_____________________ TestWidgetService.test_create_widget _____________________\n../../.pythonlibs/lib/python3.11/site-packages/httpx/_transports/default.py:101: in map_httpcore_exceptions\n    yield\n../../.pythonlibs/lib/python3.11/site-packages/httpx/_transports/default.py:394: in handle_async_request\n    resp = await self._pool.handle_async_request(req)\n           ^^^^^^^^^^^^^^^^^^^^^^^^^^^^^^^^^^^^^^^^^^\n../../.pythonlibs/lib/python3.11/site-packages/httpcore/_async/connection_pool.py:256: in handle_async_request\n    raise exc from None\n../../.pythonlibs/lib/python3.11/site-packages/httpcore/_async/connection_pool.py:236: in handle_async_request\n    response = await connection.handle_async_request(\n../../.pythonlibs/lib/python3.11/site-packages/httpcore/_async/connection.py:101: in handle_async_request\n    raise exc\n../../.pythonlibs/lib/python3.11/site-packages/httpcore/_async/connection.py:78: in handle_async_request\n    stream = await self._connect(request)\n             ^^^^^^^^^^^^^^^^^^^^^^^^^^^^\n../../.pythonlibs/lib/python3.11/site-packages/httpcore/_async/connection.py:124: in _connect\n    stream = await self._network_backend.connect_tcp(**kwargs)\n             ^^^^^^^^^^^^^^^^^^^^^^^^^^^^^^^^^^^^^^^^^^^^^^^^^\n../../.pythonlibs/lib/python3.11/site-packages/httpcore/_backends/auto.py:31: in connect_tcp\n    return await self._backend.connect_tcp(\n../../.pythonlibs/lib/python3.11/site-packages/httpcore/_backends/anyio.py:113: in connect_tcp\n    with map_exceptions(exc_map):\n/nix/store/7d088dip86hlzri9sk0h78b63yfmx0a0-python3-3.11.13/lib/python3.11/contextlib.py:158: in __exit__\n    self.gen.throw(typ, value, traceback)\n../../.pythonlibs/lib/python3.11/site-packages/httpcore/_exceptions.py:14: in map_exceptions\n    raise to_exc(exc) from exc\nE   httpcore.ConnectError: All connection attempts failed\n\nThe above exception was the direct cause of the following exception:\ntest_widget.py:50: in test_create_widget\n    response = await client.post(\"/api/widgets\", json=sample_widget_data)\n               ^^^^^^^^^^^^^^^^^^^^^^^^^^^^^^^^^^^^^^^^^^^^^^^^^^^^^^^^^^\n../../.pythonlibs/lib/python3.11/site-packages/httpx/_client.py:1859: in post\n    return await self.request(\n../../.pythonlibs/lib/python3.11/site-packages/httpx/_client.py:1540: in request\n    return await self.send(request, auth=auth, follow_redirects=follow_redirects)\n           ^^^^^^^^^^^^^^^^^^^^^^^^^^^^^^^^^^^^^^^^^^^^^^^^^^^^^^^^^^^^^^^^^^^^^^\n../../.pythonlibs/lib/python3.11/site-packages/httpx/_client.py:1629: in send\n    response = await self._send_handling_auth(\n../../.pythonlibs/lib/python3.11/site-packages/httpx/_client.py:1657: in _send_handling_auth\n    response = await self._send_handling_redirects(\n../../.pythonlibs/lib/python3.11/site-packages/httpx/_client.py:1694: in _send_handling_redirects\n    response = await self._send_single_request(request)\n               ^^^^^^^^^^^^^^^^^^^^^^^^^^^^^^^^^^^^^^^^\n../../.pythonlibs/lib/python3.11/site-packages/httpx/_client.py:1730: in _send_single_request\n    response = await transport.handle_async_request(request)\n               ^^^^^^^^^^^^^^^^^^^^^^^^^^^^^^^^^^^^^^^^^^^^^\n../../.pythonlibs/lib/python3.11/site-packages/httpx/_transports/default.py:393: in handle_async_request\n    with map_httpcore_exceptions():\n/nix/store/7d088dip86hlzri9sk0h78b63yfmx0a0-python3-3.11.13/lib/python3.11/contextlib.py:158: in __exit__\n    self.gen.throw(typ, value, traceback)\n../../.pythonlibs/lib/python3.11/site-packages/httpx/_transports/default.py:118: in map_httpcore_exceptions\n    raise mapped_exc(message) from exc\nE   httpx.ConnectError: All connection attempts failed\n______________________ TestWidgetService.test_get_widgets ______________________\n../../.pythonlibs/lib/python3.11/site-packages/httpx/_transports/default.py:101: in map_httpcore_exceptions\n    yield\n../../.pythonlibs/lib/python3.11/site-packages/httpx/_transports/default.py:394: in handle_async_request\n    resp = await self._pool.handle_async_request(req)\n           ^^^^^^^^^^^^^^^^^^^^^^^^^^^^^^^^^^^^^^^^^^\n../../.pythonlibs/lib/python3.11/site-packages/httpcore/_async/connection_pool.py:256: in handle_async_request\n    raise exc from None\n../../.pythonlibs/lib/python3.11/site-packages/httpcore/_async/connection_pool.py:236: in handle_async_request\n    response = await connection.handle_async_request(\n../../.pythonlibs/lib/python3.11/site-packages/httpcore/_async/connection.py:101: in handle_async_request\n    raise exc\n../../.pythonlibs/lib/python3.11/site-packages/httpcore/_async/connection.py:78: in handle_async_request\n    stream = await self._connect(request)\n             ^^^^^^^^^^^^^^^^^^^^^^^^^^^^\n../../.pythonlibs/lib/python3.11/site-packages/httpcore/_async/connection.py:124: in _connect\n    stream = await self._network_backend.connect_tcp(**kwargs)\n             ^^^^^^^^^^^^^^^^^^^^^^^^^^^^^^^^^^^^^^^^^^^^^^^^^\n../../.pythonlibs/lib/python3.11/site-packages/httpcore/_backends/auto.py:31: in connect_tcp\n    return await self._backend.connect_tcp(\n../../.pythonlibs/lib/python3.11/site-packages/httpcore/_backends/anyio.py:113: in connect_tcp\n    with map_exceptions(exc_map):\n/nix/store/7d088dip86hlzri9sk0h78b63yfmx0a0-python3-3.11.13/lib/python3.11/contextlib.py:158: in __exit__\n    self.gen.throw(typ, value, traceback)\n../../.pythonlibs/lib/python3.11/site-packages/httpcore/_exceptions.py:14: in map_exceptions\n    raise to_exc(exc) from exc\nE   httpcore.ConnectError: All connection attempts failed\n\nThe above exception was the direct cause of the following exception:\ntest_widget.py:61: in test_get_widgets\n    response = await client.get(\"/api/widgets\")\n               ^^^^^^^^^^^^^^^^^^^^^^^^^^^^^^^^\n../../.pythonlibs/lib/python3.11/site-packages/httpx/_client.py:1768: in get\n    return await self.request(\n../../.pythonlibs/lib/python3.11/site-packages/httpx/_client.py:1540: in request\n    return await self.send(request, auth=auth, follow_redirects=follow_redirects)\n           ^^^^^^^^^^^^^^^^^^^^^^^^^^^^^^^^^^^^^^^^^^^^^^^^^^^^^^^^^^^^^^^^^^^^^^\n../../.pythonlibs/lib/python3.11/site-packages/httpx/_client.py:1629: in send\n    response = await self._send_handling_auth(\n../../.pythonlibs/lib/python3.11/site-packages/httpx/_client.py:1657: in _send_handling_auth\n    response = await self._send_handling_redirects(\n../../.pythonlibs/lib/python3.11/site-packages/httpx/_client.py:1694: in _send_handling_redirects\n    response = await self._send_single_request(request)\n               ^^^^^^^^^^^^^^^^^^^^^^^^^^^^^^^^^^^^^^^^\n../../.pythonlibs/lib/python3.11/site-packages/httpx/_client.py:1730: in _send_single_request\n    response = await transport.handle_async_request(request)\n               ^^^^^^^^^^^^^^^^^^^^^^^^^^^^^^^^^^^^^^^^^^^^^\n../../.pythonlibs/lib/python3.11/site-packages/httpx/_transports/default.py:393: in handle_async_request\n    with map_httpcore_exceptions():\n/nix/store/7d088dip86hlzri9sk0h78b63yfmx0a0-python3-3.11.13/lib/python3.11/contextlib.py:158: in __exit__\n    self.gen.throw(typ, value, traceback)\n../../.pythonlibs/lib/python3.11/site-packages/httpx/_transports/default.py:118: in map_httpcore_exceptions\n    raise mapped_exc(message) from exc\nE   httpx.ConnectError: All connection attempts failed\n_________________ TestWidgetService.test_get_widget_templates __________________\n../../.pythonlibs/lib/python3.11/site-packages/httpx/_transports/default.py:101: in map_httpcore_exceptions\n    yield\n../../.pythonlibs/lib/python3.11/site-packages/httpx/_transports/default.py:394: in handle_async_request\n    resp = await self._pool.handle_async_request(req)\n           ^^^^^^^^^^^^^^^^^^^^^^^^^^^^^^^^^^^^^^^^^^\n../../.pythonlibs/lib/python3.11/site-packages/httpcore/_async/connection_pool.py:256: in handle_async_request\n    raise exc from None\n../../.pythonlibs/lib/python3.11/site-packages/httpcore/_async/connection_pool.py:236: in handle_async_request\n    response = await connection.handle_async_request(\n../../.pythonlibs/lib/python3.11/site-packages/httpcore/_async/connection.py:101: in handle_async_request\n    raise exc\n../../.pythonlibs/lib/python3.11/site-packages/httpcore/_async/connection.py:78: in handle_async_request\n    stream = await self._connect(request)\n             ^^^^^^^^^^^^^^^^^^^^^^^^^^^^\n../../.pythonlibs/lib/python3.11/site-packages/httpcore/_async/connection.py:124: in _connect\n    stream = await self._network_backend.connect_tcp(**kwargs)\n             ^^^^^^^^^^^^^^^^^^^^^^^^^^^^^^^^^^^^^^^^^^^^^^^^^\n../../.pythonlibs/lib/python3.11/site-packages/httpcore/_backends/auto.py:31: in connect_tcp\n    return await self._backend.connect_tcp(\n../../.pythonlibs/lib/python3.11/site-packages/httpcore/_backends/anyio.py:113: in connect_tcp\n    with map_exceptions(exc_map):\n/nix/store/7d088dip86hlzri9sk0h78b63yfmx0a0-python3-3.11.13/lib/python3.11/contextlib.py:158: in __exit__\n    self.gen.throw(typ, value, traceback)\n../../.pythonlibs/lib/python3.11/site-packages/httpcore/_exceptions.py:14: in map_exceptions\n    raise to_exc(exc) from exc\nE   httpcore.ConnectError: All connection attempts failed\n\nThe above exception was the direct cause of the following exception:\ntest_widget.py:69: in test_get_widget_templates\n    response = await client.get(\"/api/templates\")\n               ^^^^^^^^^^^^^^^^^^^^^^^^^^^^^^^^^^\n../../.pythonlibs/lib/python3.11/site-packages/httpx/_client.py:1768: in get\n    return await self.request(\n../../.pythonlibs/lib/python3.11/site-packages/httpx/_client.py:1540: in request\n    return await self.send(request, auth=auth, follow_redirects=follow_redirects)\n           ^^^^^^^^^^^^^^^^^^^^^^^^^^^^^^^^^^^^^^^^^^^^^^^^^^^^^^^^^^^^^^^^^^^^^^\n../../.pythonlibs/lib/python3.11/site-packages/httpx/_client.py:1629: in send\n    response = await self._send_handling_auth(\n../../.pythonlibs/lib/python3.11/site-packages/httpx/_client.py:1657: in _send_handling_auth\n    response = await self._send_handling_redirects(\n../../.pythonlibs/lib/python3.11/site-packages/httpx/_client.py:1694: in _send_handling_redirects\n    response = await self._send_single_request(request)\n               ^^^^^^^^^^^^^^^^^^^^^^^^^^^^^^^^^^^^^^^^\n../../.pythonlibs/lib/python3.11/site-packages/httpx/_client.py:1730: in _send_single_request\n    response = await transport.handle_async_request(request)\n               ^^^^^^^^^^^^^^^^^^^^^^^^^^^^^^^^^^^^^^^^^^^^^\n../../.pythonlibs/lib/python3.11/site-packages/httpx/_transports/default.py:393: in handle_async_request\n    with map_httpcore_exceptions():\n/nix/store/7d088dip86hlzri9sk0h78b63yfmx0a0-python3-3.11.13/lib/python3.11/contextlib.py:158: in __exit__\n    self.gen.throw(typ, value, traceback)\n../../.pythonlibs/lib/python3.11/site-packages/httpx/_transports/default.py:118: in map_httpcore_exceptions\n    raise mapped_exc(message) from exc\nE   httpx.ConnectError: All connection attempts failed\n__________________ TestWidgetService.test_generate_embed_code __________________\n../../.pythonlibs/lib/python3.11/site-packages/httpx/_transports/default.py:101: in map_httpcore_exceptions\n    yield\n../../.pythonlibs/lib/python3.11/site-packages/httpx/_transports/default.py:394: in handle_async_request\n    resp = await self._pool.handle_async_request(req)\n           ^^^^^^^^^^^^^^^^^^^^^^^^^^^^^^^^^^^^^^^^^^\n../../.pythonlibs/lib/python3.11/site-packages/httpcore/_async/connection_pool.py:256: in handle_async_request\n    raise exc from None\n../../.pythonlibs/lib/python3.11/site-packages/httpcore/_async/connection_pool.py:236: in handle_async_request\n    response = await connection.handle_async_request(\n../../.pythonlibs/lib/python3.11/site-packages/httpcore/_async/connection.py:101: in handle_async_request\n    raise exc\n../../.pythonlibs/lib/python3.11/site-packages/httpcore/_async/connection.py:78: in handle_async_request\n    stream = await self._connect(request)\n             ^^^^^^^^^^^^^^^^^^^^^^^^^^^^\n../../.pythonlibs/lib/python3.11/site-packages/httpcore/_async/connection.py:124: in _connect\n    stream = await self._network_backend.connect_tcp(**kwargs)\n             ^^^^^^^^^^^^^^^^^^^^^^^^^^^^^^^^^^^^^^^^^^^^^^^^^\n../../.pythonlibs/lib/python3.11/site-packages/httpcore/_backends/auto.py:31: in connect_tcp\n    return await self._backend.connect_tcp(\n../../.pythonlibs/lib/python3.11/site-packages/httpcore/_backends/anyio.py:113: in connect_tcp\n    with map_exceptions(exc_map):\n/nix/store/7d088dip86hlzri9sk0h78b63yfmx0a0-python3-3.11.13/lib/python3.11/contextlib.py:158: in __exit__\n    self.gen.throw(typ, value, traceback)\n../../.pythonlibs/lib/python3.11/site-packages/httpcore/_exceptions.py:14: in map_exceptions\n    raise to_exc(exc) from exc\nE   httpcore.ConnectError: All connection attempts failed\n\nThe above exception was the direct cause of the following exception:\ntest_widget.py:78: in test_generate_embed_code\n    create_response = await client.post(\"/api/widgets\", json=sample_widget_data)\n                      ^^^^^^^^^^^^^^^^^^^^^^^^^^^^^^^^^^^^^^^^^^^^^^^^^^^^^^^^^^\n../../.pythonlibs/lib/python3.11/site-packages/httpx/_client.py:1859: in post\n    return await self.request(\n../../.pythonlibs/lib/python3.11/site-packages/httpx/_client.py:1540: in request\n    return await self.send(request, auth=auth, follow_redirects=follow_redirects)\n           ^^^^^^^^^^^^^^^^^^^^^^^^^^^^^^^^^^^^^^^^^^^^^^^^^^^^^^^^^^^^^^^^^^^^^^\n../../.pythonlibs/lib/python3.11/site-packages/httpx/_client.py:1629: in send\n    response = await self._send_handling_auth(\n../../.pythonlibs/lib/python3.11/site-packages/httpx/_client.py:1657: in _send_handling_auth\n    response = await self._send_handling_redirects(\n../../.pythonlibs/lib/python3.11/site-packages/httpx/_client.py:1694: in _send_handling_redirects\n    response = await self._send_single_request(request)\n               ^^^^^^^^^^^^^^^^^^^^^^^^^^^^^^^^^^^^^^^^\n../../.pythonlibs/lib/python3.11/site-packages/httpx/_client.py:1730: in _send_single_request\n    response = await transport.handle_async_request(request)\n               ^^^^^^^^^^^^^^^^^^^^^^^^^^^^^^^^^^^^^^^^^^^^^\n../../.pythonlibs/lib/python3.11/site-packages/httpx/_transports/default.py:393: in handle_async_request\n    with map_httpcore_exceptions():\n/nix/store/7d088dip86hlzri9sk0h78b63yfmx0a0-python3-3.11.13/lib/python3.11/contextlib.py:158: in __exit__\n    self.gen.throw(typ, value, traceback)\n../../.pythonlibs/lib/python3.11/site-packages/httpx/_transports/default.py:118: in map_httpcore_exceptions\n    raise mapped_exc(message) from exc\nE   httpx.ConnectError: All connection attempts failed\n=========================== short test summary info ============================\nFAILED test_widget.py::TestWidgetService::test_health_endpoint - httpx.Connec...\nFAILED test_widget.py::TestWidgetService::test_create_widget - httpx.ConnectE...\nFAILED test_widget.py::TestWidgetService::test_get_widgets - httpx.ConnectErr...\nFAILED test_widget.py::TestWidgetService::test_get_widget_templates - httpx.C...\nFAILED test_widget.py::TestWidgetService::test_generate_embed_code - httpx.Co...\n============================== 5 failed in 1.10s ===============================\n",
      "errors": ""
    },
    "dashboard": {
      "return_code": 1,
      "passed": false,
      "failed": true,
      "output": "============================= test session starts ==============================\nplatform linux -- Python 3.11.13, pytest-8.4.1, pluggy-1.6.0 -- /home/runner/workspace/.pythonlibs/bin/python3\ncachedir: .pytest_cache\nrootdir: /home/runner/workspace\nconfigfile: pyproject.toml\nplugins: anyio-4.9.0, asyncio-1.1.0\nasyncio: mode=Mode.AUTO, asyncio_default_fixture_loop_scope=None, asyncio_default_test_loop_scope=function\ncollecting ... collected 4 items\n\ntest_dashboard.py::TestDashboardService::test_health_endpoint FAILED     [ 25%]\ntest_dashboard.py::TestDashboardService::test_dashboard_summary FAILED   [ 50%]\ntest_dashboard.py::TestDashboardService::test_dashboard_metrics FAILED   [ 75%]\ntest_dashboard.py::TestDashboardService::test_real_time_activity FAILED  [100%]\n\n=================================== FAILURES ===================================\n__________________ TestDashboardService.test_health_endpoint ___________________\n../../.pythonlibs/lib/python3.11/site-packages/httpx/_transports/default.py:101: in map_httpcore_exceptions\n    yield\n../../.pythonlibs/lib/python3.11/site-packages/httpx/_transports/default.py:394: in handle_async_request\n    resp = await self._pool.handle_async_request(req)\n           ^^^^^^^^^^^^^^^^^^^^^^^^^^^^^^^^^^^^^^^^^^\n../../.pythonlibs/lib/python3.11/site-packages/httpcore/_async/connection_pool.py:256: in handle_async_request\n    raise exc from None\n../../.pythonlibs/lib/python3.11/site-packages/httpcore/_async/connection_pool.py:236: in handle_async_request\n    response = await connection.handle_async_request(\n../../.pythonlibs/lib/python3.11/site-packages/httpcore/_async/connection.py:101: in handle_async_request\n    raise exc\n../../.pythonlibs/lib/python3.11/site-packages/httpcore/_async/connection.py:78: in handle_async_request\n    stream = await self._connect(request)\n             ^^^^^^^^^^^^^^^^^^^^^^^^^^^^\n../../.pythonlibs/lib/python3.11/site-packages/httpcore/_async/connection.py:124: in _connect\n    stream = await self._network_backend.connect_tcp(**kwargs)\n             ^^^^^^^^^^^^^^^^^^^^^^^^^^^^^^^^^^^^^^^^^^^^^^^^^\n../../.pythonlibs/lib/python3.11/site-packages/httpcore/_backends/auto.py:31: in connect_tcp\n    return await self._backend.connect_tcp(\n../../.pythonlibs/lib/python3.11/site-packages/httpcore/_backends/anyio.py:113: in connect_tcp\n    with map_exceptions(exc_map):\n/nix/store/7d088dip86hlzri9sk0h78b63yfmx0a0-python3-3.11.13/lib/python3.11/contextlib.py:158: in __exit__\n    self.gen.throw(typ, value, traceback)\n../../.pythonlibs/lib/python3.11/site-packages/httpcore/_exceptions.py:14: in map_exceptions\n    raise to_exc(exc) from exc\nE   httpcore.ConnectError: All connection attempts failed\n\nThe above exception was the direct cause of the following exception:\ntest_dashboard.py:23: in test_health_endpoint\n    response = await client.get(\"/health\")\n               ^^^^^^^^^^^^^^^^^^^^^^^^^^^\n../../.pythonlibs/lib/python3.11/site-packages/httpx/_client.py:1768: in get\n    return await self.request(\n../../.pythonlibs/lib/python3.11/site-packages/httpx/_client.py:1540: in request\n    return await self.send(request, auth=auth, follow_redirects=follow_redirects)\n           ^^^^^^^^^^^^^^^^^^^^^^^^^^^^^^^^^^^^^^^^^^^^^^^^^^^^^^^^^^^^^^^^^^^^^^\n../../.pythonlibs/lib/python3.11/site-packages/httpx/_client.py:1629: in send\n    response = await self._send_handling_auth(\n../../.pythonlibs/lib/python3.11/site-packages/httpx/_client.py:1657: in _send_handling_auth\n    response = await self._send_handling_redirects(\n../../.pythonlibs/lib/python3.11/site-packages/httpx/_client.py:1694: in _send_handling_redirects\n    response = await self._send_single_request(request)\n               ^^^^^^^^^^^^^^^^^^^^^^^^^^^^^^^^^^^^^^^^\n../../.pythonlibs/lib/python3.11/site-packages/httpx/_client.py:1730: in _send_single_request\n    response = await transport.handle_async_request(request)\n               ^^^^^^^^^^^^^^^^^^^^^^^^^^^^^^^^^^^^^^^^^^^^^\n../../.pythonlibs/lib/python3.11/site-packages/httpx/_transports/default.py:393: in handle_async_request\n    with map_httpcore_exceptions():\n/nix/store/7d088dip86hlzri9sk0h78b63yfmx0a0-python3-3.11.13/lib/python3.11/contextlib.py:158: in __exit__\n    self.gen.throw(typ, value, traceback)\n../../.pythonlibs/lib/python3.11/site-packages/httpx/_transports/default.py:118: in map_httpcore_exceptions\n    raise mapped_exc(message) from exc\nE   httpx.ConnectError: All connection attempts failed\n_________________ TestDashboardService.test_dashboard_summary __________________\n../../.pythonlibs/lib/python3.11/site-packages/httpx/_transports/default.py:101: in map_httpcore_exceptions\n    yield\n../../.pythonlibs/lib/python3.11/site-packages/httpx/_transports/default.py:394: in handle_async_request\n    resp = await self._pool.handle_async_request(req)\n           ^^^^^^^^^^^^^^^^^^^^^^^^^^^^^^^^^^^^^^^^^^\n../../.pythonlibs/lib/python3.11/site-packages/httpcore/_async/connection_pool.py:256: in handle_async_request\n    raise exc from None\n../../.pythonlibs/lib/python3.11/site-packages/httpcore/_async/connection_pool.py:236: in handle_async_request\n    response = await connection.handle_async_request(\n../../.pythonlibs/lib/python3.11/site-packages/httpcore/_async/connection.py:101: in handle_async_request\n    raise exc\n../../.pythonlibs/lib/python3.11/site-packages/httpcore/_async/connection.py:78: in handle_async_request\n    stream = await self._connect(request)\n             ^^^^^^^^^^^^^^^^^^^^^^^^^^^^\n../../.pythonlibs/lib/python3.11/site-packages/httpcore/_async/connection.py:124: in _connect\n    stream = await self._network_backend.connect_tcp(**kwargs)\n             ^^^^^^^^^^^^^^^^^^^^^^^^^^^^^^^^^^^^^^^^^^^^^^^^^\n../../.pythonlibs/lib/python3.11/site-packages/httpcore/_backends/auto.py:31: in connect_tcp\n    return await self._backend.connect_tcp(\n../../.pythonlibs/lib/python3.11/site-packages/httpcore/_backends/anyio.py:113: in connect_tcp\n    with map_exceptions(exc_map):\n/nix/store/7d088dip86hlzri9sk0h78b63yfmx0a0-python3-3.11.13/lib/python3.11/contextlib.py:158: in __exit__\n    self.gen.throw(typ, value, traceback)\n../../.pythonlibs/lib/python3.11/site-packages/httpcore/_exceptions.py:14: in map_exceptions\n    raise to_exc(exc) from exc\nE   httpcore.ConnectError: All connection attempts failed\n\nThe above exception was the direct cause of the following exception:\ntest_dashboard.py:32: in test_dashboard_summary\n    response = await client.get(\"/api/dashboard/summary\")\n               ^^^^^^^^^^^^^^^^^^^^^^^^^^^^^^^^^^^^^^^^^^\n../../.pythonlibs/lib/python3.11/site-packages/httpx/_client.py:1768: in get\n    return await self.request(\n../../.pythonlibs/lib/python3.11/site-packages/httpx/_client.py:1540: in request\n    return await self.send(request, auth=auth, follow_redirects=follow_redirects)\n           ^^^^^^^^^^^^^^^^^^^^^^^^^^^^^^^^^^^^^^^^^^^^^^^^^^^^^^^^^^^^^^^^^^^^^^\n../../.pythonlibs/lib/python3.11/site-packages/httpx/_client.py:1629: in send\n    response = await self._send_handling_auth(\n../../.pythonlibs/lib/python3.11/site-packages/httpx/_client.py:1657: in _send_handling_auth\n    response = await self._send_handling_redirects(\n../../.pythonlibs/lib/python3.11/site-packages/httpx/_client.py:1694: in _send_handling_redirects\n    response = await self._send_single_request(request)\n               ^^^^^^^^^^^^^^^^^^^^^^^^^^^^^^^^^^^^^^^^\n../../.pythonlibs/lib/python3.11/site-packages/httpx/_client.py:1730: in _send_single_request\n    response = await transport.handle_async_request(request)\n               ^^^^^^^^^^^^^^^^^^^^^^^^^^^^^^^^^^^^^^^^^^^^^\n../../.pythonlibs/lib/python3.11/site-packages/httpx/_transports/default.py:393: in handle_async_request\n    with map_httpcore_exceptions():\n/nix/store/7d088dip86hlzri9sk0h78b63yfmx0a0-python3-3.11.13/lib/python3.11/contextlib.py:158: in __exit__\n    self.gen.throw(typ, value, traceback)\n../../.pythonlibs/lib/python3.11/site-packages/httpx/_transports/default.py:118: in map_httpcore_exceptions\n    raise mapped_exc(message) from exc\nE   httpx.ConnectError: All connection attempts failed\n_________________ TestDashboardService.test_dashboard_metrics __________________\n../../.pythonlibs/lib/python3.11/site-packages/httpx/_transports/default.py:101: in map_httpcore_exceptions\n    yield\n../../.pythonlibs/lib/python3.11/site-packages/httpx/_transports/default.py:394: in handle_async_request\n    resp = await self._pool.handle_async_request(req)\n           ^^^^^^^^^^^^^^^^^^^^^^^^^^^^^^^^^^^^^^^^^^\n../../.pythonlibs/lib/python3.11/site-packages/httpcore/_async/connection_pool.py:256: in handle_async_request\n    raise exc from None\n../../.pythonlibs/lib/python3.11/site-packages/httpcore/_async/connection_pool.py:236: in handle_async_request\n    response = await connection.handle_async_request(\n../../.pythonlibs/lib/python3.11/site-packages/httpcore/_async/connection.py:101: in handle_async_request\n    raise exc\n../../.pythonlibs/lib/python3.11/site-packages/httpcore/_async/connection.py:78: in handle_async_request\n    stream = await self._connect(request)\n             ^^^^^^^^^^^^^^^^^^^^^^^^^^^^\n../../.pythonlibs/lib/python3.11/site-packages/httpcore/_async/connection.py:124: in _connect\n    stream = await self._network_backend.connect_tcp(**kwargs)\n             ^^^^^^^^^^^^^^^^^^^^^^^^^^^^^^^^^^^^^^^^^^^^^^^^^\n../../.pythonlibs/lib/python3.11/site-packages/httpcore/_backends/auto.py:31: in connect_tcp\n    return await self._backend.connect_tcp(\n../../.pythonlibs/lib/python3.11/site-packages/httpcore/_backends/anyio.py:113: in connect_tcp\n    with map_exceptions(exc_map):\n/nix/store/7d088dip86hlzri9sk0h78b63yfmx0a0-python3-3.11.13/lib/python3.11/contextlib.py:158: in __exit__\n    self.gen.throw(typ, value, traceback)\n../../.pythonlibs/lib/python3.11/site-packages/httpcore/_exceptions.py:14: in map_exceptions\n    raise to_exc(exc) from exc\nE   httpcore.ConnectError: All connection attempts failed\n\nThe above exception was the direct cause of the following exception:\ntest_dashboard.py:42: in test_dashboard_metrics\n    response = await client.get(\"/api/dashboard\")\n               ^^^^^^^^^^^^^^^^^^^^^^^^^^^^^^^^^^\n../../.pythonlibs/lib/python3.11/site-packages/httpx/_client.py:1768: in get\n    return await self.request(\n../../.pythonlibs/lib/python3.11/site-packages/httpx/_client.py:1540: in request\n    return await self.send(request, auth=auth, follow_redirects=follow_redirects)\n           ^^^^^^^^^^^^^^^^^^^^^^^^^^^^^^^^^^^^^^^^^^^^^^^^^^^^^^^^^^^^^^^^^^^^^^\n../../.pythonlibs/lib/python3.11/site-packages/httpx/_client.py:1629: in send\n    response = await self._send_handling_auth(\n../../.pythonlibs/lib/python3.11/site-packages/httpx/_client.py:1657: in _send_handling_auth\n    response = await self._send_handling_redirects(\n../../.pythonlibs/lib/python3.11/site-packages/httpx/_client.py:1694: in _send_handling_redirects\n    response = await self._send_single_request(request)\n               ^^^^^^^^^^^^^^^^^^^^^^^^^^^^^^^^^^^^^^^^\n../../.pythonlibs/lib/python3.11/site-packages/httpx/_client.py:1730: in _send_single_request\n    response = await transport.handle_async_request(request)\n               ^^^^^^^^^^^^^^^^^^^^^^^^^^^^^^^^^^^^^^^^^^^^^\n../../.pythonlibs/lib/python3.11/site-packages/httpx/_transports/default.py:393: in handle_async_request\n    with map_httpcore_exceptions():\n/nix/store/7d088dip86hlzri9sk0h78b63yfmx0a0-python3-3.11.13/lib/python3.11/contextlib.py:158: in __exit__\n    self.gen.throw(typ, value, traceback)\n../../.pythonlibs/lib/python3.11/site-packages/httpx/_transports/default.py:118: in map_httpcore_exceptions\n    raise mapped_exc(message) from exc\nE   httpx.ConnectError: All connection attempts failed\n_________________ TestDashboardService.test_real_time_activity _________________\n../../.pythonlibs/lib/python3.11/site-packages/httpx/_transports/default.py:101: in map_httpcore_exceptions\n    yield\n../../.pythonlibs/lib/python3.11/site-packages/httpx/_transports/default.py:394: in handle_async_request\n    resp = await self._pool.handle_async_request(req)\n           ^^^^^^^^^^^^^^^^^^^^^^^^^^^^^^^^^^^^^^^^^^\n../../.pythonlibs/lib/python3.11/site-packages/httpcore/_async/connection_pool.py:256: in handle_async_request\n    raise exc from None\n../../.pythonlibs/lib/python3.11/site-packages/httpcore/_async/connection_pool.py:236: in handle_async_request\n    response = await connection.handle_async_request(\n../../.pythonlibs/lib/python3.11/site-packages/httpcore/_async/connection.py:101: in handle_async_request\n    raise exc\n../../.pythonlibs/lib/python3.11/site-packages/httpcore/_async/connection.py:78: in handle_async_request\n    stream = await self._connect(request)\n             ^^^^^^^^^^^^^^^^^^^^^^^^^^^^\n../../.pythonlibs/lib/python3.11/site-packages/httpcore/_async/connection.py:124: in _connect\n    stream = await self._network_backend.connect_tcp(**kwargs)\n             ^^^^^^^^^^^^^^^^^^^^^^^^^^^^^^^^^^^^^^^^^^^^^^^^^\n../../.pythonlibs/lib/python3.11/site-packages/httpcore/_backends/auto.py:31: in connect_tcp\n    return await self._backend.connect_tcp(\n../../.pythonlibs/lib/python3.11/site-packages/httpcore/_backends/anyio.py:113: in connect_tcp\n    with map_exceptions(exc_map):\n/nix/store/7d088dip86hlzri9sk0h78b63yfmx0a0-python3-3.11.13/lib/python3.11/contextlib.py:158: in __exit__\n    self.gen.throw(typ, value, traceback)\n../../.pythonlibs/lib/python3.11/site-packages/httpcore/_exceptions.py:14: in map_exceptions\n    raise to_exc(exc) from exc\nE   httpcore.ConnectError: All connection attempts failed\n\nThe above exception was the direct cause of the following exception:\ntest_dashboard.py:52: in test_real_time_activity\n    response = await client.get(\"/api/dashboard/activity\")\n               ^^^^^^^^^^^^^^^^^^^^^^^^^^^^^^^^^^^^^^^^^^^\n../../.pythonlibs/lib/python3.11/site-packages/httpx/_client.py:1768: in get\n    return await self.request(\n../../.pythonlibs/lib/python3.11/site-packages/httpx/_client.py:1540: in request\n    return await self.send(request, auth=auth, follow_redirects=follow_redirects)\n           ^^^^^^^^^^^^^^^^^^^^^^^^^^^^^^^^^^^^^^^^^^^^^^^^^^^^^^^^^^^^^^^^^^^^^^\n../../.pythonlibs/lib/python3.11/site-packages/httpx/_client.py:1629: in send\n    response = await self._send_handling_auth(\n../../.pythonlibs/lib/python3.11/site-packages/httpx/_client.py:1657: in _send_handling_auth\n    response = await self._send_handling_redirects(\n../../.pythonlibs/lib/python3.11/site-packages/httpx/_client.py:1694: in _send_handling_redirects\n    response = await self._send_single_request(request)\n               ^^^^^^^^^^^^^^^^^^^^^^^^^^^^^^^^^^^^^^^^\n../../.pythonlibs/lib/python3.11/site-packages/httpx/_client.py:1730: in _send_single_request\n    response = await transport.handle_async_request(request)\n               ^^^^^^^^^^^^^^^^^^^^^^^^^^^^^^^^^^^^^^^^^^^^^\n../../.pythonlibs/lib/python3.11/site-packages/httpx/_transports/default.py:393: in handle_async_request\n    with map_httpcore_exceptions():\n/nix/store/7d088dip86hlzri9sk0h78b63yfmx0a0-python3-3.11.13/lib/python3.11/contextlib.py:158: in __exit__\n    self.gen.throw(typ, value, traceback)\n../../.pythonlibs/lib/python3.11/site-packages/httpx/_transports/default.py:118: in map_httpcore_exceptions\n    raise mapped_exc(message) from exc\nE   httpx.ConnectError: All connection attempts failed\n=========================== short test summary info ============================\nFAILED test_dashboard.py::TestDashboardService::test_health_endpoint - httpx....\nFAILED test_dashboard.py::TestDashboardService::test_dashboard_summary - http...\nFAILED test_dashboard.py::TestDashboardService::test_dashboard_metrics - http...\nFAILED test_dashboard.py::TestDashboardService::test_real_time_activity - htt...\n============================== 4 failed in 0.95s ===============================\n",
      "errors": ""
    }
  },
  "integration_results": {
    "return_code": 1,
    "passed": true,
    "failed": true,
    "output": "============================= test session starts ==============================\nplatform linux -- Python 3.11.13, pytest-8.4.1, pluggy-1.6.0 -- /home/runner/workspace/.pythonlibs/bin/python3\ncachedir: .pytest_cache\nrootdir: /home/runner/workspace\nconfigfile: pyproject.toml\nplugins: anyio-4.9.0, asyncio-1.1.0\nasyncio: mode=Mode.AUTO, asyncio_default_fixture_loop_scope=None, asyncio_default_test_loop_scope=function\ncollecting ... collected 8 items\n\ntest_integration.py::TestMicroservicesIntegration::test_all_services_health FAILED [ 12%]\ntest_integration.py::TestMicroservicesIntegration::test_agent_creation_workflow SKIPPED [ 25%]\ntest_integration.py::TestMicroservicesIntegration::test_dashboard_data_aggregation PASSED [ 37%]\ntest_integration.py::TestMicroservicesIntegration::test_cross_service_communication PASSED [ 50%]\ntest_integration.py::TestMicroservicesIntegration::test_data_consistency PASSED [ 62%]\ntest_integration.py::TestEndToEndWorkflows::test_complete_agent_lifecycle PASSED [ 75%]\ntest_integration.py::TestEndToEndWorkflows::test_platform_performance PASSED [ 87%]\ntest_integration.py::test_system_resilience PASSED                       [100%]\n\n=================================== FAILURES ===================================\n____________ TestMicroservicesIntegration.test_all_services_health _____________\ntest_integration.py:57: in test_all_services_health\n    assert healthy_services >= 3, f\"Only {healthy_services}/6 services are healthy\"\nE   AssertionError: Only 0/6 services are healthy\nE   assert 0 >= 3\n----------------------------- Captured stdout call -----------------------------\n\n=== Service Health Status ===\nagent-wizard: \u2717 (None)\nanalytics: \u2717 (None)\nbilling: \u2717 (None)\ndashboard: \u2717 (None)\nwidget: \u2717 (None)\nmy-agents: \u2717 (None)\n=========================== short test summary info ============================\nFAILED test_integration.py::TestMicroservicesIntegration::test_all_services_health\n==================== 1 failed, 6 passed, 1 skipped in 1.18s ====================\n",
    "errors": ""
  },
  "e2e_results": {
    "agent_lifecycle": {
      "success": false,
      "steps": [
        [
          "error",
          false
        ]
      ],
      "completion_rate": "0/1"
    },
    "data_flow": {
      "success": false,
      "checks": [
        [
          "error",
          false
        ]
      ],
      "success_rate": "0/1"
    },
    "resilience": {
      "success": false,
      "tests": [
        [
          "error",
          false
        ]
      ],
      "success_rate": "0/1"
    }
  },
  "overall_score": 0.2
}